Workbook

Sheet 2021-2022
A1: Country of residence | B1: Currency | C1: Exchange rate | D1: Lower earnings threshold (GBP) | E1: Upper earnings threshold (GBP) | F1: Fixed monthly repayment (GBP) | H1: https://web.archive.org/web/20220404134127/https://www.gov.uk/government/publications/overseas-earnings-thresholds-for-plan-2-student-loans/overseas-earnings-thresholds-for-plan-2-student-loans-2020-21 | I1: Link
A2: Afghanistan | B2: Afghanis | C2: 0.010752 | D2: £5,460.00 | E2: £9,830.00 | F2: £40.20
A3: Albania | B3: Leke | C3: 0.007178 | D3: £10,920.00 | E3: £19,655.00 | F3: £80.40
A4: Algeria | B4: Algerian Dinar | C4: 0.006227 | D4: £10,920.00 | E4: £19,655.00 | F4: £80.40
A5: American Samoa | B5: U.S. Dollar | C5: 0.783249 | D5: £32,755.00 | E5: £58,960.00 | F5: £241.20
A6: Andorra | B6: Euro | C6: 0.885798 | D6: £27,295.00 | E6: £49,130.00 | F6: £201.00
A7: Angola | B7: Kwanza | C7: 0.00139 | D7: £10,920.00 | E7: £19,655.00 | F7: £80.40
A8: Anguilla | B8: East Caribbean Dollar | C8: 0.290093 | D8: £27,295.00 | E8: £49,130.00 | F8: £201.00
A9: Antarctica | B9: U.S. Dollar | C9: 0.783249 | D9: £32,755.00 | E9: £58,960.00 | F9: £241.20
A10: Antigua and Barbuda | B10: East Caribbean Dollar | C10: 0.290093 | D10: £21,840.00 | E10: £39,305.00 | F10: £160.80
A11: Argentina | B11: Argentine Peso | C11: 0.011345 | D11: £16,380.00 | E11: £29,480.00 | F11: £120.60
A12: Armenia | B12: Dram | C12: 0.001615 | D12: £10,920.00 | E12: £19,655.00 | F12: £80.40
A13: Aruba | B13: Aruban Guilder | C13: 0.437573 | D13: £27,295.00 | E13: £49,130.00 | F13: £201.00
A14: Australia | B14: Australian Dollar | C14: 0.533862 | D14: £32,755.00 | E14: £58,960.00 | F14: £241.20
A15: Austria | B15: Euro | C15: 0.885798 | D15: £27,295.00 | E15: £49,130.00 | F15: £201.00
A16: Azerbaijan | B16: Azerbaijanian Manat | C16: 0.461398 | D16: £10,920.00 | E16: £19,655.00 | F16: £80.40
A17: Bahamas | B17: Bahamian Dollar | C17: 0.783249 | D17: £27,295.00 | E17: £49,130.00 | F17: £201.00
A18: Bahrain | B18: Bahrain Dinar | C18: 2.080191 | D18: £16,380.00 | E18: £29,480.00 | F18: £120.60
A19: Bangladesh | B19: Taka | C19: 0.009225 | D19: £10,920.00 | E19: £19,655.00 | F19: £80.40
A20: Barbados | B20: Barbados Dollar | C20: 0.391626 | D20: £32,755.00 | E20: £58,960.00 | F20: £241.20
A21: Belarus | B21: Belarusian Ruble | C21: 0.327272 | D21: £10,920.00 | E21: £19,655.00 | F21: £80.40
A22: Belgium | B22: Euro | C22: 0.885798 | D22: £27,295.00 | E22: £49,130.00 | F22: £201.00
A23: Belize | B23: Belizean Dollar | C23: 0.391626 | D23: £21,840.00 | E23: £39,305.00 | F23: £160.80
A24: Benin | B24: CFA Franc (BEAC) | C24: 0.00135 | D24: £10,920.00 | E24: £19,655.00 | F24: £80.40
A25: Bermuda | B25: Bermudian Dollar | C25: 0.783249 | D25: £27,295.00 | E25: £49,130.00 | F25: £201.00
A26: Bhutan | B26: Bhutanese Ngultrum | C26: 0.010595 | D26: £10,920.00 | E26: £19,655.00 | F26: £80.40
A27: Bolivia | B27: Boliviano | C27: 0.113351 | D27: £10,920.00 | E27: £19,655.00 | F27: £80.40
... A44: Chad | B44: CFA Franc (BEAC) | C44: 0.00135 | D44: £10,920.00 | E44: £19,655.00 | F44: £80.40
A45: Channel Islands | B45: British Pound | C45: 1 | D45: £27,295.00 | E45: £49,130.00 | F45: £201.00
A46: Chile | B46: Chilean Peso | C46: 0.000988 | D46: £16,380.00 | E46: £29,480.00 | F46: £120.60
A47: China | B47: Yuan Renminbi | C47: 0.113173 | D47: £21,840.00 | E47: £39,305.00 | F47: £160.80
A48: Christmas Island | B48: Australian Dollar | C48: 0.533862 | D48: £32,755.00 | E48: £58,960.00 | F48: £241.20
A49: Cocos (Keeling) Islands | B49: Australian Dollar | C49: 0.533862 | D49: £32,755.00 | E49: £58,960.00 | F49: £241.20
A50: Colombia | B50: Colombian Peso | C50: 0.000211 | D50: £10,920.00 | E50: £19,655.00 | F50: £80.40
A51: Comoros | B51: Comorian Franc | C51: 0.001801 | D51: £16,380.00 | E51: £29,480.00 | F51: £120.60
A52: Congo | B52: Congolese Franc | C52: 0.000428 | D52: £16,380.00 | E52: £29,480.00 | F52: £120.60
A53: Congo, Democratic Republic of | B53: Congolese Franc | C53: 0.000428 | D53: £16,380.00 | E53: £29,480.00 | F53: £120.60
A54: Cook Islands | B54: New Zealand Dollar | C54: 0.50445 | D54: £32,755.00 | E54: £58,960.00 | F54: £241.20
A55: Costa Rica | B55: Costa Rican Colon | C55: 0.001348 | D55: £16,380.00 | E55: £29,480.00 | F55: £120.60
A56: Cote d’Ivoire | B56: CFA Franc (BEAC) | C56: 0.00135 | D56: £10,920.00 | E56: £19,655.00 | F56: £80.40
...

Sheet 2025-26
A1: Country | B1: Currency | C1: Exchange rate | D1: Lower earnings threshold (GBP) | E1: Upper earnings threshold (GBP) | F1: Fixed monthly repayment (GBP) | H1: https://www.gov.uk/government/publications/overseas-earnings-thresholds-for-plan-2-student-loans/overseas-earnings-thresholds-for-plan-2-student-loans-2024-25?utm_source=chatgpt.com | I1: Link
A2: Afghanistan | B2: Afghanis | C2: 0.010752 | D2: £5,695.00 | E2: £10,250.00 | F2: £77.20
A3: Aland Islands | B3: Euro | C3: 0.848248 | D3: £28,470.00 | E3: £51,245.00 | F3: £386.00
A4: Albania | B4: Leke | C4: 0.0084 | D4: £11,390.00 | E4: £20,500.00 | F4: £154.40
A5: Algeria | B5: Algerian Dinar | C5: 0.005828 | D5: £11,390.00 | E5: £20,500.00 | F5: £154.40
A6: American Samoa | B6: U.S. Dollar | C6: 0.782044 | D6: £34,165.00 | E6: £61,495.00 | F6: £463.20
A7: Andorra | B7: Euro | C7: 0.848248 | D7: £22,780.00 | E7: £41,000.00 | F7: £308.80
A8: Angola | B8: Kwanza | C8: 0.000893 | D8: £11,390.00 | E8: £20,500.00 | F8: £154.40
A9: Anguilla | B9: East Caribbean Dollar | C9: 0.289452 | D9: £28,470.00 | E9: £51,245.00 | F9: £386.00
A10: Antarctica | B10: U.S. Dollar | C10: 0.782044 | D10: £28,470.00 | E10: £51,245.00 | F10: £386.00
A11: Antigua and Barbuda | B11: East Caribbean Dollar | C11: 0.289452 | D11: £22,780.00 | E11: £41,000.00 | F11: £308.80
A12: Argentina | B12: Argentine Peso | C12: 0.000869 | D12: £17,085.00 | E12: £30,750.00 | F12: £231.60
A13: Armenia | B13: Dram | C13: 0.001993 | D13: £11,390.00 | E13: £20,500.00 | F13: £154.40
... A15: Australia | B15: Australian Dollar | C15: 0.518403 | D15: £34,165.00 | E15: £61,495.00 | F15: £463.20
A16: Austria | B16: Euro | C16: 0.848248 | D16: £28,470.00 | E16: £51,245.00 | F16: £386.00
A17: Azerbaijan | B17: Azerbaijanian Manat | C17: 0.459939 | D17: £11,390.00 | E17: £20,500.00 | F17: £154.40
A18: Bahamas | B18: Bahamian Dollar | C18: 0.782044 | D18: £34,165.00 | E18: £61,495.00 | F18: £463.20
A19: Bahrain | B19: Bahrain Dinar | C19: 2.079867 | D19: £17,085.00 | E19: £30,750.00 | F19: £231.60
A20: Bangladesh | B20: Taka | C20: 0.006806 | D20: £11,390.00 | E20: £20,500.00 | F20: £154.40
A21: Barbados | B21: Barbados Dollar | C21: 0.391037 | D21: £39,860.00 | E21: £71,745.00 | F21: £540.40
A22: Belarus | B22: Belarusian Ruble | C22: 0.23888 | D22: £11,390.00 | E22: £20,500.00 | F22: £154.40
A23: Belgium | B23: Euro | C23: 0.848248 | D23: £28,470.00 | E23: £51,245.00 | F23: £386.00
A24: Belize | B24: Belizean Dollar | C24: 0.387342 | D24: £17,085.00 | E24: £30,750.00 | F24: £231.60
A25: Benin | B25: CFA Franc (BEAC) | C25: 0.001293 | D25: £11,390.00 | E25: £20,500.00 | F25: £154.40
A26: Bermuda | B26: Bermudian Dollar | C26: 0.782044 | D26: £39,860.00 | E26: £71,745.00 | F26: £540.40
A27: Bhutan | B27: Bhutanese Ngultrum | C27: 0.009361 | D27: £11,390.00 | E27: £20,500.00 | F27: £154.40
A28: Bolivia | B28: Boliviano | C28: 0.113228 | D28: £11,390.00 | E28: £20,500.00 | F28: £154.40
... A45: Chad | B45: CFA Franc (BEAC) | C45: 0.001293 | D45: £11,390.00 | E45: £20,500.00 | F45: £154.40
A46: Channel Islands | B46: British Pound | C46: 1 | D46: £28,470.00 | E46: £51,245.00 | F46: £386.00
A47: Chile | B47: Chilean Peso | C47: 0.000836 | D47: £17,085.00 | E47: £30,750.00 | F47: £231.60
A48: China | B48: Yuan Renminbi | C48: 0.10879 | D48: £17,085.00 | E48: £30,750.00 | F48: £231.60
A49: Christmas Island | B49: Australian Dollar | C49: 0.518403 | D49: £34,165.00 | E49: £61,495.00 | F49: £463.20
A50: Cocos (Keeling) Islands | B50: Australian Dollar | C50: 0.518403 | D50: £34,165.00 | E50: £61,495.00 | F50: £463.20
A51: Colombia | B51: Colombian Peso | C51: 0.000194 | D51: £11,390.00 | E51: £20,500.00 | F51: £154.40
A52: Comoros | B52: Comorian Franc | C52: 0.001724 | D52: £11,390.00 | E52: £20,500.00 | F52: £154.40
A53: Congo | B53: Congolese Franc | C53: 0.000279 | D53: £11,390.00 | E53: £20,500.00 | F53: £154.40
A54: Congo, Democratic Republic of | B54: Congolese Franc | C54: 0.000279 | D54: £11,390.00 | E54: £20,500.00 | F54: £154.40
A55: Cook Islands | B55: New Zealand Dollar | C55: 0.476372 | D55: £28,470.00 | E55: £51,245.00 | F55: £386.00
A56: Costa Rica | B56: Costa Rican Colon | C56: 0.001519 | D56: £22,780.00 | E56: £41,000.00 | F56: £308.80
A57: Cote d’Ivoire | B57: CFA Franc (BEAC) | C57: 0.001293 | D57: £11,390.00 | E57: £20,500.00 | F57: £154.40
...

Sheet checks
A1: 2021 tresholds in £ | D1: 2025 tresholds £
A2: Countries | B2: Lower threshold | C2: Upper threshold | D2: Countries | E2: Lower threshold | F2: Upper threshold
A3: Bulgaria, Romania | B3: £10,920 | C3: £19,655 | D3: Bulgaria, Romania | E3: £11,390 | F3: £20,500
A4: Croatia, Czechia, Hungary, Latvia, Lithuania, Poland, Slovakia | B4: £16,380 | C4: £29,480 | D4: Croatia, Czechia, Greece, Hungary, Latvia, Lithuania, Poland, Portugal, Slovakia | E4: £17,085 | F4: £30,750
A5: Cyprus, Estonia, Greece, Italy, Malta, Portugal, Slovenia, Spain | B5: £21,840 | C5: £39,305 | D5: Cyprus, Estonia, France, Italy, Malta, Slovenia, Spain | E5: £22,780 | F5: £41,000
A6: Austria, Belgium, Finland, France, Germany, Luxembourg, Netherlands, Sweden | B6: £27,295 | C6: £49,130 | D6: Austria, Belgium, Denmark, Finland, Germany, Luxembourg, Netherlands, Sweden | E6: £28,470 | F6: £51,245
A7: Denmark | B7: £32,755 | C7: £58,960
A9: Country | B9: ISO2 | C9: Lower_2021_22 | D9: Upper_2021_22 | E9: Lower_2025_26 | F9: Upper_2025_26
A10: Bulgaria | B10: BG | C10: =VLOOKUP(A10,Таблица1[#All],4,FALSE) -> £10,920.00 | D10: =VLOOKUP(A10,Таблица1[#All],5,FALSE) -> £19,655.00 | E10: =VLOOKUP(A10,Таблица2[#All],4,FALSE) -> £11,390.00 | F10: =VLOOKUP(A10,Таблица2[#All],5,FALSE) -> £20,500.00
A11: Romania | B11: RO | C11: =VLOOKUP(A11,Таблица1[#All],4,FALSE) -> £10,920.00 | D11: =VLOOKUP(A11,Таблица1[#All],5,FALSE) -> £19,655.00 | E11: =VLOOKUP(A11,Таблица2[#All],4,FALSE) -> £11,390.00 | F11: =VLOOKUP(A11,Таблица2[#All],5,FALSE) -> £20,500.00
A12: Croatia | B12: HR | C12: =VLOOKUP(A12,Таблица1[#All],4,FALSE) -> £16,380.00 | D12: =VLOOKUP(A12,Таблица1[#All],5,FALSE) -> £29,480.00 | E12: =VLOOKUP(A12,Таблица2[#All],4,FALSE) -> £17,085.00 | F12: =VLOOKUP(A12,Таблица2[#All],5,FALSE) -> £30,750.00
A13: Czechia | B13: CZ | C13: ='2021-2022'!D61 -> £16,380.00 | D13: ='2021-2022'!E61 -> £29,480.00 | E13: ='2025-26'!D62 -> £17,085.00 | F13: ='2025-26'!E62 -> £30,750.00
A14: Hungary | B14: HU | C14: =VLOOKUP(A14,Таблица1[#All],4,FALSE) -> £16,380.00 | D14: =VLOOKUP(A14,Таблица1[#All],5,FALSE) -> £29,480.00 | E14: =VLOOKUP(A14,Таблица2[#All],4,FALSE) -> £17,085.00 | F14: =VLOOKUP(A14,Таблица2[#All],5,FALSE) -> £30,750.00
A15: Latvia | B15: LV | C15: =VLOOKUP(A15,Таблица1[#All],4,FALSE) -> £16,380.00 | D15: =VLOOKUP(A15,Таблица1[#All],5,FALSE) -> £29,480.00 | E15: =VLOOKUP(A15,Таблица2[#All],4,FALSE) -> £17,085.00 | F15: =VLOOKUP(A15,Таблица2[#All],5,FALSE) -> £30,750.00
A16: Lithuania | B16: LT | C16: =VLOOKUP(A16,Таблица1[#All],4,FALSE) -> £16,380.00 | D16: =VLOOKUP(A16,Таблица1[#All],5,FALSE) -> £29,480.00 | E16: =VLOOKUP(A16,Таблица2[#All],4,FALSE) -> £17,085.00 | F16: =VLOOKUP(A16,Таблица2[#All],5,FALSE) -> £30,750.00
A17: Poland | B17: PL | C17: =VLOOKUP(A17,Таблица1[#All],4,FALSE) -> £16,380.00 | D17: =VLOOKUP(A17,Таблица1[#All],5,FALSE) -> £29,480.00 | E17: =VLOOKUP(A17,Таблица2[#All],4,FALSE) -> £17,085.00 | F17: =VLOOKUP(A17,Таблица2[#All],5,FALSE) -> £30,750.00
A18: Slovakia | B18: SK | C18: =VLOOKUP(A18,Таблица1[#All],4,FALSE) -> £16,380.00 | D18: =VLOOKUP(A18,Таблица1[#All],5,FALSE) -> £29,480.00 | E18: =VLOOKUP(A18,Таблица2[#All],4,FALSE) -> £17,085.00 | F18: =VLOOKUP(A18,Таблица2[#All],5,FALSE) -> £30,750.00
A19: Cyprus | B19: CY | C19: =VLOOKUP(A19,Таблица1[#All],4,FALSE) -> £21,840.00 | D19: =VLOOKUP(A19,Таблица1[#All],5,FALSE) -> £39,305.00 | E19: =VLOOKUP(A19,Таблица2[#All],4,FALSE) -> £22,780.00 | F19: =VLOOKUP(A19,Таблица2[#All],5,FALSE) -> £41,000.00
A20: Estonia | B20: EE | C20: =VLOOKUP(A20,Таблица1[#All],4,FALSE) -> £21,840.00 | D20: =VLOOKUP(A20,Таблица1[#All],5,FALSE) -> £39,305.00 | E20: =VLOOKUP(A20,Таблица2[#All],4,FALSE) -> £22,780.00 | F20: =VLOOKUP(A20,Таблица2[#All],5,FALSE) -> £41,000.00
A21: Greece | B21: GR | C21: =VLOOKUP(A21,Таблица1[#All],4,FALSE) -> £21,840.00 | D21: =VLOOKUP(A21,Таблица1[#All],5,FALSE) -> £39,305.00 | E21: =VLOOKUP(A21,Таблица2[#All],4,FALSE) -> £17,085.00 | F21: =VLOOKUP(A21,Таблица2[#All],5,FALSE) -> £30,750.00
A22: Italy | B22: IT | C22: =VLOOKUP(A22,Таблица1[#All],4,FALSE) -> £21,840.00 | D22: =VLOOKUP(A22,Таблица1[#All],5,FALSE) -> £39,305.00 | E22: =VLOOKUP(A22,Таблица2[#All],4,FALSE) -> £22,780.00 | F22: =VLOOKUP(A22,Таблица2[#All],5,FALSE) -> £41,000.00
A23: Malta | B23: MT | C23: =VLOOKUP(A23,Таблица1[#All],4,FALSE) -> £21,840.00 | D23: =VLOOKUP(A23,Таблица1[#All],5,FALSE) -> £39,305.00 | E23: =VLOOKUP(A23,Таблица2[#All],4,FALSE) -> £22,780.00 | F23: =VLOOKUP(A23,Таблица2[#All],5,FALSE) -> £41,000.00
A24: Portugal | B24: PT | C24: =VLOOKUP(A24,Таблица1[#All],4,FALSE) -> £21,840.00 | D24: =VLOOKUP(A24,Таблица1[#All],5,FALSE) -> £39,305.00 | E24: =VLOOKUP(A24,Таблица2[#All],4,FALSE) -> £17,085.00 | F24: =VLOOKUP(A24,Таблица2[#All],5,FALSE) -> £30,750.00
A25: Slovenia | B25: SI | C25: =VLOOKUP(A25,Таблица1[#All],4,FALSE) -> £21,840.00 | D25: =VLOOKUP(A25,Таблица1[#All],5,FALSE) -> £39,305.00 | E25: =VLOOKUP(A25,Таблица2[#All],4,FALSE) -> £22,780.00 | F25: =VLOOKUP(A25,Таблица2[#All],5,FALSE) -> £41,000.00
... A35: Denmark | B35: DK | C35: =VLOOKUP(A35,Таблица1[#All],4,FALSE) -> £32,755.00 | D35: =VLOOKUP(A35,Таблица1[#All],5,FALSE) -> £58,960.00 | E35: =VLOOKUP(A35,Таблица2[#All],4,FALSE) -> £28,470.00 | F35: =VLOOKUP(A35,Таблица2[#All],5,FALSE) -> £51,245.00

Sheet Wages
A1: Country | B1: Wage_EURO_2021 | C1: Country | D1: Wage_EURO_2024 | E1: check | F1: check | J1: TIME | K1: 2021 | L1: 2024
A2: European Union - 27 countries (from 2020) | B2: 33915 | C2: European Union - 27 countries (from 2020) | D2: 39808 | E2: =IF(IFERROR(VLOOKUP(A2,$J$2:$L$28,2,FALSE),1)=1,FALSE,VLOOKUP(A2,$J$2:$L$28,2,FALSE)-B2) -> 0 | F2: =IF(IFERROR(VLOOKUP(A2,$J$2:$L$28,3,FALSE),1)=1,FALSE,VLOOKUP(A2,$J$2:$L$28,3,FALSE)-D2) -> 0 | J2: European Union - 27 countries (from 2020) | K2: 33915 | L2: 39808
A3: Euro area – 20 countries (2023-2025) | B3: 37711 | C3: Euro area – 20 countries (2023-2025) | D3: 43512 | E3: =IF(IFERROR(VLOOKUP(A3,$J$2:$L$28,2,FALSE),1)=1,FALSE,VLOOKUP(A3,$J$2:$L$28,2,FALSE)-B3) -> FALSE | F3: =IF(IFERROR(VLOOKUP(A3,$J$2:$L$28,3,FALSE),1)=1,FALSE,VLOOKUP(A3,$J$2:$L$28,3,FALSE)-D3) -> FALSE | J3: Belgium | K3: 49706 | L3: 59632
A4: Belgium | B4: 49706 | C4: Belgium | D4: 59632 | E4: =IF(IFERROR(VLOOKUP(A4,$J$2:$L$28,2,FALSE),1)=1,FALSE,VLOOKUP(A4,$J$2:$L$28,2,FALSE)-B4) -> 0 | F4: =IF(IFERROR(VLOOKUP(A4,$J$2:$L$28,3,FALSE),1)=1,FALSE,VLOOKUP(A4,$J$2:$L$28,3,FALSE)-D4) -> 0 | J4: Bulgaria | K4: 10345 | L4: 15387
A5: Bulgaria | B5: 10345 | C5: Bulgaria | D5: 15387 | E5: =IF(IFERROR(VLOOKUP(A5,$J$2:$L$28,2,FALSE),1)=1,FALSE,VLOOKUP(A5,$J$2:$L$28,2,FALSE)-B5) -> 0 | F5: =IF(IFERROR(VLOOKUP(A5,$J$2:$L$28,3,FALSE),1)=1,FALSE,VLOOKUP(A5,$J$2:$L$28,3,FALSE)-D5) -> 0 | J5: Czechia | K5: 18875 | L5: 23998
A6: Czechia | B6: 18875 | C6: Czechia | D6: 23998 | E6: =IF(IFERROR(VLOOKUP(A6,$J$2:$L$28,2,FALSE),1)=1,FALSE,VLOOKUP(A6,$J$2:$L$28,2,FALSE)-B6) -> 0 | F6: =IF(IFERROR(VLOOKUP(A6,$J$2:$L$28,3,FALSE),1)=1,FALSE,VLOOKUP(A6,$J$2:$L$28,3,FALSE)-D6) -> 0 | J6: Denmark | K6: 63043 | L6: 71565
A7: Denmark | B7: 63043 | C7: Denmark | D7: 71565 | E7: =IF(IFERROR(VLOOKUP(A7,$J$2:$L$28,2,FALSE),1)=1,FALSE,VLOOKUP(A7,$J$2:$L$28,2,FALSE)-B7) -> 0 | F7: =IF(IFERROR(VLOOKUP(A7,$J$2:$L$28,3,FALSE),1)=1,FALSE,VLOOKUP(A7,$J$2:$L$28,3,FALSE)-D7) -> 0 | J7: Germany | K7: 45718 | L7: 53791
A8: Germany | B8: 45718 | C8: Germany | D8: 53791 | E8: =IF(IFERROR(VLOOKUP(A8,$J$2:$L$28,2,FALSE),1)=1,FALSE,VLOOKUP(A8,$J$2:$L$28,2,FALSE)-B8) -> 0 | F8: =IF(IFERROR(VLOOKUP(A8,$J$2:$L$28,3,FALSE),1)=1,FALSE,VLOOKUP(A8,$J$2:$L$28,3,FALSE)-D8) -> 0 | J8: Estonia | K8: 21146 | L8: 26546
A9: Estonia | B9: 21146 | C9: Estonia | D9: 26546 | E9: =IF(IFERROR(VLOOKUP(A9,$J$2:$L$28,2,FALSE),1)=1,FALSE,VLOOKUP(A9,$J$2:$L$28,2,FALSE)-B9) -> 0 | F9: =IF(IFERROR(VLOOKUP(A9,$J$2:$L$28,3,FALSE),1)=1,FALSE,VLOOKUP(A9,$J$2:$L$28,3,FALSE)-D9) -> 0 | J9: Ireland | K9: 52638 | L9: 61051
A10: Ireland | B10: 52638 | C10: Ireland | D10: 61051 | E10: =IF(IFERROR(VLOOKUP(A10,$J$2:$L$28,2,FALSE),1)=1,FALSE,VLOOKUP(A10,$J$2:$L$28,2,FALSE)-B10) -> 0 | F10: =IF(IFERROR(VLOOKUP(A10,$J$2:$L$28,3,FALSE),1)=1,FALSE,VLOOKUP(A10,$J$2:$L$28,3,FALSE)-D10) -> 0 | J10: Greece | K10: 16018 | L10: 17954
A11: Greece | B11: 16018 | C11: Greece | D11: 17954 | E11: =IF(IFERROR(VLOOKUP(A11,$J$2:$L$28,2,FALSE),1)=1,FALSE,VLOOKUP(A11,$J$2:$L$28,2,FALSE)-B11) -> 0 | F11: =IF(IFERROR(VLOOKUP(A11,$J$2:$L$28,3,FALSE),1)=1,FALSE,VLOOKUP(A11,$J$2:$L$28,3,FALSE)-D11) -> 0 | J11: Spain | K11: 29383 | L11: 33700
A12: Spain | B12: 29383 | C12: Spain | D12: 33700 | E12: =IF(IFERROR(VLOOKUP(A12,$J$2:$L$28,2,FALSE),1)=1,FALSE,VLOOKUP(A12,$J$2:$L$28,2,FALSE)-B12) -> 0 | F12: =IF(IFERROR(VLOOKUP(A12,$J$2:$L$28,3,FALSE),1)=1,FALSE,VLOOKUP(A12,$J$2:$L$28,3,FALSE)-D12) -> 0 | J12: France | K12: 38861 | L12: 43790
A13: France | B13: 38861 | C13: France | D13: 43790 | E13: =IF(IFERROR(VLOOKUP(A13,$J$2:$L$28,2,FALSE),1)=1,FALSE,VLOOKUP(A13,$J$2:$L$28,2,FALSE)-B13) -> 0 | F13: =IF(IFERROR(VLOOKUP(A13,$J$2:$L$28,3,FALSE),1)=1,FALSE,VLOOKUP(A13,$J$2:$L$28,3,FALSE)-D13) -> 0 | J13: Croatia | K13: 17008 | L13: 23446
... A28: Finland | B28: 45351 | C28: Finland | D28: 49428 | E28: =IF(IFERROR(VLOOKUP(A28,$J$2:$L$28,2,FALSE),1)=1,FALSE,VLOOKUP(A28,$J$2:$L$28,2,FALSE)-B28) -> 0 | F28: =IF(IFERROR(VLOOKUP(A28,$J$2:$L$28,3,FALSE),1)=1,FALSE,VLOOKUP(A28,$J$2:$L$28,3,FALSE)-D28) -> 0 | J28: Sweden | K28: 47301 | L28: 46525
A29: Sweden | B29: 47301 | C29: Sweden | D29: 46525 | E29: =IF(IFERROR(VLOOKUP(A29,$J$2:$L$28,2,FALSE),1)=1,FALSE,VLOOKUP(A29,$J$2:$L$28,2,FALSE)-B29) -> 0 | F29: =IF(IFERROR(VLOOKUP(A29,$J$2:$L$28,3,FALSE),1)=1,FALSE,VLOOKUP(A29,$J$2:$L$28,3,FALSE)-D29) -> 0

Sheet Wage to tresholds
A1: Country | B1: Wage_EURO_2021 | C1: Wage_EURO_2024 | D1: Tresholds_2021 | E1: Treshold_2025 | F1: Wage_POUNDS_2021 | G1: WAGE_POUNDS_2025 | H1: wage/tau_2021 | I1: wage/tau_2025
A4: Belgium | B4: 49706 | C4: 59632 | D4: 27295 | E4: 28470 | F4: =B4*'2021-2022'!$C$15 -> 44029.475 | G4: =C4*'2025-26'!$C$16 -> 50582.725 | H4: =F4/D4 -> 1.6130967 | I4: =G4/E4 -> 1.7767027
A5: Bulgaria | B5: 10345 | C5: 15387 | D5: 10920 | E5: 11390 | F5: =B5*'2021-2022'!$C$15 -> 9163.5803 | G5: =C5*'2025-26'!$C$16 -> 13051.992 | H5: =F5/D5 -> 0.83915571 | I5: =G5/E5 -> 1.1459168
A6: Czechia | B6: 18875 | C6: 23998 | D6: 16380 | E6: 17085 | F6: =B6*'2021-2022'!$C$15 -> 16719.437 | G6: =C6*'2025-26'!$C$16 -> 20356.256 | H6: =F6/D6 -> 1.0207227 | I6: =G6/E6 -> 1.1914694
A7: Denmark | B7: 63043 | C7: 71565 | D7: 32755 | E7: 28470 | F7: =B7*'2021-2022'!$C$15 -> 55843.363 | G7: =C7*'2025-26'!$C$16 -> 60704.868 | H7: =F7/D7 -> 1.7048806 | I7: =G7/E7 -> 2.1322398
A8: Germany | B8: 45718 | C8: 53791 | D8: 27295 | E8: 28470 | F8: =B8*'2021-2022'!$C$15 -> 40496.913 | G8: =C8*'2025-26'!$C$16 -> 45628.108 | H8: =F8/D8 -> 1.4836751 | I8: =G8/E8 -> 1.6026733
A9: Estonia | B9: 21146 | C9: 26546 | D9: 21840 | E9: 22780 | F9: =B9*'2021-2022'!$C$15 -> 18731.085 | G9: =C9*'2025-26'!$C$16 -> 22517.591 | H9: =F9/D9 -> 0.85765039 | I9: =G9/E9 -> 0.98848075
A10: Ireland
A11: Greece | B11: 16018 | C11: 17954 | D11: 21840 | E11: 17085 | F11: =B11*'2021-2022'!$C$15 -> 14188.712 | G11: =C11*'2025-26'!$C$16 -> 15229.445 | H11: =F11/D11 -> 0.64966632 | I11: =G11/E11 -> 0.89139272
A12: Spain | B12: 29383 | C12: 33700 | D12: 21840 | E12: 22780 | F12: =B12*'2021-2022'!$C$15 -> 26027.403 | G12: =C12*'2025-26'!$C$16 -> 28585.958 | H12: =F12/D12 -> 1.1917309 | I12: =G12/E12 -> 1.2548708
A13: France | B13: 38861 | C13: 43790 | D13: 27295 | E13: 22780 | F13: =B13*'2021-2022'!$C$15 -> 34422.996 | G13: =C13*'2025-26'!$C$16 -> 37144.78 | H13: =F13/D13 -> 1.2611466 | I13: =G13/E13 -> 1.6305874
A14: Croatia | B14: 17008 | C14: 23446 | D14: 16380 | E14: 17085 | F14: =B14*'2021-2022'!$C$15 -> 15065.652 | G14: =C14*'2025-26'!$C$16 -> 19888.023 | H14: =F14/D14 -> 0.919759 | I14: =G14/E14 -> 1.1640634
A15: Italy | B15: 30719 | C15: 33523 | D15: 21840 | E15: 22780 | F15: =B15*'2021-2022'!$C$15 -> 27210.829 | G15: =C15*'2025-26'!$C$16 -> 28435.818 | H15: =F15/D15 -> 1.2459171 | I15: =G15/E15 -> 1.24828
A16: Cyprus | B16: 22197 | C16: 27611 | D16: 21840 | E16: 22780 | F16: =B16*'2021-2022'!$C$15 -> 19662.058 | G16: =C16*'2025-26'!$C$16 -> 23420.976 | H16: =F16/D16 -> 0.90027739 | I16: =G16/E16 -> 1.0281376
A17: Latvia | B17: 17018 | C17: 22262 | D17: 16380 | E17: 17085 | F17: =B17*'2021-2022'!$C$15 -> 15074.51 | G17: =C17*'2025-26'!$C$16 -> 18883.697 | H17: =F17/D17 -> 0.92029978 | I17: =G17/E17 -> 1.1052793
A18: Lithuania | B18: 21719 | C18: 29104 | D18: 16380 | E18: 17085 | F18: =B18*'2021-2022'!$C$15 -> 19238.647 | G18: =C18*'2025-26'!$C$16 -> 24687.41 | H18: =F18/D18 -> 1.1745206 | I18: =G18/E18 -> 1.4449757
A19: Luxembourg | B19: 71564 | C19: 82969 | D19: 27295 | E19: 28470 | F19: =B19*'2021-2022'!$C$15 -> 63391.248 | G19: =C19*'2025-26'!$C$16 -> 70378.288 | H19: =F19/D19 -> 2.3224491 | I19: =G19/E19 -> 2.4720157
A20: Hungary | B20: 13234 | C20: 18461 | D20: 16380 | E20: 17085 | F20: =B20*'2021-2022'!$C$15 -> 11722.651 | G20: =C20*'2025-26'!$C$16 -> 15659.506 | H20: =F20/D20 -> 0.71566854 | I20: =G20/E20 -> 0.91656461
A21: Malta | B21: 28329 | C21: 33499 | D21: 21840 | E21: 22780 | F21: =B21*'2021-2022'!$C$15 -> 25093.772 | G21: =C21*'2025-26'!$C$16 -> 28415.46 | H21: =F21/D21 -> 1.1489822 | I21: =G21/E21 -> 1.2473863
A22: Austria | B22: 48166 | C22: 58600 | D22: 27295 | E22: 28470 | F22: =B22*'2021-2022'!$C$15 -> 42665.346 | G22: =C22*'2025-26'!$C$16 -> 49707.333 | H22: =F22/D22 -> 1.5631195 | I22: =G22/E22 -> 1.7459548
... A29: Sweden | B29: 47301 | C29: 46525 | D29: 27295 | E29: 28470 | F29: =B29*'2021-2022'!$C$15 -> 41899.131 | G29: =C29*'2025-26'!$C$16 -> 39464.738 | H29: =F29/D29 -> 1.5350479 | I29: =G29/E29 -> 1.3861868
A31: wage/tau_2021 | B31: wage/tau_2025 | D31: Number of countries below the treshold in 2021 | F31: 10
A32: 0.64966632 | B32: 0.89139272 | D32: Number of countries below the treshold in 2025 | F32: 2
A33: 0.71566854 | B33: 0.91656461
A34: 0.76282458 | B34: 1.0548362
A35: 0.80512711 | B35: 1.2321814
A36: 0.83915571 | B36: 1.1459168
A37: 0.85765039 | B37: 0.98848075
A38: 0.87833523 | B38: 1.0072231
A39: 0.90027739 | B39: 1.0281376
A40: 0.919759 | B40: 1.1640634
A41: 0.92029978 | B41: 1.1052793
A42: 1.0207227 | B42: 1.1914694
A43: 1.0743951 | B43: 1.5719771
A44: 1.1489822 | B44: 1.2473863
... A56: 2.3224491 | B56: 2.4720157
