Workbook

Sheet aggregate_level
J1: Repayment schedule with an income of 20000 pounds
A2: Starting parameters | E2: Starting salary | F2: PV loan | G2: k | H2: Elasticity | J2: Year | K2: Income | L2: raw repayment | M2: Opening balance | N2: actual repayment | O2: discounted payment | P2: Closing balance
A3: L | B3: 9250 | E3: 20000 | F3: =MAX(SUM(O3:O32),1) -> 2366.6928 | G3: =LN($B$4)-LN(F3) -> 2.2385988 | H3: =-$B$10/G3 -> 0.48244465 | J3: 1 | K3: =$E$3*(1+$B$7)^(J3-1) -> 20000 | L3: =$B$5*MAX(0,K3-$B$6) -> 0 | M3: =$B$3 -> 9250 | N3: =MIN(L3,M3) -> 0 | O3: =N3/(1+$B$8)^J3 -> 0 | P3: =M3-N3 -> 9250
A4: Ppost | B4: 22200 | E4: 26000 | F4: =MAX(SUM(O37:O66),1) -> 5835.482 | G4: =LN($B$4)-LN(F4) -> 1.3361354 | H4: =-$B$10/G4 -> 0.8083013 | J4: =J3+1 -> 2 | K4: =$E$3*(1+$B$7)^(J4-1) -> 20400 | L4: =$B$5*MAX(0,K4-$B$6) -> 0 | M4: =P3 -> 9250 | N4: =IF(M4<=0,0,MIN(L4,M4)) -> 0 | O4: =N4/(1+$B$8)^J4 -> 0 | P4: =MAX(0,M4-N4) -> 9250
A5: alpha | B5: 0.09 | E5: 32000 | F5: =MAX(SUM(O72:O101),1) -> 7435.2478 | G5: =LN($B$4)-LN(F5) -> 1.0938604 | H5: =-$B$10/G5 -> 0.98732892 | J5: =J4+1 -> 3 | K5: =$E$3*(1+$B$7)^(J5-1) -> 20808 | L5: =$B$5*MAX(0,K5-$B$6) -> 0 | M5: =P4 -> 9250 | N5: =IF(M5<=0,0,MIN(L5,M5)) -> 0 | O5: =N5/(1+$B$8)^J5 -> 0 | P5: =MAX(0,M5-N5) -> 9250
A6: tau | B6: 27295 | E6: 35000 | F6: =MAX(SUM(O107:O137),1) -> 7822.4386 | G6: =LN($B$4)-LN(F6) -> 1.0430959 | H6: =-$B$10/G6 -> 1.0353793 | J6: =J5+1 -> 4 | K6: =$E$3*(1+$B$7)^(J6-1) -> 21224.16 | L6: =$B$5*MAX(0,K6-$B$6) -> 0 | M6: =P5 -> 9250 | N6: =IF(M6<=0,0,MIN(L6,M6)) -> 0 | O6: =N6/(1+$B$8)^J6 -> 0 | P6: =MAX(0,M6-N6) -> 9250
A7: g | B7: 0.02 | E7: 42000 | F7: =MAX(SUM(O142:O172),1) -> 8301.8075 | G7: =LN($B$4)-LN(F7) -> 0.98361902 | H7: =-$B$10/G7 -> 1.0979861 | J7: =J6+1 -> 5 | K7: =$E$3*(1+$B$7)^(J7-1) -> 21648.643 | L7: =$B$5*MAX(0,K7-$B$6) -> 0 | M7: =P6 -> 9250 | N7: =IF(M7<=0,0,MIN(L7,M7)) -> 0 | O7: =N7/(1+$B$8)^J7 -> 0 | P7: =MAX(0,M7-N7) -> 9250
A8: r | B8: 0.03 | E8: 50000 | F8: =MAX(SUM(O177:O207),1) -> 8547.9214 | G8: =LN($B$4)-LN(F8) -> 0.95440414 | H8: =-$B$10/G8 -> 1.1315961 | J8: =J7+1 -> 6 | K8: =$E$3*(1+$B$7)^(J8-1) -> 22081.616 | L8: =$B$5*MAX(0,K8-$B$6) -> 0 | M8: =P7 -> 9250 | N8: =IF(M8<=0,0,MIN(L8,M8)) -> 0 | O8: =N8/(1+$B$8)^J8 -> 0 | P8: =MAX(0,M8-N8) -> 9250
A9: T | B9: 30 | J9: =J8+1 -> 7 | K9: =$E$3*(1+$B$7)^(J9-1) -> 22523.248 | L9: =$B$5*MAX(0,K9-$B$6) -> 0 | M9: =P8 -> 9250 | N9: =IF(M9<=0,0,MIN(L9,M9)) -> 0 | O9: =N9/(1+$B$8)^J9 -> 0 | P9: =MAX(0,M9-N9) -> 9250
A10: beta_pooled | B10: -1.08 | J10: =J9+1 -> 8 | K10: =$E$3*(1+$B$7)^(J10-1) -> 22973.713 | L10: =$B$5*MAX(0,K10-$B$6) -> 0 | M10: =P9 -> 9250 | N10: =IF(M10<=0,0,MIN(L10,M10)) -> 0 | O10: =N10/(1+$B$8)^J10 -> 0 | P10: =MAX(0,M10-N10) -> 9250
J11: =J10+1 -> 9 | K11: =$E$3*(1+$B$7)^(J11-1) -> 23433.188 | L11: =$B$5*MAX(0,K11-$B$6) -> 0 | M11: =P10 -> 9250 | N11: =IF(M11<=0,0,MIN(L11,M11)) -> 0 | O11: =N11/(1+$B$8)^J11 -> 0 | P11: =MAX(0,M11-N11) -> 9250
J12: =J11+1 -> 10 | K12: =$E$3*(1+$B$7)^(J12-1) -> 23901.851 | L12: =$B$5*MAX(0,K12-$B$6) -> 0 | M12: =P11 -> 9250 | N12: =IF(M12<=0,0,MIN(L12,M12)) -> 0 | O12: =N12/(1+$B$8)^J12 -> 0 | P12: =MAX(0,M12-N12) -> 9250
J13: =J12+1 -> 11 | K13: =$E$3*(1+$B$7)^(J13-1) -> 24379.888 | L13: =$B$5*MAX(0,K13-$B$6) -> 0 | M13: =P12 -> 9250 | N13: =IF(M13<=0,0,MIN(L13,M13)) -> 0 | O13: =N13/(1+$B$8)^J13 -> 0 | P13: =MAX(0,M13-N13) -> 9250
J14: =J13+1 -> 12 | K14: =$E$3*(1+$B$7)^(J14-1) -> 24867.486 | L14: =$B$5*MAX(0,K14-$B$6) -> 0 | M14: =P13 -> 9250 | N14: =IF(M14<=0,0,MIN(L14,M14)) -> 0 | O14: =N14/(1+$B$8)^J14 -> 0 | P14: =MAX(0,M14-N14) -> 9250
J15: =J14+1 -> 13 | K15: =$E$3*(1+$B$7)^(J15-1) -> 25364.836 | L15: =$B$5*MAX(0,K15-$B$6) -> 0 | M15: =P14 -> 9250 | N15: =IF(M15<=0,0,MIN(L15,M15)) -> 0 | O15: =N15/(1+$B$8)^J15 -> 0 | P15: =MAX(0,M15-N15) -> 9250
J16: =J15+1 -> 14 | K16: =$E$3*(1+$B$7)^(J16-1) -> 25872.133 | L16: =$B$5*MAX(0,K16-$B$6) -> 0 | M16: =P15 -> 9250 | N16: =IF(M16<=0,0,MIN(L16,M16)) -> 0 | O16: =N16/(1+$B$8)^J16 -> 0 | P16: =MAX(0,M16-N16) -> 9250
J17: =J16+1 -> 15 | K17: =$E$3*(1+$B$7)^(J17-1) -> 26389.575 | L17: =$B$5*MAX(0,K17-$B$6) -> 0 | M17: =P16 -> 9250 | N17: =IF(M17<=0,0,MIN(L17,M17)) -> 0 | O17: =N17/(1+$B$8)^J17 -> 0 | P17: =MAX(0,M17-N17) -> 9250
J18: =J17+1 -> 16 | K18: =$E$3*(1+$B$7)^(J18-1) -> 26917.367 | L18: =$B$5*MAX(0,K18-$B$6) -> 0 | M18: =P17 -> 9250 | N18: =IF(M18<=0,0,MIN(L18,M18)) -> 0 | O18: =N18/(1+$B$8)^J18 -> 0 | P18: =MAX(0,M18-N18) -> 9250
J19: =J18+1 -> 17 | K19: =$E$3*(1+$B$7)^(J19-1) -> 27455.714 | L19: =$B$5*MAX(0,K19-$B$6) -> 14.464269 | M19: =P18 -> 9250 | N19: =IF(M19<=0,0,MIN(L19,M19)) -> 14.464269 | O19: =N19/(1+$B$8)^J19 -> 8.7511207 | P19: =MAX(0,M19-N19) -> 9235.5357
J20: =J19+1 -> 18 | K20: =$E$3*(1+$B$7)^(J20-1) -> 28004.828 | L20: =$B$5*MAX(0,K20-$B$6) -> 63.884555 | M20: =P19 -> 9235.5357 | N20: =IF(M20<=0,0,MIN(L20,M20)) -> 63.884555 | O20: =N20/(1+$B$8)^J20 -> 37.525443 | P20: =MAX(0,M20-N20) -> 9171.6512
J21: =J20+1 -> 19 | K21: =$E$3*(1+$B$7)^(J21-1) -> 28564.925 | L21: =$B$5*MAX(0,K21-$B$6) -> 114.29325 | M21: =P20 -> 9171.6512 | N21: =IF(M21<=0,0,MIN(L21,M21)) -> 114.29325 | O21: =N21/(1+$B$8)^J21 -> 65.179841 | P21: =MAX(0,M21-N21) -> 9057.3579
J22: =J21+1 -> 20 | K22: =$E$3*(1+$B$7)^(J22-1) -> 29136.223 | L22: =$B$5*MAX(0,K22-$B$6) -> 165.71011 | M22: =P21 -> 9057.3579 | N22: =IF(M22<=0,0,MIN(L22,M22)) -> 165.71011 | O22: =N22/(1+$B$8)^J22 -> 91.74967 | P22: =MAX(0,M22-N22) -> 8891.6478
... J32: =J31+1 -> 30 | K32: =$E$3*(1+$B$7)^(J32-1) -> 35516.894 | L32: =$B$5*MAX(0,K32-$B$6) -> 739.97044 | M32: =P31 -> 4909.8413 | N32: =IF(M32<=0,0,MIN(L32,M32)) -> 739.97044 | O32: =N32/(1+$B$8)^J32 -> 304.85802 | P32: =MAX(0,M32-N32) -> 4169.8709
K33: =$E$3*(1+$B$7)^(J33-1) -> 19607.843 | L33: =$B$5*MAX(0,K33-$B$6) -> 0 | M33: =P32 -> 4169.8709 | N33: =IF(M33<=0,0,MIN(L33,M33)) -> 0 | O33: =N33/(1+$B$8)^J33 -> 0 | P33: =MAX(0,M33-N33) -> 4169.8709
J35: Repayment schedule with an income of 26000 pounds
J36: Year | K36: Income | L36: raw repayment | M36: Opening balance | N36: actual repayment | O36: discounted payment | P36: Closing balance
J37: 1 | K37: =$E$4*(1+$B$7)^(J37-1) -> 26000 | L37: =$B$5*MAX(0,K37-$B$6) -> 0 | M37: =$B$3 -> 9250 | N37: =MIN(L37,M37) -> 0 | O37: =N37/(1+$B$8)^J37 -> 0 | P37: =M37-N37 -> 9250
J38: =J37+1 -> 2 | K38: =$E$4*(1+$B$7)^(J38-1) -> 26520 | L38: =$B$5*MAX(0,K38-$B$6) -> 0 | M38: =P37 -> 9250 | N38: =MIN(L38,M38) -> 0 | O38: =N38/(1+$B$8)^J38 -> 0 | P38: =M38-N38 -> 9250
J39: =J38+1 -> 3 | K39: =$E$4*(1+$B$7)^(J39-1) -> 27050.4 | L39: =$B$5*MAX(0,K39-$B$6) -> 0 | M39: =P38 -> 9250 | N39: =MIN(L39,M39) -> 0 | O39: =N39/(1+$B$8)^J39 -> 0 | P39: =M39-N39 -> 9250
J40: =J39+1 -> 4 | K40: =$E$4*(1+$B$7)^(J40-1) -> 27591.408 | L40: =$B$5*MAX(0,K40-$B$6) -> 26.67672 | M40: =P39 -> 9250 | N40: =MIN(L40,M40) -> 26.67672 | O40: =N40/(1+$B$8)^J40 -> 23.70192 | P40: =M40-N40 -> 9223.3233
J41: =J40+1 -> 5 | K41: =$E$4*(1+$B$7)^(J41-1) -> 28143.236 | L41: =$B$5*MAX(0,K41-$B$6) -> 76.341254 | M41: =P40 -> 9223.3233 | N41: =MIN(L41,M41) -> 76.341254 | O41: =N41/(1+$B$8)^J41 -> 65.852637 | P41: =M41-N41 -> 9146.982
J42: =J41+1 -> 6 | K42: =$E$4*(1+$B$7)^(J42-1) -> 28706.101 | L42: =$B$5*MAX(0,K42-$B$6) -> 126.99908 | M42: =P41 -> 9146.982 | N42: =MIN(L42,M42) -> 126.99908 | O42: =N42/(1+$B$8)^J42 -> 106.35973 | P42: =M42-N42 -> 9019.9829
J43: =J42+1 -> 7 | K43: =$E$4*(1+$B$7)^(J43-1) -> 29280.223 | L43: =$B$5*MAX(0,K43-$B$6) -> 178.67006 | M43: =P42 -> 9019.9829 | N43: =MIN(L43,M43) -> 178.67006 | O43: =N43/(1+$B$8)^J43 -> 145.27511 | P43: =M43-N43 -> 8841.3129
J44: =J43+1 -> 8 | K44: =$E$4*(1+$B$7)^(J44-1) -> 29865.827 | L44: =$B$5*MAX(0,K44-$B$6) -> 231.37446 | M44: =P43 -> 8841.3129 | N44: =MIN(L44,M44) -> 231.37446 | O44: =N44/(1+$B$8)^J44 -> 182.64914 | P44: =M44-N44 -> 8609.9384
J45: =J44+1 -> 9 | K45: =$E$4*(1+$B$7)^(J45-1) -> 30463.144 | L45: =$B$5*MAX(0,K45-$B$6) -> 285.13295 | M45: =P44 -> 8609.9384 | N45: =MIN(L45,M45) -> 285.13295 | O45: =N45/(1+$B$8)^J45 -> 218.53067 | P45: =M45-N45 -> 8324.8055
J46: =J45+1 -> 10 | K46: =$E$4*(1+$B$7)^(J46-1) -> 31072.407 | L46: =$B$5*MAX(0,K46-$B$6) -> 339.96661 | M46: =P45 -> 8324.8055 | N46: =MIN(L46,M46) -> 339.96661 | O46: =N46/(1+$B$8)^J46 -> 252.96709 | P46: =M46-N46 -> 7984.8389
J47: =J46+1 -> 11 | K47: =$E$4*(1+$B$7)^(J47-1) -> 31693.855 | L47: =$B$5*MAX(0,K47-$B$6) -> 395.89694 | M47: =P46 -> 7984.8389 | N47: =MIN(L47,M47) -> 395.89694 | O47: =N47/(1+$B$8)^J47 -> 286.00437 | P47: =M47-N47 -> 7588.9419
J48: =J47+1 -> 12 | K48: =$E$4*(1+$B$7)^(J48-1) -> 32327.732 | L48: =$B$5*MAX(0,K48-$B$6) -> 452.94588 | M48: =P47 -> 7588.9419 | N48: =MIN(L48,M48) -> 452.94588 | O48: =N48/(1+$B$8)^J48 -> 317.68713 | P48: =M48-N48 -> 7135.996
J49: =J48+1 -> 13 | K49: =$E$4*(1+$B$7)^(J49-1) -> 32974.287 | L49: =$B$5*MAX(0,K49-$B$6) -> 511.1358 | M49: =P48 -> 7135.996 | N49: =MIN(L49,M49) -> 511.1358 | O49: =N49/(1+$B$8)^J49 -> 348.05861 | P49: =M49-N49 -> 6624.8602
... J66: =J65+1 -> 30 | K66: =$E$4*(1+$B$7)^(J66-1) -> 46171.962 | L66: =$B$5*MAX(0,K66-$B$6) -> 1698.9266 | M66: =P65 -> 0 | N66: =MIN(L66,M66) -> 0 | O66: =N66/(1+$B$8)^J66 -> 0 | P66: =M66-N66 -> 0
...

Sheet Country_PV
A1: Starting parameters | D1: Country | E1: Wage_EURO | F1: wage_gbp | G1: PV_loan | H1: k_i | I1: k_i from R | V1: Repayment schedule for Belgium
A2: L | B2: 9250 | D2: Belgium | E2: 59632 | F2: =E2*$B$4 -> 51283.52 | G2: =MAX(SUM(AA3:AA32),1) -> 8579.3385 | H2: =LN($B$3)-LN(G2) -> 0.95073548 | I2: 0.95073548 | V2: Year | W2: Income | X2: raw repayment | Y2: Opening balance | Z2: actual repayment | AA2: discounted payment | AB2: Closing balance
A3: Ppost | B3: 22200 | D3: Bulgaria | E3: 15387 | F3: =E3*$B$4 -> 13232.82 | G3: =MAX(SUM(P37:P66),1) -> 1 | H3: =LN($B$3)-LN(G3) -> 10.007848 | I3: 10.007848 | V3: 1 | W3: =$F$2*(1+$B$7)^(V3-1) -> 51283.52 | X3: =$B$5*MAX(0,W3-$B$6) -> 2158.9668 | Y3: =$B$2 -> 9250 | Z3: =MIN(X3,Y3) -> 2158.9668 | AA3: =Z3/(1+$B$8)^V3 -> 2096.0843 | AB3: =Y3-Z3 -> 7091.0332
A4: eur_gbp | B4: 0.86 | D4: Czechia | E4: 23998 | F4: =E4*$B$4 -> 20638.28 | G4: =MAX(SUM(P71:P100),1) -> 3021.0957 | H4: =LN($B$3)-LN(G4) -> 1.9944727 | I4: 1.9944727 | V4: =V3+1 -> 2 | W4: =$F$2*(1+$B$7)^(V4-1) -> 52309.19 | X4: =$B$5*MAX(0,W4-$B$6) -> 2251.2771 | Y4: =AB3 -> 7091.0332 | Z4: =IF(Y4<=0,0,MIN(X4,Y4)) -> 2251.2771 | AA4: =Z4/(1+$B$8)^V4 -> 2122.0446 | AB4: =MAX(0,Y4-Z4) -> 4839.7561
A5: alpha | B5: 0.09 | D5: Denmark | E5: 71565 | F5: =E5*$B$4 -> 61545.9 | G5: =MAX(SUM(X37:X66),1) -> 8724.5305 | H5: =LN($B$3)-LN(G5) -> 0.93395363 | I5: 0.93395363 | V5: =V4+1 -> 3 | W5: =$F$2*(1+$B$7)^(V5-1) -> 53355.374 | X5: =$B$5*MAX(0,W5-$B$6) -> 2345.4337 | Y5: =AB4 -> 4839.7561 | Z5: =IF(Y5<=0,0,MIN(X5,Y5)) -> 2345.4337 | AA5: =Z5/(1+$B$8)^V5 -> 2146.4041 | AB5: =MAX(0,Y5-Z5) -> 2494.3224
A6: tau | B6: 27295 | D6: Germany | E6: 53791 | F6: =E6*$B$4 -> 46260.26 | G6: =MAX(SUM(AF37:AF66),1) -> 8456.3829 | H6: =LN($B$3)-LN(G6) -> 0.96517076 | I6: 0.96517076 | V6: =V5+1 -> 4 | W6: =$F$2*(1+$B$7)^(V6-1) -> 54422.482 | X6: =$B$5*MAX(0,W6-$B$6) -> 2441.4734 | Y6: =AB5 -> 2494.3224 | Z6: =IF(Y6<=0,0,MIN(X6,Y6)) -> 2441.4734 | AA6: =Z6/(1+$B$8)^V6 -> 2169.2175 | AB6: =MAX(0,Y6-Z6) -> 52.849033
A7: g | B7: 0.02 | D7: Estonia | E7: 26546 | F7: =E7*$B$4 -> 22829.56 | G7: =MAX(SUM(AN37:AN66),1) -> 4804.714 | H7: =LN($B$3)-LN(G7) -> 1.5304948 | I7: 1.5304948 | V7: =V6+1 -> 5 | W7: =$F$2*(1+$B$7)^(V7-1) -> 55510.931 | X7: =$B$5*MAX(0,W7-$B$6) -> 2539.4338 | Y7: =AB6 -> 52.849033 | Z7: =IF(Y7<=0,0,MIN(X7,Y7)) -> 52.849033 | AA7: =Z7/(1+$B$8)^V7 -> 45.58804 | AB7: =MAX(0,Y7-Z7) -> 0
A8: r | B8: 0.03 | D8: Ireland | E8: 61051 | F8: =E8*$B$4 -> 52503.86 | G8: N/a | H8: N/a | V8: =V7+1 -> 6 | W8: =$F$2*(1+$B$7)^(V8-1) -> 56621.15 | X8: =$B$5*MAX(0,W8-$B$6) -> 2639.3535 | Y8: =AB7 -> 0 | Z8: =IF(Y8<=0,0,MIN(X8,Y8)) -> 0 | AA8: =Z8/(1+$B$8)^V8 -> 0 | AB8: =MAX(0,Y8-Z8) -> 0
A9: T | B9: 30 | D9: Greece | E9: 17954 | F9: =E9*$B$4 -> 15440.44 | G9: =MAX(SUM(X71:X100),1) -> 4.6283026 | H9: =LN($B$3)-LN(G9) -> 8.4756574 | I9: 8.4756574 | V9: =V8+1 -> 7 | W9: =$F$2*(1+$B$7)^(V9-1) -> 57753.573 | X9: =$B$5*MAX(0,W9-$B$6) -> 2741.2716 | Y9: =AB8 -> 0 | Z9: =IF(Y9<=0,0,MIN(X9,Y9)) -> 0 | AA9: =Z9/(1+$B$8)^V9 -> 0 | AB9: =MAX(0,Y9-Z9) -> 0
D10: Spain | E10: 33700 | F10: =E10*$B$4 -> 28982 | G10: =MAX(SUM(AF71:AF100),1) -> 6801.1286 | H10: =LN($B$3)-LN(G10) -> 1.1830037 | I10: 1.1830037 | V10: =V9+1 -> 8 | W10: =$F$2*(1+$B$7)^(V10-1) -> 58908.644 | X10: =$B$5*MAX(0,W10-$B$6) -> 2845.228 | Y10: =AB9 -> 0 | Z10: =IF(Y10<=0,0,MIN(X10,Y10)) -> 0 | AA10: =Z10/(1+$B$8)^V10 -> 0 | AB10: =MAX(0,Y10-Z10) -> 0
D11: France | E11: 43790 | F11: =E11*$B$4 -> 37659.4 | G11: =MAX(SUM(AN71:AN100),1) -> 8054.806 | H11: =LN($B$3)-LN(G11) -> 1.0138234 | I11: 1.0138234 | V11: =V10+1 -> 9 | W11: =$F$2*(1+$B$7)^(V11-1) -> 60086.817 | X11: =$B$5*MAX(0,W11-$B$6) -> 2951.2636 | Y11: =AB10 -> 0 | Z11: =IF(Y11<=0,0,MIN(X11,Y11)) -> 0 | AA11: =Z11/(1+$B$8)^V11 -> 0 | AB11: =MAX(0,Y11-Z11) -> 0
D12: Croatia | E12: 23446 | F12: =E12*$B$4 -> 20163.56 | G12: =MAX(SUM(P105:P134),1) -> 2527.4656 | H12: =LN($B$3)-LN(G12) -> 2.1728752 | I12: 2.1728752 | V12: =V11+1 -> 10 | W12: =$F$2*(1+$B$7)^(V12-1) -> 61288.554 | X12: =$B$5*MAX(0,W12-$B$6) -> 3059.4198 | Y12: =AB11 -> 0 | Z12: =IF(Y12<=0,0,MIN(X12,Y12)) -> 0 | AA12: =Z12/(1+$B$8)^V12 -> 0 | AB12: =MAX(0,Y12-Z12) -> 0
D13: Italy | E13: 33523 | F13: =E13*$B$4 -> 28829.78 | G13: =MAX(SUM(X105:X134),1) -> 6758.7787 | H13: =LN($B$3)-LN(G13) -> 1.1892501 | I13: 1.1892501 | V13: =V12+1 -> 11 | W13: =$F$2*(1+$B$7)^(V13-1) -> 62514.325 | X13: =$B$5*MAX(0,W13-$B$6) -> 3169.7392 | Y13: =AB12 -> 0 | Z13: =IF(Y13<=0,0,MIN(X13,Y13)) -> 0 | AA13: =Z13/(1+$B$8)^V13 -> 0 | AB13: =MAX(0,Y13-Z13) -> 0
D14: Cyprus | E14: 27611 | F14: =E14*$B$4 -> 23745.46 | G14: =MAX(SUM(AF105:AF134),1) -> 5095.4373 | H14: =LN($B$3)-LN(G14) -> 1.4717468 | I14: 1.4717468 | V14: =V13+1 -> 12 | W14: =$F$2*(1+$B$7)^(V14-1) -> 63764.611 | X14: =$B$5*MAX(0,W14-$B$6) -> 3282.265 | Y14: =AB13 -> 0 | Z14: =IF(Y14<=0,0,MIN(X14,Y14)) -> 0 | AA14: =Z14/(1+$B$8)^V14 -> 0 | AB14: =MAX(0,Y14-Z14) -> 0
D15: Latvia | E15: 22262 | F15: =E15*$B$4 -> 19145.32 | G15: =MAX(SUM(AN105:AN134),1) -> 1607.4555 | H15: =LN($B$3)-LN(G15) -> 2.6254398 | I15: 2.6254398 | V15: =V14+1 -> 13 | W15: =$F$2*(1+$B$7)^(V15-1) -> 65039.903 | X15: =$B$5*MAX(0,W15-$B$6) -> 3397.0413 | Y15: =AB14 -> 0 | Z15: =IF(Y15<=0,0,MIN(X15,Y15)) -> 0 | AA15: =Z15/(1+$B$8)^V15 -> 0 | AB15: =MAX(0,Y15-Z15) -> 0
D16: Lithuania | E16: 29104 | F16: =E16*$B$4 -> 25029.44 | G16: =MAX(SUM(P139:P168),1) -> 5513.5374 | H16: =LN($B$3)-LN(G16) -> 1.3928859 | I16: 1.3928859 | V16: =V15+1 -> 14 | W16: =$F$2*(1+$B$7)^(V16-1) -> 66340.702 | X16: =$B$5*MAX(0,W16-$B$6) -> 3514.1131 | Y16: =AB15 -> 0 | Z16: =IF(Y16<=0,0,MIN(X16,Y16)) -> 0 | AA16: =Z16/(1+$B$8)^V16 -> 0 | AB16: =MAX(0,Y16-Z16) -> 0
D17: Luxembourg | E17: 82969 | F17: =E17*$B$4 -> 71353.34 | G17: =MAX(SUM(X139:X168),1) -> 8798.4413 | H17: =LN($B$3)-LN(G17) -> 0.92551771 | I17: 0.92551771 | V17: =V16+1 -> 15 | W17: =$F$2*(1+$B$7)^(V17-1) -> 67667.516 | X17: =$B$5*MAX(0,W17-$B$6) -> 3633.5264 | Y17: =AB16 -> 0 | Z17: =IF(Y17<=0,0,MIN(X17,Y17)) -> 0 | AA17: =Z17/(1+$B$8)^V17 -> 0 | AB17: =MAX(0,Y17-Z17) -> 0
D18: Hungary | E18: 18461 | F18: =E18*$B$4 -> 15876.46 | G18: =MAX(SUM(AF139:AF168),1) -> 46.564213 | H18: =LN($B$3)-LN(G18) -> 6.1670153 | I18: 6.1670153 | V18: =V17+1 -> 16 | W18: =$F$2*(1+$B$7)^(V18-1) -> 69020.866 | X18: =$B$5*MAX(0,W18-$B$6) -> 3755.3279 | Y18: =AB17 -> 0 | Z18: =IF(Y18<=0,0,MIN(X18,Y18)) -> 0 | AA18: =Z18/(1+$B$8)^V18 -> 0 | AB18: =MAX(0,Y18-Z18) -> 0
D19: Malta | E19: 33499 | F19: =E19*$B$4 -> 28809.14 | G19: =MAX(SUM(AN139:AN168),1) -> 6752.8799 | H19: =LN($B$3)-LN(G19) -> 1.1901232 | I19: 1.1901232 | V19: =V18+1 -> 17 | W19: =$F$2*(1+$B$7)^(V19-1) -> 70401.283 | X19: =$B$5*MAX(0,W19-$B$6) -> 3879.5655 | Y19: =AB18 -> 0 | Z19: =IF(Y19<=0,0,MIN(X19,Y19)) -> 0 | AA19: =Z19/(1+$B$8)^V19 -> 0 | AB19: =MAX(0,Y19-Z19) -> 0
D20: Austria | E20: 58600 | F20: =E20*$B$4 -> 50396 | G20: =MAX(SUM(P173:P202),1) -> 8557.6144 | H20: =LN($B$3)-LN(G20) -> 0.95327083 | I20: 0.95327083 | V20: =V19+1 -> 18 | W20: =$F$2*(1+$B$7)^(V20-1) -> 71809.309 | X20: =$B$5*MAX(0,W20-$B$6) -> 4006.2878 | Y20: =AB19 -> 0 | Z20: =IF(Y20<=0,0,MIN(X20,Y20)) -> 0 | AA20: =Z20/(1+$B$8)^V20 -> 0 | AB20: =MAX(0,Y20-Z20) -> 0
D21: Poland | E21: 21246 | F21: =E21*$B$4 -> 18271.56 | G21: =MAX(SUM(X173:X202),1) -> 980.81535 | H21: =LN($B$3)-LN(G21) -> 3.1194633 | I21: 3.1194633 | V21: =V20+1 -> 19 | W21: =$F$2*(1+$B$7)^(V21-1) -> 73245.495 | X21: =$B$5*MAX(0,W21-$B$6) -> 4135.5446 | Y21: =AB20 -> 0 | Z21: =IF(Y21<=0,0,MIN(X21,Y21)) -> 0 | AA21: =Z21/(1+$B$8)^V21 -> 0 | AB21: =MAX(0,Y21-Z21) -> 0
D22: Portugal | E22: 24818 | F22: =E22*$B$4 -> 21343.48 | G22: =MAX(SUM(P241:P270),1) -> 3836.3558 | H22: =LN($B$3)-LN(G22) -> 1.7555694 | I22: 1.7555694 | V22: =V21+1 -> 20 | W22: =$F$2*(1+$B$7)^(V22-1) -> 74710.405 | X22: =$B$5*MAX(0,W22-$B$6) -> 4267.3864 | Y22: =AB21 -> 0 | Z22: =IF(Y22<=0,0,MIN(X22,Y22)) -> 0 | AA22: =Z22/(1+$B$8)^V22 -> 0 | AB22: =MAX(0,Y22-Z22) -> 0
D23: Romania | E23: 21108 | F23: =E23*$B$4 -> 18152.88 | G23: =MAX(SUM(AN173:AN202),1) -> 907.66157 | H23: =LN($B$3)-LN(G23) -> 3.196976 | I23: 3.196976 | V23: =V22+1 -> 21 | W23: =$F$2*(1+$B$7)^(V23-1) -> 76204.613 | X23: =$B$5*MAX(0,W23-$B$6) -> 4401.8652 | Y23: =AB22 -> 0 | Z23: =IF(Y23<=0,0,MIN(X23,Y23)) -> 0 | AA23: =Z23/(1+$B$8)^V23 -> 0 | AB23: =MAX(0,Y23-Z23) -> 0
D24: Slovenia | E24: 35133 | F24: =E24*$B$4 -> 30214.38 | G24: =MAX(SUM(P207:P236),1) -> 7098.4662 | H24: =LN($B$3)-LN(G24) -> 1.1402136 | I24: 1.1402136 | V24: =V23+1 -> 22 | W24: =$F$2*(1+$B$7)^(V24-1) -> 77728.705 | X24: =$B$5*MAX(0,W24-$B$6) -> 4539.0335 | Y24: =AB23 -> 0 | Z24: =IF(Y24<=0,0,MIN(X24,Y24)) -> 0 | AA24: =Z24/(1+$B$8)^V24 -> 0 | AB24: =MAX(0,Y24-Z24) -> 0
D25: Slovakia | E25: 20287 | F25: =E25*$B$4 -> 17446.82 | G25: =MAX(SUM(X207:X236),1) -> 527.15205 | H25: =LN($B$3)-LN(G25) -> 3.7403585 | I25: 3.7403585 | V25: =V24+1 -> 23 | W25: =$F$2*(1+$B$7)^(V25-1) -> 79283.279 | X25: =$B$5*MAX(0,W25-$B$6) -> 4678.9451 | Y25: =AB24 -> 0 | Z25: =IF(Y25<=0,0,MIN(X25,Y25)) -> 0 | AA25: =Z25/(1+$B$8)^V25 -> 0 | AB25: =MAX(0,Y25-Z25) -> 0
D26: Finland | E26: 49428 | F26: =E26*$B$4 -> 42508.08 | G26: =MAX(SUM(AF207:AF236),1) -> 8323.75 | H26: =LN($B$3)-LN(G26) -> 0.98097942 | I26: 0.98097942 | V26: =V25+1 -> 24 | W26: =$F$2*(1+$B$7)^(V26-1) -> 80868.945 | X26: =$B$5*MAX(0,W26-$B$6) -> 4821.655 | Y26: =AB25 -> 0 | Z26: =IF(Y26<=0,0,MIN(X26,Y26)) -> 0 | AA26: =Z26/(1+$B$8)^V26 -> 0 | AB26: =MAX(0,Y26-Z26) -> 0
D27: Sweden | E27: 46525 | F27: =E27*$B$4 -> 40011.5 | G27: =MAX(SUM(AN207:AN236),1) -> 8202.1973 | H27: =LN($B$3)-LN(G27) -> 0.99569021 | I27: 0.99569021 | V27: =V26+1 -> 25 | W27: =$F$2*(1+$B$7)^(V27-1) -> 82486.324 | X27: =$B$5*MAX(0,W27-$B$6) -> 4967.2191 | Y27: =AB26 -> 0 | Z27: =IF(Y27<=0,0,MIN(X27,Y27)) -> 0 | AA27: =Z27/(1+$B$8)^V27 -> 0 | AB27: =MAX(0,Y27-Z27) -> 0
V28: =V27+1 -> 26 | W28: =$F$2*(1+$B$7)^(V28-1) -> 84136.05 | X28: =$B$5*MAX(0,W28-$B$6) -> 5115.6945 | Y28: =AB27 -> 0 | Z28: =IF(Y28<=0,0,MIN(X28,Y28)) -> 0 | AA28: =Z28/(1+$B$8)^V28 -> 0 | AB28: =MAX(0,Y28-Z28) -> 0
V29: =V28+1 -> 27 | W29: =$F$2*(1+$B$7)^(V29-1) -> 85818.771 | X29: =$B$5*MAX(0,W29-$B$6) -> 5267.1394 | Y29: =AB28 -> 0 | Z29: =IF(Y29<=0,0,MIN(X29,Y29)) -> 0 | AA29: =Z29/(1+$B$8)^V29 -> 0 | AB29: =MAX(0,Y29-Z29) -> 0
V30: =V29+1 -> 28 | W30: =$F$2*(1+$B$7)^(V30-1) -> 87535.147 | X30: =$B$5*MAX(0,W30-$B$6) -> 5421.6132 | Y30: =AB29 -> 0 | Z30: =IF(Y30<=0,0,MIN(X30,Y30)) -> 0 | AA30: =Z30/(1+$B$8)^V30 -> 0 | AB30: =MAX(0,Y30-Z30) -> 0
V31: =V30+1 -> 29 | W31: =$F$2*(1+$B$7)^(V31-1) -> 89285.85 | X31: =$B$5*MAX(0,W31-$B$6) -> 5579.1765 | Y31: =AB30 -> 0 | Z31: =IF(Y31<=0,0,MIN(X31,Y31)) -> 0 | AA31: =Z31/(1+$B$8)^V31 -> 0 | AB31: =MAX(0,Y31-Z31) -> 0
V32: =V31+1 -> 30 | W32: =$F$2*(1+$B$7)^(V32-1) -> 91071.567 | X32: =$B$5*MAX(0,W32-$B$6) -> 5739.891 | Y32: =AB31 -> 0 | Z32: =IF(Y32<=0,0,MIN(X32,Y32)) -> 0 | AA32: =Z32/(1+$B$8)^V32 -> 0 | AB32: =MAX(0,Y32-Z32) -> 0
K35: Repayment schedule for Bulgaria | S35: Repayment schedule for Denmark | AA35: Repayment schedule for Germany | AI35: Repayment schedule for Estonia
K36: Year | L36: Income | M36: raw repayment | N36: Opening balance | O36: actual repayment | P36: discounted payment | Q36: Closing balance | S36: Year | T36: Income | U36: raw repayment | V36: Opening balance | W36: actual repayment | X36: discounted payment | Y36: Closing balance | AA36: Year | AB36: Income | AC36: raw repayment | AD36: Opening balance | AE36: actual repayment | AF36: discounted payment | AG36: Closing balance | AI36: Year | AJ36: Income | AK36: raw repayment | AL36: Opening balance | AM36: actual repayment | AN36: discounted payment | AO36: Closing balance
K37: 1 | L37: =$F$3*(1+$B$7)^(K37-1) -> 13232.82 | M37: =$B$5*MAX(0,L37-$B$6) -> 0 | N37: =$B$2 -> 9250 | O37: =MIN(M37,N37) -> 0 | P37: =O37/(1+$B$8)^K37 -> 0 | Q37: =N37-O37 -> 9250 | S37: 1 | T37: =$F$5*(1+$B$7)^(S37-1) -> 61545.9 | U37: =$B$5*MAX(0,T37-$B$6) -> 3082.581 | V37: =$B$2 -> 9250 | W37: =MIN(U37,V37) -> 3082.581 | X37: =W37/(1+$B$8)^S37 -> 2992.7971 | Y37: =V37-W37 -> 6167.419 | AA37: 1 | AB37: =$F$6*(1+$B$7)^(AA37-1) -> 46260.26 | AC37: =$B$5*MAX(0,AB37-$B$6) -> 1706.8734 | AD37: =$B$2 -> 9250 | AE37: =MIN(AC37,AD37) -> 1706.8734 | AF37: =AE37/(1+$B$8)^AA37 -> 1657.1586 | AG37: =AD37-AE37 -> 7543.1266 | AI37: 1 | AJ37: =$F$7*(1+$B$7)^(AI37-1) -> 22829.56 | AK37: =$B$5*MAX(0,AJ37-$B$6) -> 0 | AL37: =$B$2 -> 9250 | AM37: =MIN(AK37,AL37) -> 0 | AN37: =AM37/(1+$B$8)^AI37 -> 0 | AO37: =AL37-AM37 -> 9250
K38: =K37+1 -> 2 | L38: =$F$3*(1+$B$7)^(K38-1) -> 13497.476 | M38: =$B$5*MAX(0,L38-$B$6) -> 0 | N38: =Q37 -> 9250 | O38: =IF(N38<=0,0,MIN(M38,N38)) -> 0 | P38: =O38/(1+$B$8)^K38 -> 0 | Q38: =MAX(0,N38-O38) -> 9250 | S38: =S37+1 -> 2 | T38: =$F$5*(1+$B$7)^(S38-1) -> 62776.818 | U38: =$B$5*MAX(0,T38-$B$6) -> 3193.3636 | V38: =Y37 -> 6167.419 | W38: =IF(V38<=0,0,MIN(U38,V38)) -> 3193.3636 | X38: =W38/(1+$B$8)^S38 -> 3010.0515 | Y38: =MAX(0,V38-W38) -> 2974.0554 | AA38: =AA37+1 -> 2 | AB38: =$F$6*(1+$B$7)^(AA38-1) -> 47185.465 | AC38: =$B$5*MAX(0,AB38-$B$6) -> 1790.1419 | AD38: =AG37 -> 7543.1266 | AE38: =IF(AD38<=0,0,MIN(AC38,AD38)) -> 1790.1419 | AF38: =AE38/(1+$B$8)^AA38 -> 1687.3804 | AG38: =MAX(0,AD38-AE38) -> 5752.9847 | AI38: =AI37+1 -> 2 | AJ38: =$F$7*(1+$B$7)^(AI38-1) -> 23286.151 | AK38: =$B$5*MAX(0,AJ38-$B$6) -> 0 | AL38: =AO37 -> 9250 | AM38: =IF(AL38<=0,0,MIN(AK38,AL38)) -> 0 | AN38: =AM38/(1+$B$8)^AI38 -> 0 | AO38: =MAX(0,AL38-AM38) -> 9250
K39: =K38+1 -> 3 | L39: =$F$3*(1+$B$7)^(K39-1) -> 13767.426 | M39: =$B$5*MAX(0,L39-$B$6) -> 0 | N39: =Q38 -> 9250 | O39: =IF(N39<=0,0,MIN(M39,N39)) -> 0 | P39: =O39/(1+$B$8)^K39 -> 0 | Q39: =MAX(0,N39-O39) -> 9250 | S39: =S38+1 -> 3 | T39: =$F$5*(1+$B$7)^(S39-1) -> 64032.354 | U39: =$B$5*MAX(0,T39-$B$6) -> 3306.3619 | V39: =Y38 -> 2974.0554 | W39: =IF(V39<=0,0,MIN(U39,V39)) -> 2974.0554 | X39: =W39/(1+$B$8)^S39 -> 2721.682 | Y39: =MAX(0,V39-W39) -> 0 | AA39: =AA38+1 -> 3 | AB39: =$F$6*(1+$B$7)^(AA39-1) -> 48129.175 | AC39: =$B$5*MAX(0,AB39-$B$6) -> 1875.0757 | AD39: =AG38 -> 5752.9847 | AE39: =IF(AD39<=0,0,MIN(AC39,AD39)) -> 1875.0757 | AF39: =AE39/(1+$B$8)^AA39 -> 1715.9599 | AG39: =MAX(0,AD39-AE39) -> 3877.909 | AI39: =AI38+1 -> 3 | AJ39: =$F$7*(1+$B$7)^(AI39-1) -> 23751.874 | AK39: =$B$5*MAX(0,AJ39-$B$6) -> 0 | AL39: =AO38 -> 9250 | AM39: =IF(AL39<=0,0,MIN(AK39,AL39)) -> 0 | AN39: =AM39/(1+$B$8)^AI39 -> 0 | AO39: =MAX(0,AL39-AM39) -> 9250
K40: =K39+1 -> 4 | L40: =$F$3*(1+$B$7)^(K40-1) -> 14042.774 | M40: =$B$5*MAX(0,L40-$B$6) -> 0 | N40: =Q39 -> 9250 | O40: =IF(N40<=0,0,MIN(M40,N40)) -> 0 | P40: =O40/(1+$B$8)^K40 -> 0 | Q40: =MAX(0,N40-O40) -> 9250 | S40: =S39+1 -> 4 | T40: =$F$5*(1+$B$7)^(S40-1) -> 65313.001 | U40: =$B$5*MAX(0,T40-$B$6) -> 3421.6201 | V40: =Y39 -> 0 | W40: =IF(V40<=0,0,MIN(U40,V40)) -> 0 | X40: =W40/(1+$B$8)^S40 -> 0 | Y40: =MAX(0,V40-W40) -> 0 | AA40: =AA39+1 -> 4 | AB40: =$F$6*(1+$B$7)^(AA40-1) -> 49091.758 | AC40: =$B$5*MAX(0,AB40-$B$6) -> 1961.7082 | AD40: =AG39 -> 3877.909 | AE40: =IF(AD40<=0,0,MIN(AC40,AD40)) -> 1961.7082 | AF40: =AE40/(1+$B$8)^AA40 -> 1742.9523 | AG40: =MAX(0,AD40-AE40) -> 1916.2008 | AI40: =AI39+1 -> 4 | AJ40: =$F$7*(1+$B$7)^(AI40-1) -> 24226.912 | AK40: =$B$5*MAX(0,AJ40-$B$6) -> 0 | AL40: =AO39 -> 9250 | AM40: =IF(AL40<=0,0,MIN(AK40,AL40)) -> 0 | AN40: =AM40/(1+$B$8)^AI40 -> 0 | AO40: =MAX(0,AL40-AM40) -> 9250
K41: =K40+1 -> 5 | L41: =$F$3*(1+$B$7)^(K41-1) -> 14323.63 | M41: =$B$5*MAX(0,L41-$B$6) -> 0 | N41: =Q40 -> 9250 | O41: =IF(N41<=0,0,MIN(M41,N41)) -> 0 | P41: =O41/(1+$B$8)^K41 -> 0 | Q41: =MAX(0,N41-O41) -> 9250 | S41: =S40+1 -> 5 | T41: =$F$5*(1+$B$7)^(S41-1) -> 66619.261 | U41: =$B$5*MAX(0,T41-$B$6) -> 3539.1835 | V41: =Y40 -> 0 | W41: =IF(V41<=0,0,MIN(U41,V41)) -> 0 | X41: =W41/(1+$B$8)^S41 -> 0 | Y41: =MAX(0,V41-W41) -> 0 | AA41: =AA40+1 -> 5 | AB41: =$F$6*(1+$B$7)^(AA41-1) -> 50073.593 | AC41: =$B$5*MAX(0,AB41-$B$6) -> 2050.0734 | AD41: =AG40 -> 1916.2008 | AE41: =IF(AD41<=0,0,MIN(AC41,AD41)) -> 1916.2008 | AF41: =AE41/(1+$B$8)^AA41 -> 1652.9316 | AG41: =MAX(0,AD41-AE41) -> 0 | AI41: =AI40+1 -> 5 | AJ41: =$F$7*(1+$B$7)^(AI41-1) -> 24711.45 | AK41: =$B$5*MAX(0,AJ41-$B$6) -> 0 | AL41: =AO40 -> 9250 | AM41: =IF(AL41<=0,0,MIN(AK41,AL41)) -> 0 | AN41: =AM41/(1+$B$8)^AI41 -> 0 | AO41: =MAX(0,AL41-AM41) -> 9250
K42: =K41+1 -> 6 | L42: =$F$3*(1+$B$7)^(K42-1) -> 14610.103 | M42: =$B$5*MAX(0,L42-$B$6) -> 0 | N42: =Q41 -> 9250 | O42: =IF(N42<=0,0,MIN(M42,N42)) -> 0 | P42: =O42/(1+$B$8)^K42 -> 0 | Q42: =MAX(0,N42-O42) -> 9250 | S42: =S41+1 -> 6 | T42: =$F$5*(1+$B$7)^(S42-1) -> 67951.647 | U42: =$B$5*MAX(0,T42-$B$6) -> 3659.0982 | V42: =Y41 -> 0 | W42: =IF(V42<=0,0,MIN(U42,V42)) -> 0 | X42: =W42/(1+$B$8)^S42 -> 0 | Y42: =MAX(0,V42-W42) -> 0 | AA42: =AA41+1 -> 6 | AB42: =$F$6*(1+$B$7)^(AA42-1) -> 51075.065 | AC42: =$B$5*MAX(0,AB42-$B$6) -> 2140.2059 | AD42: =AG41 -> 0 | AE42: =IF(AD42<=0,0,MIN(AC42,AD42)) -> 0 | AF42: =AE42/(1+$B$8)^AA42 -> 0 | AG42: =MAX(0,AD42-AE42) -> 0 | AI42: =AI41+1 -> 6 | AJ42: =$F$7*(1+$B$7)^(AI42-1) -> 25205.679 | AK42: =$B$5*MAX(0,AJ42-$B$6) -> 0 | AL42: =AO41 -> 9250 | AM42: =IF(AL42<=0,0,MIN(AK42,AL42)) -> 0 | AN42: =AM42/(1+$B$8)^AI42 -> 0 | AO42: =MAX(0,AL42-AM42) -> 9250
...

Sheet Elasticities
A1: betas from models | G1: k_j s | M1: Elasticities
A2: Country | B2: Estimate_TWFE | C2: Estimate_controls | D2: Estimate_Pooled | G2: =Country_PV!D1 -> Country | H2: =Country_PV!E1 -> Wage_EURO | I2: =Country_PV!F1 -> wage_gbp | J2: =Country_PV!G1 -> PV_loan | K2: =Country_PV!H1 -> k_i | M2: Country | N2: Estimate_TWFE | O2: Estimate_controls | P2: Estimate_Pooled | Q2: k_i | R2: elasticity_TWFE_new | S2: elasticity_controls_new | T2: elasticity_Pooled_new | U2: elasticity_TWFE_old | V2: elasticity_controls_old | W2: elasticity_Pooled_old
A3: Austria | B3: -0.548534 | C3: -0.502849 | D3: -0.96075537 | G3: =Country_PV!D2 -> Belgium | H3: =Country_PV!E2 -> 59632 | I3: =Country_PV!F2 -> 51283.52 | J3: =Country_PV!G2 -> 8579.3385 | K3: =Country_PV!H2 -> 0.95073548 | M3: Belgium | N3: =INDEX($B$3:$B$28,MATCH(M3,$A$3:$A$28,0)) -> -0.602657 | O3: =INDEX($C$3:$C$28,MATCH(M3,$A$3:$A$28,0)) -> -0.575323 | P3: =INDEX($D$3:$D$28,MATCH(M3,$A$3:$A$28,0)) -> -0.43381198 | Q3: =INDEX($K$3:$K$28,MATCH(M3,$G$3:$G$28,0)) -> 0.95073548 | R3: =N3/Q3 -> -0.63388504 | S3: =O3/Q3 -> -0.60513467 | T3: =P3/Q3 -> -0.45629094 | U3: =N3/(LN(22200)-LN(9250)) -> -0.68838209 | V3: =O3/(LN(22200)-LN(9250)) -> -0.65715996 | W3: =P3/(LN(22200)-LN(9250)) -> -0.49551967
A4: Belgium | B4: -0.602657 | C4: -0.575323 | D4: -0.43381198 | G4: =Country_PV!D3 -> Bulgaria | H4: =Country_PV!E3 -> 15387 | I4: =Country_PV!F3 -> 13232.82 | J4: =Country_PV!G3 -> 1 | K4: =Country_PV!H3 -> 10.007848 | M4: Bulgaria | N4: =INDEX($B$3:$B$28,MATCH(M4,$A$3:$A$28,0)) -> -1.887146 | O4: =INDEX($C$3:$C$28,MATCH(M4,$A$3:$A$28,0)) -> -1.785586 | P4: =INDEX($D$3:$D$28,MATCH(M4,$A$3:$A$28,0)) -> -1.0063262 | Q4: =INDEX($K$3:$K$28,MATCH(M4,$G$3:$G$28,0)) -> 10.007848 | R4: =N4/Q4 -> -0.18856662 | S4: =O4/Q4 -> -0.17841858 | T4: =P4/Q4 -> -0.10055371 | U4: =N4/(LN(22200)-LN(9250)) -> -2.1555835 | V4: =O4/(LN(22200)-LN(9250)) -> -2.0395771 | W4: =P4/(LN(22200)-LN(9250)) -> -1.1494713
A5: Bulgaria | B5: -1.887146 | C5: -1.785586 | D5: -1.0063262 | G5: =Country_PV!D4 -> Czechia | H5: =Country_PV!E4 -> 23998 | I5: =Country_PV!F4 -> 20638.28 | J5: =Country_PV!G4 -> 3021.0957 | K5: =Country_PV!H4 -> 1.9944727 | M5: Czechia | N5: =INDEX($B$3:$B$28,MATCH(M5,$A$3:$A$28,0)) -> -1.137201 | O5: =INDEX($C$3:$C$28,MATCH(M5,$A$3:$A$28,0)) -> -1.075068 | P5: =INDEX($D$3:$D$28,MATCH(M5,$A$3:$A$28,0)) -> -0.90086981 | Q5: =INDEX($K$3:$K$28,MATCH(M5,$G$3:$G$28,0)) -> 1.9944727 | R5: =N5/Q5 -> -0.57017626 | S5: =O5/Q5 -> -0.53902367 | T5: =P5/Q5 -> -0.4516832 | U5: =N5/(LN(22200)-LN(9250)) -> -1.2989624 | V5: =O5/(LN(22200)-LN(9250)) -> -1.2279913 | W5: =P5/(LN(22200)-LN(9250)) -> -1.0290143
A6: Croatia | B6: -1.654745 | C6: -1.53452 | D6: -2.5720774 | G6: =Country_PV!D5 -> Denmark | H6: =Country_PV!E5 -> 71565 | I6: =Country_PV!F5 -> 61545.9 | J6: =Country_PV!G5 -> 8724.5305 | K6: =Country_PV!H5 -> 0.93395363 | M6: Denmark | N6: =INDEX($B$3:$B$28,MATCH(M6,$A$3:$A$28,0)) -> -1.046503 | O6: =INDEX($C$3:$C$28,MATCH(M6,$A$3:$A$28,0)) -> -1.029858 | P6: =INDEX($D$3:$D$28,MATCH(M6,$A$3:$A$28,0)) -> -1.6091993 | Q6: =INDEX($K$3:$K$28,MATCH(M6,$G$3:$G$28,0)) -> 0.93395363 | R6: =N6/Q6 -> -1.1205085 | S6: =O6/Q6 -> -1.1026864 | T6: =P6/Q6 -> -1.722997 | U6: =N6/(LN(22200)-LN(9250)) -> -1.1953631 | V6: =O6/(LN(22200)-LN(9250)) -> -1.1763504 | W6: =P6/(LN(22200)-LN(9250)) -> -1.8381002
A7: Cyprus | B7: -0.902163 | C7: -0.946609 | D7: 0.25508166 | G7: =Country_PV!D6 -> Germany | H7: =Country_PV!E6 -> 53791 | I7: =Country_PV!F6 -> 46260.26 | J7: =Country_PV!G6 -> 8456.3829 | K7: =Country_PV!H6 -> 0.96517076 | M7: Germany | N7: =INDEX($B$3:$B$28,MATCH(M7,$A$3:$A$28,0)) -> -0.6815 | O7: =INDEX($C$3:$C$28,MATCH(M7,$A$3:$A$28,0)) -> -0.581445 | P7: =INDEX($D$3:$D$28,MATCH(M7,$A$3:$A$28,0)) -> 0.65222662 | Q7: =INDEX($K$3:$K$28,MATCH(M7,$G$3:$G$28,0)) -> 0.96517076 | R7: =N7/Q7 -> -0.70609267 | S7: =O7/Q7 -> -0.60242708 | T7: =P7/Q7 -> 0.67576294 | U7: =N7/(LN(22200)-LN(9250)) -> -0.77844013 | V7: =O7/(LN(22200)-LN(9250)) -> -0.66415278 | W7: =P7/(LN(22200)-LN(9250)) -> 0.74500276
A8: Czechia | B8: -1.137201 | C8: -1.075068 | D8: -0.90086981 | G8: =Country_PV!D7 -> Estonia | H8: =Country_PV!E7 -> 26546 | I8: =Country_PV!F7 -> 22829.56 | J8: =Country_PV!G7 -> 4804.714 | K8: =Country_PV!H7 -> 1.5304948 | M8: Estonia | N8: =INDEX($B$3:$B$28,MATCH(M8,$A$3:$A$28,0)) -> -1.447445 | O8: =INDEX($C$3:$C$28,MATCH(M8,$A$3:$A$28,0)) -> -1.407405 | P8: =INDEX($D$3:$D$28,MATCH(M8,$A$3:$A$28,0)) -> -2.2370894 | Q8: =INDEX($K$3:$K$28,MATCH(M8,$G$3:$G$28,0)) -> 1.5304948 | R8: =N8/Q8 -> -0.94573665 | S8: =O8/Q8 -> -0.91957517 | T8: =P8/Q8 -> -1.4616773 | U8: =N8/(LN(22200)-LN(9250)) -> -1.6533372 | V8: =O8/(LN(22200)-LN(9250)) -> -1.6076017 | W8: =P8/(LN(22200)-LN(9250)) -> -2.5553048
A9: Denmark | B9: -1.046503 | C9: -1.029858 | D9: -1.6091993 | G9: =Country_PV!D8 -> Ireland | H9: =Country_PV!E8 -> 61051 | I9: =Country_PV!F8 -> 52503.86 | J9: =Country_PV!G8 -> N/a | K9: =Country_PV!H8 -> N/a | M9: Ireland | N9: =INDEX($B$3:$B$28,MATCH(M9,$A$3:$A$28,0)) -> #N/A | O9: =INDEX($C$3:$C$28,MATCH(M9,$A$3:$A$28,0)) -> #N/A | P9: =INDEX($D$3:$D$28,MATCH(M9,$A$3:$A$28,0)) -> #N/A | Q9: =INDEX($K$3:$K$28,MATCH(M9,$G$3:$G$28,0)) -> N/a | R9: =N9/Q9 -> #N/A | S9: =O9/Q9 -> #N/A | T9: =P9/Q9 -> #N/A | U9: =N9/(LN(22200)-LN(9250)) -> #N/A | V9: =O9/(LN(22200)-LN(9250)) -> #N/A | W9: =P9/(LN(22200)-LN(9250)) -> #N/A
A10: Estonia | B10: -1.447445 | C10: -1.407405 | D10: -2.2370894 | G10: =Country_PV!D9 -> Greece | H10: =Country_PV!E9 -> 17954 | I10: =Country_PV!F9 -> 15440.44 | J10: =Country_PV!G9 -> 4.6283026 | K10: =Country_PV!H9 -> 8.4756574 | M10: Greece | N10: =INDEX($B$3:$B$28,MATCH(M10,$A$3:$A$28,0)) -> -0.86575 | O10: =INDEX($C$3:$C$28,MATCH(M10,$A$3:$A$28,0)) -> -0.718908 | P10: =INDEX($D$3:$D$28,MATCH(M10,$A$3:$A$28,0)) -> 0.10535878 | Q10: =INDEX($K$3:$K$28,MATCH(M10,$G$3:$G$28,0)) -> 8.4756574 | R10: =N10/Q10 -> -0.10214547 | S10: =O10/Q10 -> -0.084820323 | T10: =P10/Q10 -> 0.01243075 | U10: =N10/(LN(22200)-LN(9250)) -> -0.98889882 | V10: =O10/(LN(22200)-LN(9250)) -> -0.82116924 | W10: =P10/(LN(22200)-LN(9250)) -> 0.12034556
A11: Finland | B11: -1.756347 | C11: -1.620129 | D11: -1.8170332 | G11: =Country_PV!D10 -> Spain | H11: =Country_PV!E10 -> 33700 | I11: =Country_PV!F10 -> 28982 | J11: =Country_PV!G10 -> 6801.1286 | K11: =Country_PV!H10 -> 1.1830037 | M11: Spain | N11: =INDEX($B$3:$B$28,MATCH(M11,$A$3:$A$28,0)) -> -0.507701 | O11: =INDEX($C$3:$C$28,MATCH(M11,$A$3:$A$28,0)) -> -0.473719 | P11: =INDEX($D$3:$D$28,MATCH(M11,$A$3:$A$28,0)) -> 0.96454423 | Q11: =INDEX($K$3:$K$28,MATCH(M11,$G$3:$G$28,0)) -> 1.1830037 | R11: =N11/Q11 -> -0.42916264 | S11: =O11/Q11 -> -0.40043745 | T11: =P11/Q11 -> 0.8153349 | U11: =N11/(LN(22200)-LN(9250)) -> -0.57991905 | V11: =O11/(LN(22200)-LN(9250)) -> -0.54110327 | W11: =P11/(LN(22200)-LN(9250)) -> 1.1017461
A12: France | B12: -0.597106 | C12: -0.535495 | D12: 1.178993 | G12: =Country_PV!D11 -> France | H12: =Country_PV!E11 -> 43790 | I12: =Country_PV!F11 -> 37659.4 | J12: =Country_PV!G11 -> 8054.806 | K12: =Country_PV!H11 -> 1.0138234 | M12: France | N12: =INDEX($B$3:$B$28,MATCH(M12,$A$3:$A$28,0)) -> -0.597106 | O12: =INDEX($C$3:$C$28,MATCH(M12,$A$3:$A$28,0)) -> -0.535495 | P12: =INDEX($D$3:$D$28,MATCH(M12,$A$3:$A$28,0)) -> 1.178993 | Q12: =INDEX($K$3:$K$28,MATCH(M12,$G$3:$G$28,0)) -> 1.0138234 | R12: =N12/Q12 -> -0.58896453 | S12: =O12/Q12 -> -0.52819359 | T12: =P12/Q12 -> 1.1629175 | U12: =N12/(LN(22200)-LN(9250)) -> -0.68204149 | V12: =O12/(LN(22200)-LN(9250)) -> -0.61166662 | W12: =P12/(LN(22200)-LN(9250)) -> 1.3466991
A13: Germany | B13: -0.6815 | C13: -0.581445 | D13: 0.65222662 | G13: =Country_PV!D12 -> Croatia | H13: =Country_PV!E12 -> 23446 | I13: =Country_PV!F12 -> 20163.56 | J13: =Country_PV!G12 -> 2527.4656 | K13: =Country_PV!H12 -> 2.1728752 | M13: Croatia | N13: =INDEX($B$3:$B$28,MATCH(M13,$A$3:$A$28,0)) -> -1.654745 | O13: =INDEX($C$3:$C$28,MATCH(M13,$A$3:$A$28,0)) -> -1.53452 | P13: =INDEX($D$3:$D$28,MATCH(M13,$A$3:$A$28,0)) -> -2.5720774 | Q13: =INDEX($K$3:$K$28,MATCH(M13,$G$3:$G$28,0)) -> 2.1728752 | R13: =N13/Q13 -> -0.76154626 | S13: =O13/Q13 -> -0.70621634 | T13: =P13/Q13 -> -1.1837207 | U13: =N13/(LN(22200)-LN(9250)) -> -1.8901246 | V13: =O13/(LN(22200)-LN(9250)) -> -1.7527982 | W13: =P13/(LN(22200)-LN(9250)) -> -2.9379431
A14: Greece | B14: -0.86575 | C14: -0.718908 | D14: 0.10535878 | G14: =Country_PV!D13 -> Italy | H14: =Country_PV!E13 -> 33523 | I14: =Country_PV!F13 -> 28829.78 | J14: =Country_PV!G13 -> 6758.7787 | K14: =Country_PV!H13 -> 1.1892501 | M14: Italy | N14: =INDEX($B$3:$B$28,MATCH(M14,$A$3:$A$28,0)) -> -0.925037 | O14: =INDEX($C$3:$C$28,MATCH(M14,$A$3:$A$28,0)) -> -0.808428 | P14: =INDEX($D$3:$D$28,MATCH(M14,$A$3:$A$28,0)) -> 0.67669479 | Q14: =INDEX($K$3:$K$28,MATCH(M14,$G$3:$G$28,0)) -> 1.1892501 | R14: =N14/Q14 -> -0.77783219 | S14: =O14/Q14 -> -0.67977964 | T14: =P14/Q14 -> 0.56900966 | U14: =N14/(LN(22200)-LN(9250)) -> -1.0566191 | V14: =O14/(LN(22200)-LN(9250)) -> -0.92342304 | W14: =P14/(LN(22200)-LN(9250)) -> 0.7729514
... A28: Sweden | B28: -0.966849 | C28: -0.927258 | D28: -0.62943314 | G28: =Country_PV!D27 -> Sweden | H28: =Country_PV!E27 -> 46525 | I28: =Country_PV!F27 -> 40011.5 | J28: =Country_PV!G27 -> 8202.1973 | K28: =Country_PV!H27 -> 0.99569021 | M28: Sweden | N28: =INDEX($B$3:$B$28,MATCH(M28,$A$3:$A$28,0)) -> -0.966849 | O28: =INDEX($C$3:$C$28,MATCH(M28,$A$3:$A$28,0)) -> -0.927258 | P28: =INDEX($D$3:$D$28,MATCH(M28,$A$3:$A$28,0)) -> -0.62943314 | Q28: =INDEX($K$3:$K$28,MATCH(M28,$G$3:$G$28,0)) -> 0.99569021 | R28: =N28/Q28 -> -0.97103395 | S28: =O28/Q28 -> -0.93127158 | T28: =P28/Q28 -> -0.6321576 | U28: =N28/(LN(22200)-LN(9250)) -> -1.1043787 | V28: =O28/(LN(22200)-LN(9250)) -> -1.059156 | W28: =P28/(LN(22200)-LN(9250)) -> -0.71896701

Sheet WB_correlations
A1: Link: https://data.worldbank.org/indicator/NY.GDP.PCAP.PP.KD | D1: Elasticities derived in previous sheets | N1: SUMMARY OUTPUT | P1: =E2 -> elasticity_TWFE_new | T1: SUMMARY OUTPUT | V1: =F2 -> elasticity_controls_new | Z1: SUMMARY OUTPUT | AB1: =G2 -> elasticity_Pooled_new
A2: Country Name | B2: 2022 | D2: =Elasticities!M2 -> Country | E2: =Elasticities!R2 -> elasticity_TWFE_new | F2: =Elasticities!S2 -> elasticity_controls_new | G2: =Elasticities!T2 -> elasticity_Pooled_new | H2: =Elasticities!U2 -> elasticity_TWFE_old | I2: =Elasticities!V2 -> elasticity_controls_old | J2: =Elasticities!W2 -> elasticity_Pooled_old | K2: GDP_per_cap
A3: Aruba | B3: 38979.836 | D3: =Elasticities!M3 -> Belgium | E3: =Elasticities!R3 -> -0.63388504 | F3: =Elasticities!S3 -> -0.60513467 | G3: =Elasticities!T3 -> -0.45629094 | H3: =Elasticities!U3 -> -0.68838209 | I3: =Elasticities!V3 -> -0.65715996 | J3: =Elasticities!W3 -> -0.49551967 | K3: =LN(VLOOKUP(D3,$A$3:$B$267,2,FALSE)) -> 11.04391 | N3: Regression Statistics | T3: Regression Statistics | Z3: Regression Statistics
A4: Africa Eastern and Southern | B4: 4106.5019 | D4: =Elasticities!M4 -> Bulgaria | E4: =Elasticities!R4 -> -0.18856662 | F4: =Elasticities!S4 -> -0.17841858 | G4: =Elasticities!T4 -> -0.10055371 | H4: =Elasticities!U4 -> -2.1555835 | I4: =Elasticities!V4 -> -2.0395771 | J4: =Elasticities!W4 -> -1.1494713 | K4: =LN(VLOOKUP(D4,$A$3:$B$267,2,FALSE)) -> 10.386956 | N4: Multiple R | O4: 0.25187648 | T4: Multiple R | U4: 0.30442605 | Z4: Multiple R | AA4: 0.2300947
A5: Afghanistan | B5: 1981.7102 | D5: =Elasticities!M5 -> Czechia | E5: =Elasticities!R5 -> -0.57017626 | F5: =Elasticities!S5 -> -0.53902367 | G5: =Elasticities!T5 -> -0.4516832 | H5: =Elasticities!U5 -> -1.2989624 | I5: =Elasticities!V5 -> -1.2279913 | J5: =Elasticities!W5 -> -1.0290143 | K5: =LN(VLOOKUP(D5,$A$3:$B$267,2,FALSE)) -> 10.787062 | N5: R Square | O5: 0.063441763 | T5: R Square | U5: 0.092675222 | Z5: R Square | AA5: 0.052943569
A6: Africa Western and Central | B6: 5806.1729 | D6: =Elasticities!M6 -> Denmark | E6: =Elasticities!R6 -> -1.1205085 | F6: =Elasticities!S6 -> -1.1026864 | G6: =Elasticities!T6 -> -1.722997 | H6: =Elasticities!U6 -> -1.1953631 | I6: =Elasticities!V6 -> -1.1763504 | J6: =Elasticities!W6 -> -1.8381002 | K6: =LN(VLOOKUP(D6,$A$3:$B$267,2,FALSE)) -> 11.148727 | N6: Adjusted R Square | O6: 0.02272184 | T6: Adjusted R Square | U6: 0.053226319 | Z6: Adjusted R Square | AA6: 0.011767202
A7: Angola | B7: 8950.1426 | D7: =Elasticities!M7 -> Germany | E7: =Elasticities!R7 -> -0.70609267 | F7: =Elasticities!S7 -> -0.60242708 | G7: =Elasticities!T7 -> 0.67576294 | H7: =Elasticities!U7 -> -0.77844013 | I7: =Elasticities!V7 -> -0.66415278 | J7: =Elasticities!W7 -> 0.74500276 | K7: =LN(VLOOKUP(D7,$A$3:$B$267,2,FALSE)) -> 11.061564 | N7: Standard Error | O7: 0.39374614 | T7: Standard Error | U7: 0.36775005 | Z7: Standard Error | AA7: 0.94275897
A8: Albania | B8: 19388.873 | D8: =Elasticities!M8 -> Estonia | E8: =Elasticities!R8 -> -0.94573665 | F8: =Elasticities!S8 -> -0.91957517 | G8: =Elasticities!T8 -> -1.4616773 | H8: =Elasticities!U8 -> -1.6533372 | I8: =Elasticities!V8 -> -1.6076017 | J8: =Elasticities!W8 -> -2.5553048 | K8: =LN(VLOOKUP(D8,$A$3:$B$267,2,FALSE)) -> 10.671942 | N8: Observations | O8: 25 | T8: Observations | U8: 25 | Z8: Observations | AA8: 25
A9: Andorra | B9: 63913.384 | D9: =Elasticities!M10 -> Greece | E9: =Elasticities!R10 -> -0.10214547 | F9: =Elasticities!S10 -> -0.084820323 | G9: =Elasticities!T10 -> 0.01243075 | H9: =Elasticities!U10 -> -0.98889882 | I9: =Elasticities!V10 -> -0.82116924 | J9: =Elasticities!W10 -> 0.12034556 | K9: =LN(VLOOKUP(D9,$A$3:$B$267,2,FALSE)) -> 10.486578
A10: Arab World | B10: 16905.49 | D10: =Elasticities!M11 -> Spain | E10: =Elasticities!R11 -> -0.42916264 | F10: =Elasticities!S11 -> -0.40043745 | G10: =Elasticities!T11 -> 0.8153349 | H10: =Elasticities!U11 -> -0.57991905 | I10: =Elasticities!V11 -> -0.54110327 | J10: =Elasticities!W11 -> 1.1017461 | K10: =LN(VLOOKUP(D10,$A$3:$B$267,2,FALSE)) -> 10.752216 | N10: ANOVA | T10: ANOVA | Z10: ANOVA
A11: United Arab Emirates | B11: 70075.63 | D11: =Elasticities!M12 -> France | E11: =Elasticities!R12 -> -0.58896453 | F11: =Elasticities!S12 -> -0.52819359 | G11: =Elasticities!T12 -> 1.1629175 | H11: =Elasticities!U12 -> -0.68204149 | I11: =Elasticities!V12 -> -0.61166662 | J11: =Elasticities!W12 -> 1.3466991 | K11: =LN(VLOOKUP(D11,$A$3:$B$267,2,FALSE)) -> 10.890681 | O11: df | P11: SS | Q11: MS | R11: F | S11: Significance F | U11: df | V11: SS | W11: MS | X11: F | Y11: Significance F | AA11: df | AB11: SS | AC11: MS | AD11: F | AE11: Significance F
A12: Argentina | B12: 27825.027 | D12: =Elasticities!M13 -> Croatia | E12: =Elasticities!R13 -> -0.76154626 | F12: =Elasticities!S13 -> -0.70621634 | G12: =Elasticities!T13 -> -1.1837207 | H12: =Elasticities!U13 -> -1.8901246 | I12: =Elasticities!V13 -> -1.7527982 | J12: =Elasticities!W13 -> -2.9379431 | K12: =LN(VLOOKUP(D12,$A$3:$B$267,2,FALSE)) -> 10.593229 | N12: Regression | O12: 1 | P12: 0.24154659 | Q12: 0.24154659 | R12: 1.558003 | S12: 0.22451558 | T12: Regression | U12: 1 | V12: 0.31771242 | W12: 0.31771242 | X12: 2.3492471 | Y12: 0.13898449 | Z12: Regression | AA12: 1 | AB12: 1.1427903 | AC12: 1.1427903 | AD12: 1.2857756 | AE12: 0.26850894
A13: Armenia | B13: 17886.178 | D13: =Elasticities!M14 -> Italy | E13: =Elasticities!R14 -> -0.77783219 | F13: =Elasticities!S14 -> -0.67977964 | G13: =Elasticities!T14 -> 0.56900966 | H13: =Elasticities!U14 -> -1.0566191 | I13: =Elasticities!V14 -> -0.92342304 | J13: =Elasticities!W14 -> 0.7729514 | K13: =LN(VLOOKUP(D13,$A$3:$B$267,2,FALSE)) -> 10.865389 | N13: Residual | O13: 23 | P13: 3.5658285 | Q13: 0.15503602 | T13: Residual | U13: 23 | V13: 3.1105223 | W13: 0.1352401 | Z13: Residual | AA13: 23 | AB13: 20.442273 | AC13: 0.88879447
A14: American Samoa | D14: =Elasticities!M15 -> Cyprus | E14: =Elasticities!R15 -> -0.61298791 | F14: =Elasticities!S15 -> -0.6431874 | G14: =Elasticities!T15 -> 0.17331898 | H14: =Elasticities!U15 -> -1.0304914 | I14: =Elasticities!V15 -> -1.0812596 | J14: =Elasticities!W15 -> 0.29136581 | K14: =LN(VLOOKUP(D14,$A$3:$B$267,2,FALSE)) -> 10.832177 | N14: Total | O14: 24 | P14: 3.8073751 | T14: Total | U14: 24 | V14: 3.4282348 | Z14: Total | AA14: 24 | AB14: 21.585063
A15: Antigua and Barbuda | B15: 27941.785 | D15: =Elasticities!M16 -> Latvia | E15: =Elasticities!R16 -> -0.57571916 | F15: =Elasticities!S16 -> -0.52964993 | G15: =Elasticities!T16 -> -0.73442091 | H15: =Elasticities!U16 -> -1.726522 | I15: =Elasticities!V16 -> -1.5883651 | J15: =Elasticities!W16 -> -2.202452 | K15: =LN(VLOOKUP(D15,$A$3:$B$267,2,FALSE)) -> 10.537912
A16: Australia | B16: 60029.133 | D16: =Elasticities!M17 -> Lithuania | E16: =Elasticities!R17 -> -1.5601515 | F16: =Elasticities!S17 -> -1.5558776 | G16: =Elasticities!T17 -> -1.0132439 | H16: =Elasticities!U17 -> -2.482228 | I16: =Elasticities!V17 -> -2.4754282 | J16: =Elasticities!W17 -> -1.6120886 | K16: =LN(VLOOKUP(D16,$A$3:$B$267,2,FALSE)) -> 10.750454 | O16: Coefficients | P16: Standard Error | Q16: t Stat | R16: P-value | S16: Lower 95% | U16: Coefficients | V16: Standard Error | W16: t Stat | X16: P-value | Y16: Lower 95% | AA16: Coefficients | AB16: Standard Error | AC16: t Stat | AD16: P-value | AE16: Lower 95%
A17: Austria | B17: 65694.551 | D17: =Elasticities!M18 -> Luxembourg | E17: =Elasticities!R18 -> -0.53256139 | F17: =Elasticities!S18 -> -0.62126418 | G17: =Elasticities!T18 -> -1.336135 | H17: =Elasticities!U18 -> -0.56300697 | I17: =Elasticities!V18 -> -0.65678073 | J17: =Elasticities!W18 -> -1.4125195 | K17: =LN(VLOOKUP(D17,$A$3:$B$267,2,FALSE)) -> 11.794872 | N17: Intercept | O17: 3.0501716 | P17: 2.9914068 | Q17: 1.0196445 | R17: 0.31850331 | S17: -3.1380249 | T17: Intercept | U17: 3.6290329 | V17: 2.7939068 | W17: 1.2989098 | X17: 0.20684657 | Y17: -2.1506037 | Z17: Intercept | AA17: 7.5577928 | AB17: 7.162421 | AC17: 1.0552009 | AD17: 0.30229229 | AE17: -7.258804
A18: Azerbaijan | B18: 21051.244 | D18: =Elasticities!M19 -> Hungary | E18: =Elasticities!R19 -> -0.18071432 | F18: =Elasticities!S19 -> -0.16598094 | G18: =Elasticities!T19 -> -0.16729694 | H18: =Elasticities!U19 -> -1.2729958 | I18: =Elasticities!V19 -> -1.1692102 | J18: =Elasticities!W19 -> -1.1784804 | K18: =LN(VLOOKUP(D18,$A$3:$B$267,2,FALSE)) -> 10.611794 | N18: GDP_per_cap | O18: -0.34501952 | P18: 0.27641367 | Q18: -1.2481999 | R18: 0.22451558 | S18: -0.91682477 | T18: GDP_per_cap | U18: -0.39569477 | V18: 0.25816417 | W18: -1.5327254 | X18: 0.13898449 | Y18: -0.92974803 | Z18: GDP_per_cap | AA18: -0.75045816 | AB18: 0.66182609 | AC18: -1.1339205 | AD18: 0.26850894 | AE18: -2.1195497
A19: Burundi | B19: 1031.2541 | D19: =Elasticities!M20 -> Malta | E19: =Elasticities!R20 -> -0.30390047 | F19: =Elasticities!S20 -> -0.44608238 | G19: =Elasticities!T20 -> -1.9621616 | H19: =Elasticities!U20 -> -0.41312612 | I19: =Elasticities!V20 -> -0.60641 | J19: =Elasticities!W20 -> -2.6673871 | K19: =LN(VLOOKUP(D19,$A$3:$B$267,2,FALSE)) -> 10.94803
A20: Belgium | B20: 62561.781 | D20: =Elasticities!M21 -> Austria | E20: =Elasticities!R21 -> -0.57542304 | F20: =Elasticities!S21 -> -0.52749857 | G20: =Elasticities!T21 -> -1.0078514 | H20: =Elasticities!U21 -> -0.62656035 | I20: =Elasticities!V21 -> -0.57437688 | J20: =Elasticities!W21 -> -1.0974182 | K20: =LN(VLOOKUP(D20,$A$3:$B$267,2,FALSE)) -> 11.092771
A21: Benin | B21: 3588.3252 | D21: =Elasticities!M22 -> Poland | E21: =Elasticities!R22 -> -0.53479744 | F21: =Elasticities!S22 -> -0.49020643 | G21: =Elasticities!T22 -> -0.043359174 | H21: =Elasticities!U22 -> -1.905586 | I21: =Elasticities!V22 -> -1.7466997 | J21: =Elasticities!W22 -> -0.15449707 | K21: =LN(VLOOKUP(D21,$A$3:$B$267,2,FALSE)) -> 10.67833 | N21: SUMMARY OUTPUT | P21: =H2 -> elasticity_TWFE_old | T21: SUMMARY OUTPUT | V21: =I2 -> elasticity_controls_old | Z21: SUMMARY OUTPUT | AB21: =J2 -> elasticity_Pooled_old
A22: Burkina Faso | B22: 2469.1996 | D22: =Elasticities!M23 -> Portugal | E22: =Elasticities!R23 -> -0.53496547 | F22: =Elasticities!S23 -> -0.47609226 | G22: =Elasticities!T23 -> -0.049494291 | H22: =Elasticities!U23 -> -1.0727613 | I22: =Elasticities!V23 -> -0.95470342 | J22: =Elasticities!W23 -> -0.099250445 | K22: =LN(VLOOKUP(D22,$A$3:$B$267,2,FALSE)) -> 10.623054
A23: Bangladesh | B23: 7888.1639 | D23: =Elasticities!M24 -> Romania | E23: =Elasticities!R24 -> -0.5353287 | F23: =Elasticities!S24 -> -0.50095528 | G23: =Elasticities!T24 -> -0.11355059 | H23: =Elasticities!U24 -> -1.9548762 | I23: =Elasticities!V24 -> -1.8293537 | J23: =Elasticities!W24 -> -0.41465617 | K23: =LN(VLOOKUP(D23,$A$3:$B$267,2,FALSE)) -> 10.577885 | N23: Regression Statistics | T23: Regression Statistics | Z23: Regression Statistics
A24: Bulgaria | B24: 32433.794 | D24: =Elasticities!M25 -> Slovenia | E24: =Elasticities!R25 -> -1.1222056 | F24: =Elasticities!S25 -> -1.0343878 | G24: =Elasticities!T25 -> -2.7253957 | H24: =Elasticities!U25 -> -1.4615645 | I24: =Elasticities!V25 -> -1.3471903 | J24: =Elasticities!W25 -> -3.5495649 | K24: =LN(VLOOKUP(D24,$A$3:$B$267,2,FALSE)) -> 10.758968 | N24: Multiple R | O24: 0.55897998 | T24: Multiple R | U24: 0.50575873 | Z24: Multiple R | AA24: 0.039569074
A25: Bahrain | B25: 57572.998 | D25: =Elasticities!M26 -> Slovakia | E25: =Elasticities!R26 -> -0.4053959 | F25: =Elasticities!S26 -> -0.37366231 | G25: =Elasticities!T26 -> -0.41972951 | H25: =Elasticities!U26 -> -1.7320162 | I25: =Elasticities!V26 -> -1.5964374 | J25: =Elasticities!W26 -> -1.7932552 | K25: =LN(VLOOKUP(D25,$A$3:$B$267,2,FALSE)) -> 10.562688 | N25: R Square | O25: 0.31245862 | T25: R Square | U25: 0.25579189 | Z25: R Square | AA25: 0.0015657116
A26: Bahamas, The | B26: 34342.929 | D26: =Elasticities!M27 -> Finland | E26: =Elasticities!R27 -> -1.7904015 | F26: =Elasticities!S27 -> -1.6515423 | G26: =Elasticities!T27 -> -1.8522643 | H26: =Elasticities!U27 -> -2.006179 | I26: =Elasticities!V27 -> -1.8505846 | J26: =Elasticities!W27 -> -2.0754975 | K26: =LN(VLOOKUP(D26,$A$3:$B$267,2,FALSE)) -> 10.952004 | N26: Adjusted R Square | O26: 0.28256551 | T26: Adjusted R Square | U26: 0.22343502 | Z26: Adjusted R Square | AA26: -0.041844475
A27: Bosnia and Herzegovina | B27: 19298.197 | D27: =Elasticities!M28 -> Sweden | E27: =Elasticities!R28 -> -0.97103395 | F27: =Elasticities!S28 -> -0.93127158 | G27: =Elasticities!T28 -> -0.6321576 | H27: =Elasticities!U28 -> -1.1043787 | I27: =Elasticities!V28 -> -1.059156 | J27: =Elasticities!W28 -> -0.71896701 | K27: =LN(VLOOKUP(D27,$A$3:$B$267,2,FALSE)) -> 11.052293 | N27: Standard Error | O27: 0.48750557 | T27: Standard Error | U27: 0.47442183 | Z27: Standard Error | AA27: 1.3378384
A28: Belarus | B28: 26537.508 | N28: Observations | O28: 25 | T28: Observations | U28: 25 | Z28: Observations | AA28: 25
A29: Belize | B29: 12565.365
A30: Bermuda | B30: 98145.169 | N30: ANOVA | T30: ANOVA | Z30: ANOVA
A31: Bolivia | B31: 11487.715 | O31: df | P31: SS | Q31: MS | R31: F | S31: Significance F | U31: df | V31: SS | W31: MS | X31: F | Y31: Significance F | AA31: df | AB31: SS | AC31: MS | AD31: F | AE31: Significance F
A32: Brazil | B32: 18554.046 | N32: Regression | O32: 1 | P32: 2.4841662 | Q32: 2.4841662 | R32: 10.452532 | S32: 0.0036763039 | T32: Regression | U32: 1 | V32: 1.7793015 | W32: 1.7793015 | X32: 7.9053338 | Y32: 0.0099014271 | Z32: Regression | AA32: 1 | AB32: 0.064554639 | AC32: 0.064554639 | AD32: 0.036067839 | AE32: 0.85104162
A33: Barbados | B33: 20716.285 | N33: Residual | O33: 23 | P33: 5.4662186 | Q33: 0.23766168 | T33: Residual | U33: 23 | V33: 5.1767497 | W33: 0.22507607 | Z33: Residual | AA33: 23 | AB33: 41.165669 | AC33: 1.7898117
A34: Brunei Darussalam | B34: 76357.829 | N34: Total | O34: 24 | P34: 7.9503848 | T34: Total | U34: 24 | V34: 6.9560511 | Z34: Total | AA34: 24 | AB34: 41.230223
A35: Bhutan | B35: 14061.312
A36: Botswana | B36: 18647.374 | O36: Coefficients | P36: Standard Error | Q36: t Stat | R36: P-value | S36: Lower 95% | U36: Coefficients | V36: Standard Error | W36: t Stat | X36: P-value | Y36: Lower 95% | AA36: Coefficients | AB36: Standard Error | AC36: t Stat | AD36: P-value | AE36: Lower 95%
A37: Central African Republic | B37: 1136.8017 | N37: Intercept | O37: -13.262931 | P37: 3.7037252 | Q37: -3.5809707 | R37: 0.0015820765 | S37: -20.92467 | T37: Intercept | U37: -11.352917 | V37: 3.6043241 | W37: -3.1498047 | X37: 0.0044845698 | Y37: -18.809029 | Z37: Intercept | AA37: -2.9137536 | AB37: 10.163958 | AC37: -0.28667511 | AD37: 0.7769277 | AE37: -23.939502
A38: Canada | B38: 58321.061 | N38: GDP_per_cap | O38: 1.1064545 | P38: 0.34223372 | Q38: 3.2330376 | R38: 0.0036763039 | S38: 0.39849008 | T38: GDP_per_cap | U38: 0.93641418 | V38: 0.3330488 | W38: 2.8116425 | X38: 0.0099014271 | Y38: 0.24745024 | Z38: GDP_per_cap | AA38: 0.17836389 | AB38: 0.93917578 | AC38: 0.18991535 | AD38: 0.85104162 | AE38: -1.7644692
A39: Central Europe and the Baltics | B39: 41834.725
A40: Switzerland | B40: 82777.294
...

Sheet WB_R_excel_check
A1: FROM R | X1: FROM EXCEL
A2: Country | B2: Wage_EURO | C2: wage_gbp | D2: PV_loan | E2: k_i | F2: Estimate_TWFE | G2: Estimate_controls | H2: Estimate_Pooled | I2: elasticity_new_TWFE | J2: elasticity_controls_new | K2: elasticity_new_Pooled | L2: elasticity_TWFE | M2: elasticity_controls | N2: elasticity_Pooled | O2: GDP_PPP | P2: gini | Q2: youth_unemp | R2: educ_spend_gdp | S2: tertiary_enroll | T2: net_migration | U2: log_gdp | X2: =WB_correlations!D2 -> Country | Y2: =WB_correlations!E2 -> elasticity_TWFE_new | Z2: =WB_correlations!F2 -> elasticity_controls_new | AA2: =WB_correlations!G2 -> elasticity_Pooled_new | AB2: =WB_correlations!H2 -> elasticity_TWFE_old | AC2: =WB_correlations!I2 -> elasticity_controls_old | AD2: =WB_correlations!J2 -> elasticity_Pooled_old | AE2: =WB_correlations!K2 -> GDP_per_cap | AG2: CHECK (difference)
A3: Belgium | B3: 59632 | C3: 51283.52 | D3: 8579.3385 | E3: 0.95073548 | F3: -0.602657 | G3: -0.575323 | H3: -0.43381198 | I3: -0.63388504 | J3: -0.60513467 | K3: -0.45629094 | L3: -0.68838209 | M3: -0.65715996 | N3: -0.49551967 | O3: 62561.781 | P3: 26.4 | Q3: 16.41 | R3: 6.2761102 | S3: 83.573647 | T3: 118615 | U3: 11.04391 | X3: =WB_correlations!D3 -> Belgium | Y3: =WB_correlations!E3 -> -0.63388504 | Z3: =WB_correlations!F3 -> -0.60513467 | AA3: =WB_correlations!G3 -> -0.45629094 | AB3: =WB_correlations!H3 -> -0.68838209 | AC3: =WB_correlations!I3 -> -0.65715996 | AD3: =WB_correlations!J3 -> -0.49551967 | AE3: =WB_correlations!K3 -> 11.04391 | AG3: =I3-Y3 -> 0 | AH3: =J3-Z3 -> 0 | AI3: =K3-AA3 -> -2.3160174e-10 | AJ3: =L3-AB3 -> 0 | AK3: =M3-AC3 -> 0 | AL3: =N3-AD3 -> -2.5151314e-10 | AM3: =AE3-U3 -> -7.2446582e-10
A4: Bulgaria | B4: 15387 | C4: 13232.82 | D4: 1 | E4: 10.007848 | F4: -1.887146 | G4: -1.785586 | H4: -1.0063262 | I4: -0.18856662 | J4: -0.17841858 | K4: -0.10055371 | L4: -2.1555835 | M4: -2.0395771 | N4: -1.1494713 | O4: 32433.794 | P4: 38.2 | Q4: 10.582 | R4: 4.50109 | S4: 84.129356 | T4: 26498 | U4: 10.386956 | X4: =WB_correlations!D4 -> Bulgaria | Y4: =WB_correlations!E4 -> -0.18856662 | Z4: =WB_correlations!F4 -> -0.17841858 | AA4: =WB_correlations!G4 -> -0.10055371 | AB4: =WB_correlations!H4 -> -2.1555835 | AC4: =WB_correlations!I4 -> -2.0395771 | AD4: =WB_correlations!J4 -> -1.1494713 | AE4: =WB_correlations!K4 -> 10.386956 | AG4: =I4-Y4 -> 0 | AH4: =J4-Z4 -> 0 | AI4: =K4-AA4 -> 1.3289606e-11 | AJ4: =L4-AB4 -> 0 | AK4: =M4-AC4 -> 0 | AL4: =N4-AD4 -> 1.519187e-10 | AM4: =AE4-U4 -> -1.5323671e-09
A5: Czechia | B5: 23998 | C5: 20638.28 | D5: 3021.0957 | E5: 1.9944727 | F5: -1.137201 | G5: -1.075068 | H5: -0.90086981 | I5: -0.57017626 | J5: -0.53902367 | K5: -0.45168319 | L5: -1.2989624 | M5: -1.2279913 | N5: -1.0290143 | O5: 48390.662 | P5: 25.9 | Q5: 6.72 | R5: 4.3029199 | S5: 70.81459 | T5: 329739 | U5: 10.787062 | X5: =WB_correlations!D5 -> Czechia | Y5: =WB_correlations!E5 -> -0.57017626 | Z5: =WB_correlations!F5 -> -0.53902367 | AA5: =WB_correlations!G5 -> -0.4516832 | AB5: =WB_correlations!H5 -> -1.2989624 | AC5: =WB_correlations!I5 -> -1.2279913 | AD5: =WB_correlations!J5 -> -1.0290143 | AE5: =WB_correlations!K5 -> 10.787062 | AG5: =I5-Y5 -> -9.9920072e-16 | AH5: =J5-Z5 -> -8.8817842e-16 | AI5: =K5-AA5 -> 7.4892204e-11 | AJ5: =L5-AB5 -> 0 | AK5: =M5-AC5 -> 0 | AL5: =N5-AD5 -> 1.7061907e-10 | AM5: =AE5-U5 -> 4.4068571e-10
A6: Denmark | B6: 71565 | C6: 61545.9 | D6: 8724.5305 | E6: 0.93395363 | F6: -1.046503 | G6: -1.029858 | H6: -1.6091993 | I6: -1.1205085 | J6: -1.1026864 | K6: -1.722997 | L6: -1.1953631 | M6: -1.1763504 | N6: -1.8381002 | O6: 69475.32 | P6: 29.3 | Q6: 10.533 | R6: 6.3558602 | S6: 84.586609 | T6: 60219 | U6: 11.148727 | X6: =WB_correlations!D6 -> Denmark | Y6: =WB_correlations!E6 -> -1.1205085 | Z6: =WB_correlations!F6 -> -1.1026864 | AA6: =WB_correlations!G6 -> -1.722997 | AB6: =WB_correlations!H6 -> -1.1953631 | AC6: =WB_correlations!I6 -> -1.1763504 | AD6: =WB_correlations!J6 -> -1.8381002 | AE6: =WB_correlations!K6 -> 11.148727 | AG6: =I6-Y6 -> 0 | AH6: =J6-Z6 -> 0 | AI6: =K6-AA6 -> -2.5489433e-10 | AJ6: =L6-AB6 -> 0 | AK6: =M6-AC6 -> 0 | AL6: =N6-AD6 -> -2.7192271e-10 | AM6: =AE6-U6 -> 5.0251003e-10
A7: Germany | B7: 53791 | C7: 46260.26 | D7: 8456.3829 | E7: 0.96517076 | F7: -0.6815 | G7: -0.581445 | H7: 0.65222662 | I7: -0.70609267 | J7: -0.60242708 | K7: 0.67576294 | L7: -0.77844013 | M7: -0.66415278 | N7: 0.74500276 | O7: 63676.088 | P7: 33.7 | Q7: 6.049 | R7: 5.2391601 | S7: 77.3657 | T7: 981552 | U7: 11.061564 | X7: =WB_correlations!D7 -> Germany | Y7: =WB_correlations!E7 -> -0.70609267 | Z7: =WB_correlations!F7 -> -0.60242708 | AA7: =WB_correlations!G7 -> 0.67576294 | AB7: =WB_correlations!H7 -> -0.77844013 | AC7: =WB_correlations!I7 -> -0.66415278 | AD7: =WB_correlations!J7 -> 0.74500276 | AE7: =WB_correlations!K7 -> 11.061564 | AG7: =I7-Y7 -> 0 | AH7: =J7-Z7 -> 0 | AI7: =K7-AA7 -> -2.2011648e-10 | AJ7: =L7-AB7 -> 0 | AK7: =M7-AC7 -> 0 | AL7: =N7-AD7 -> -2.4266988e-10 | AM7: =AE7-U7 -> -3.4248693e-10
A8: Estonia | B8: 26546 | C8: 22829.56 | D8: 4804.714 | E8: 1.5304948 | F8: -1.447445 | G8: -1.407405 | H8: -2.2370894 | I8: -0.94573665 | J8: -0.91957517 | K8: -1.4616773 | L8: -1.6533372 | M8: -1.6076017 | N8: -2.5553048 | O8: 43128.633 | P8: 32.3 | Q8: 18.392 | R8: 5.2073398 | S8: 71.425194 | T8: 39754 | U8: 10.671942 | X8: =WB_correlations!D8 -> Estonia | Y8: =WB_correlations!E8 -> -0.94573665 | Z8: =WB_correlations!F8 -> -0.91957517 | AA8: =WB_correlations!G8 -> -1.4616773 | AB8: =WB_correlations!H8 -> -1.6533372 | AC8: =WB_correlations!I8 -> -1.6076017 | AD8: =WB_correlations!J8 -> -2.5553048 | AE8: =WB_correlations!K8 -> 10.671942 | AG8: =I8-Y8 -> 0 | AH8: =J8-Z8 -> 0 | AI8: =K8-AA8 -> 1.2974222e-10 | AJ8: =L8-AB8 -> 0 | AK8: =M8-AC8 -> 0 | AL8: =N8-AD8 -> 2.2681634e-10 | AM8: =AE8-U8 -> 6.6399863e-10
A9: Greece | B9: 17954 | C9: 15440.44 | D9: 4.6283026 | E9: 8.4756574 | F9: -0.86575 | G9: -0.718908 | H9: 0.10535878 | I9: -0.10214547 | J9: -0.084820323 | K9: 0.01243075 | L9: -0.98889882 | M9: -0.82116924 | N9: 0.12034556 | O9: 35831.344 | P9: 33.4 | Q9: 31.29 | R9: 3.3754799 | S9: 166.38956 | T9: -53997 | U9: 10.486578 | X9: =WB_correlations!D9 -> Greece | Y9: =WB_correlations!E9 -> -0.10214547 | Z9: =WB_correlations!F9 -> -0.084820323 | AA9: =WB_correlations!G9 -> 0.01243075 | AB9: =WB_correlations!H9 -> -0.98889882 | AC9: =WB_correlations!I9 -> -0.82116924 | AD9: =WB_correlations!J9 -> 0.12034556 | AE9: =WB_correlations!K9 -> 10.486578 | AG9: =I9-Y9 -> -2.0400348e-15 | AH9: =J9-Z9 -> -1.7347235e-15 | AI9: =K9-AA9 -> 1.1697756e-11 | AJ9: =L9-AB9 -> 0 | AK9: =M9-AC9 -> 0 | AL9: =N9-AD9 -> 1.1324677e-10 | AM9: =AE9-U9 -> 6.1062444e-10
A10: Spain | B10: 33700 | C10: 28982 | D10: 6801.1286 | E10: 1.1830037 | F10: -0.507701 | G10: -0.473719 | H10: 0.96454423 | I10: -0.42916264 | J10: -0.40043745 | K10: 0.8153349 | L10: -0.57991905 | M10: -0.54110327 | N10: 1.1017461 | O10: 46733.481 | P10: 33.6 | Q10: 29.713 | R10: 4.5855398 | S10: 95.027161 | T10: 299779 | U10: 10.752216 | X10: =WB_correlations!D10 -> Spain | Y10: =WB_correlations!E10 -> -0.42916264 | Z10: =WB_correlations!F10 -> -0.40043745 | AA10: =WB_correlations!G10 -> 0.8153349 | AB10: =WB_correlations!H10 -> -0.57991905 | AC10: =WB_correlations!I10 -> -0.54110327 | AD10: =WB_correlations!J10 -> 1.1017461 | AE10: =WB_correlations!K10 -> 10.752216 | AG10: =I10-Y10 -> 7.2164497e-16 | AH10: =J10-Z10 -> 6.1062266e-16 | AI10: =K10-AA10 -> 1.683913e-10 | AJ10: =L10-AB10 -> 0 | AK10: =M10-AC10 -> 0 | AL10: =N10-AD10 -> 2.2754532e-10 | AM10: =AE10-U10 -> 4.6961013e-10
A11: France | B11: 43790 | C11: 37659.4 | D11: 8054.806 | E11: 1.0138234 | F11: -0.597106 | G11: -0.535495 | H11: 1.178993 | I11: -0.58896453 | J11: -0.52819359 | K11: 1.1629175 | L11: -0.68204149 | M11: -0.61166662 | N11: 1.3466991 | O11: 53673.814 | P11: 31.2 | Q11: 17.856 | R11: 5.3243499 | S11: 71.510727 | T11: 179377 | U11: 10.890681 | X11: =WB_correlations!D11 -> France | Y11: =WB_correlations!E11 -> -0.58896453 | Z11: =WB_correlations!F11 -> -0.52819359 | AA11: =WB_correlations!G11 -> 1.1629175 | AB11: =WB_correlations!H11 -> -0.68204149 | AC11: =WB_correlations!I11 -> -0.61166662 | AD11: =WB_correlations!J11 -> 1.3466991 | AE11: =WB_correlations!K11 -> 10.890681 | AG11: =I11-Y11 -> 0 | AH11: =J11-Z11 -> 0 | AI11: =K11-AA11 -> 3.953553e-10 | AJ11: =L11-AB11 -> 0 | AK11: =M11-AC11 -> 0 | AL11: =N11-AD11 -> 4.5783466e-10 | AM11: =AE11-U11 -> -7.5720941e-10
