Workbook

Sheet covariates_matrix
A1: Country_ISO | B1: COUNTRY_FULL | C1: Educ_spend_gdp | D1: GDP_growth | E1: Gini | F1: Inflation | G1: log_cons | H1: log_gdp | I1: log_gni | J1: log_pop | K1: Tertiary_attain | L1: Tertiary_enrol | M1: Unemp | N1: Youth_unemp | O1: IGE | P1: eta_0.04 | Q1: eta_0.075 | R1: eta_0.14 | S1: eta_0.04_Z | T1: eta_0.075_Z | U1: eta_0.14_Z | V1: Educ_spend_gdp | W1: GDP_growth | X1: Gini | Y1: Inflation | Z1: log_cons | AA1: log_gdp | AB1: log_gni | AC1: log_pop | AD1: Tertiary_attain | AE1: Tertiary_enrol | AF1: Unemp | AG1: Youth_unemp | AH1: IGE
A2: AT | B2: Austria | C2: 5.27749 | D2: 5.3309638 | E2: 30.9 | F2: 8.54687 | G2: 10.068442 | H2: 11.09277 | I2: 11.06734 | J2: 16.01737 | K2: 14.87918 | L2: 94.51169 | M2: 4.992 | N2: 10.327 | O2: 0.3334917 | P2: =VLOOKUP(B2,elasticities!$A$11:$D$35,2,FALSE) -> -0.6311931 | Q2: =VLOOKUP(B2,elasticities!$A$11:$D$35,3,FALSE) -> -0.5602358 | R2: =VLOOKUP(B2,elasticities!$A$11:$D$35,4,FALSE) -> -0.4696517 | S2: =(P2-AVERAGE($P$2:$P$26))/_xlfn.STDEV.S($P$2:$P$26) -> 1.0545188 | T2: =(Q2-AVERAGE($Q$2:$Q$26))/_xlfn.STDEV.S($Q$2:$Q$26) -> 0.86075011 | U2: =(Q2-AVERAGE($Q$2:$Q$26))/_xlfn.STDEV.S($Q$2:$Q$26) -> 0.86075011 | V2: =(C2-AVERAGE($C$2:$C$26))/_xlfn.STDEV.S($C$2:$C$26) -> 0.48692417 | W2: =(D2-AVERAGE($D$2:$D$26))/_xlfn.STDEV.S($D$2:$D$26) -> 0.75923605 | X2: =(E2-AVERAGE($E$2:$E$26))/_xlfn.STDEV.S($E$2:$E$26) -> -0.14292764
A3: BE | B3: Belgium | C3: 6.27611 | D3: 4.0246085 | E3: 26.4 | F3: 9.597512 | G3: 10.016499 | H3: 11.04457 | I3: 11.01925 | J3: 16.27341 | K3: 36.30749 | L3: 83.57365 | M3: 5.57 | N3: 16.41 | O3: 0.3582048 | P3: =VLOOKUP(B3,elasticities!$A$11:$D$35,2,FALSE) -> -0.7181885 | Q3: =VLOOKUP(B3,elasticities!$A$11:$D$35,3,FALSE) -> -0.6400927 | R3: =VLOOKUP(B3,elasticities!$A$11:$D$35,4,FALSE) -> -0.5392725 | S3: =(P3-AVERAGE($P$2:$P$26))/_xlfn.STDEV.S($P$2:$P$26) -> 0.92239408 | T3: =(Q3-AVERAGE($Q$2:$Q$26))/_xlfn.STDEV.S($Q$2:$Q$26) -> 0.68147438 | U3: =(Q3-AVERAGE($Q$2:$Q$26))/_xlfn.STDEV.S($Q$2:$Q$26) -> 0.68147438 | V3: =(C3-AVERAGE($C$2:$C$26))/_xlfn.STDEV.S($C$2:$C$26) -> 1.5013885 | W3: =(D3-AVERAGE($D$2:$D$26))/_xlfn.STDEV.S($D$2:$D$26) -> 0.25127953 | X3: =(E3-AVERAGE($E$2:$E$26))/_xlfn.STDEV.S($E$2:$E$26) -> -1.3395311
A4: BG | B4: Bulgaria | C4: 4.50109 | D4: 4.083864 | E4: 38.2 | F4: 15.325259 | G4: 8.736852 | H4: 10.38695 | I4: 10.28329 | J4: 15.68193 | K4: 26.00696 | L4: 84.12936 | M4: 4.148 | N4: 10.582 | O4: 0.6383207 | P4: =VLOOKUP(B4,elasticities!$A$11:$D$35,2,FALSE) -> -1.906783 | Q4: =VLOOKUP(B4,elasticities!$A$11:$D$35,3,FALSE) -> -1.2221638 | R4: =VLOOKUP(B4,elasticities!$A$11:$D$35,4,FALSE) -> -0.8081628 | S4: =(P4-AVERAGE($P$2:$P$26))/_xlfn.STDEV.S($P$2:$P$26) -> -0.88279063 | T4: =(Q4-AVERAGE($Q$2:$Q$26))/_xlfn.STDEV.S($Q$2:$Q$26) -> -0.62525328 | U4: =(Q4-AVERAGE($Q$2:$Q$26))/_xlfn.STDEV.S($Q$2:$Q$26) -> -0.62525328 | V4: =(C4-AVERAGE($C$2:$C$26))/_xlfn.STDEV.S($C$2:$C$26) -> -0.30179434 | W4: =(D4-AVERAGE($D$2:$D$26))/_xlfn.STDEV.S($D$2:$D$26) -> 0.27432014 | X4: =(E4-AVERAGE($E$2:$E$26))/_xlfn.STDEV.S($E$2:$E$26) -> 1.7982291
A5: CY | B5: Cyprus | C5: 4.74211 | D5: 8.7385468 | E5: 31.5 | F5: 8.395483 | G5: 9.833622 | H5: 10.83646 | I5: 10.72325 | J5: 14.10172 | K5: 33.16464 | L5: 105.38498 | M5: 6.806 | N5: 18.707 | O5: 0.5799067 | P5: =VLOOKUP(B5,elasticities!$A$11:$D$35,2,FALSE) -> -1.218459 | Q5: =VLOOKUP(B5,elasticities!$A$11:$D$35,3,FALSE) -> -0.7309305 | R5: =VLOOKUP(B5,elasticities!$A$11:$D$35,4,FALSE) -> -0.4555112 | S5: =(P5-AVERAGE($P$2:$P$26))/_xlfn.STDEV.S($P$2:$P$26) -> 0.16260539 | T5: =(Q5-AVERAGE($Q$2:$Q$26))/_xlfn.STDEV.S($Q$2:$Q$26) -> 0.47754695 | U5: =(Q5-AVERAGE($Q$2:$Q$26))/_xlfn.STDEV.S($Q$2:$Q$26) -> 0.47754695 | V5: =(C5-AVERAGE($C$2:$C$26))/_xlfn.STDEV.S($C$2:$C$26) -> -0.056950272 | W5: =(D5-AVERAGE($D$2:$D$26))/_xlfn.STDEV.S($D$2:$D$26) -> 2.0842232 | X5: =(E5-AVERAGE($E$2:$E$26))/_xlfn.STDEV.S($E$2:$E$26) -> 0.016619493
A6: CZ | B6: Czechia | C6: 4.30292 | D6: 2.8471707 | E6: 25.9 | F6: 15.100165 | G6: 9.174563 | H6: 10.78706 | I6: 10.72021 | J6: 16.18315 | K6: 22.28766 | L6: 70.81459 | M6: 2.224 | N6: 6.72 | O6: 0.4912439 | P6: =VLOOKUP(B6,elasticities!$A$11:$D$35,2,FALSE) -> -1.4719672 | Q6: =VLOOKUP(B6,elasticities!$A$11:$D$35,3,FALSE) -> -0.9492907 | R6: =VLOOKUP(B6,elasticities!$A$11:$D$35,4,FALSE) -> -0.6191261 | S6: =(P6-AVERAGE($P$2:$P$26))/_xlfn.STDEV.S($P$2:$P$26) -> -0.22241164 | T6: =(Q6-AVERAGE($Q$2:$Q$26))/_xlfn.STDEV.S($Q$2:$Q$26) -> -0.012663464 | U6: =(Q6-AVERAGE($Q$2:$Q$26))/_xlfn.STDEV.S($Q$2:$Q$26) -> -0.012663464 | V6: =(C6-AVERAGE($C$2:$C$26))/_xlfn.STDEV.S($C$2:$C$26) -> -0.50310855 | W6: =(D6-AVERAGE($D$2:$D$26))/_xlfn.STDEV.S($D$2:$D$26) -> -0.20654936 | X6: =(E6-AVERAGE($E$2:$E$26))/_xlfn.STDEV.S($E$2:$E$26) -> -1.472487
A7: DE | B7: Germany | C7: 5.23916 | D7: 1.8092581 | E7: 33.7 | F7: 6.872574 | G7: 10.079892 | H7: 11.06316 | I7: 11.07808 | J7: 18.23649 | K7: 29.57574 | L7: 77.3657 | M7: 3.137 | N7: 6.049 | O7: 0.3897916 | P7: =VLOOKUP(B7,elasticities!$A$11:$D$35,2,FALSE) -> -0.7315306 | Q7: =VLOOKUP(B7,elasticities!$A$11:$D$35,3,FALSE) -> -0.6362615 | R7: =VLOOKUP(B7,elasticities!$A$11:$D$35,4,FALSE) -> -0.5208939 | S7: =(P7-AVERAGE($P$2:$P$26))/_xlfn.STDEV.S($P$2:$P$26) -> 0.90213069 | T7: =(Q7-AVERAGE($Q$2:$Q$26))/_xlfn.STDEV.S($Q$2:$Q$26) -> 0.69007528 | U7: =(Q7-AVERAGE($Q$2:$Q$26))/_xlfn.STDEV.S($Q$2:$Q$26) -> 0.69007528 | V7: =(C7-AVERAGE($C$2:$C$26))/_xlfn.STDEV.S($C$2:$C$26) -> 0.44798602 | W7: =(D7-AVERAGE($D$2:$D$26))/_xlfn.STDEV.S($D$2:$D$26) -> -0.61012599 | X7: =(E7-AVERAGE($E$2:$E$26))/_xlfn.STDEV.S($E$2:$E$26) -> 0.60162563
A8: DK | B8: Denmark | C8: 6.35586 | D8: 0.4438326 | E8: 29.3 | F8: 7.696567 | G8: 10.227137 | H8: 11.14316 | I8: 11.19969 | J8: 15.59098 | K8: 33.08082 | L8: 84.58661 | M8: 4.434 | N8: 10.533 | O8: 0.2259895 | P8: =VLOOKUP(B8,elasticities!$A$11:$D$35,2,FALSE) -> -1.2563437 | Q8: =VLOOKUP(B8,elasticities!$A$11:$D$35,3,FALSE) -> -1.1533261 | R8: =VLOOKUP(B8,elasticities!$A$11:$D$35,4,FALSE) -> -1.0095158 | S8: =(P8-AVERAGE($P$2:$P$26))/_xlfn.STDEV.S($P$2:$P$26) -> 0.10506778 | T8: =(Q8-AVERAGE($Q$2:$Q$26))/_xlfn.STDEV.S($Q$2:$Q$26) -> -0.47071524 | U8: =(Q8-AVERAGE($Q$2:$Q$26))/_xlfn.STDEV.S($Q$2:$Q$26) -> -0.47071524 | V8: =(C8-AVERAGE($C$2:$C$26))/_xlfn.STDEV.S($C$2:$C$26) -> 1.5824038 | W8: =(D8-AVERAGE($D$2:$D$26))/_xlfn.STDEV.S($D$2:$D$26) -> -1.1410511 | X8: =(E8-AVERAGE($E$2:$E$26))/_xlfn.STDEV.S($E$2:$E$26) -> -0.56838664
A9: EE | B9: Estonia | C9: 5.20734 | D9: -1.2261697 | E9: 32.3 | F9: 19.398263 | G9: 9.349349 | H9: 10.67185 | I9: 10.66448 | J9: 14.11476 | K9: 32.66017 | L9: 71.42519 | M9: 5.571 | N9: 18.392 | O9: 0.3474851 | P9: =VLOOKUP(B9,elasticities!$A$11:$D$35,2,FALSE) -> -1.8044746 | Q9: =VLOOKUP(B9,elasticities!$A$11:$D$35,3,FALSE) -> -1.0204729 | R9: =VLOOKUP(B9,elasticities!$A$11:$D$35,4,FALSE) -> -0.615241 | S9: =(P9-AVERAGE($P$2:$P$26))/_xlfn.STDEV.S($P$2:$P$26) -> -0.72740916 | T9: =(Q9-AVERAGE($Q$2:$Q$26))/_xlfn.STDEV.S($Q$2:$Q$26) -> -0.17246482 | U9: =(Q9-AVERAGE($Q$2:$Q$26))/_xlfn.STDEV.S($Q$2:$Q$26) -> -0.17246482 | V9: =(C9-AVERAGE($C$2:$C$26))/_xlfn.STDEV.S($C$2:$C$26) -> 0.41566116 | W9: =(D9-AVERAGE($D$2:$D$26))/_xlfn.STDEV.S($D$2:$D$26) -> -1.7904062 | X9: =(E9-AVERAGE($E$2:$E$26))/_xlfn.STDEV.S($E$2:$E$26) -> 0.229349
A10: ES | B10: Spain | C10: 4.58554 | D10: 6.3703171 | E10: 33.6 | F10: 8.390576 | G10: 9.670609 | H10: 10.75222 | I10: 10.7349 | J10: 17.68225 | K10: 24.15342 | L10: 95.02716 | M10: 13.033 | N10: 29.713 | O10: 0.49607 | P10: =VLOOKUP(B10,elasticities!$A$11:$D$35,2,FALSE) -> -0.6087522 | Q10: =VLOOKUP(B10,elasticities!$A$11:$D$35,3,FALSE) -> -0.4546566 | R10: =VLOOKUP(B10,elasticities!$A$11:$D$35,4,FALSE) -> -0.3238962 | S10: =(P10-AVERAGE($P$2:$P$26))/_xlfn.STDEV.S($P$2:$P$26) -> 1.0886011 | T10: =(Q10-AVERAGE($Q$2:$Q$26))/_xlfn.STDEV.S($Q$2:$Q$26) -> 1.0977714 | U10: =(Q10-AVERAGE($Q$2:$Q$26))/_xlfn.STDEV.S($Q$2:$Q$26) -> 1.0977714 | V10: =(C10-AVERAGE($C$2:$C$26))/_xlfn.STDEV.S($C$2:$C$26) -> -0.21600444 | W10: =(D10-AVERAGE($D$2:$D$26))/_xlfn.STDEV.S($D$2:$D$26) -> 1.1633729 | X10: =(E10-AVERAGE($E$2:$E$26))/_xlfn.STDEV.S($E$2:$E$26) -> 0.57503444
A11: FI | B11: Finland | C11: 6.37578 | D11: 0.7630419 | E11: 27.9 | F11: 7.123508 | G11: 10.075524 | H11: 10.952 | I11: 10.95949 | J11: 15.53041 | K11: 28.86382 | L11: 104.94422 | M11: 6.719 | N11: 14.138 | O11: 0.1449637 | P11: =VLOOKUP(B11,elasticities!$A$11:$D$35,2,FALSE) -> -2.0263068 | Q11: =VLOOKUP(B11,elasticities!$A$11:$D$35,3,FALSE) -> -1.7187965 | R11: =VLOOKUP(B11,elasticities!$A$11:$D$35,4,FALSE) -> -1.3692607 | S11: =(P11-AVERAGE($P$2:$P$26))/_xlfn.STDEV.S($P$2:$P$26) -> -1.0643181 | T11: =(Q11-AVERAGE($Q$2:$Q$26))/_xlfn.STDEV.S($Q$2:$Q$26) -> -1.740175 | U11: =(Q11-AVERAGE($Q$2:$Q$26))/_xlfn.STDEV.S($Q$2:$Q$26) -> -1.740175 | V11: =(C11-AVERAGE($C$2:$C$26))/_xlfn.STDEV.S($C$2:$C$26) -> 1.6026399 | W11: =(D11-AVERAGE($D$2:$D$26))/_xlfn.STDEV.S($D$2:$D$26) -> -1.0169314 | X11: =(E11-AVERAGE($E$2:$E$26))/_xlfn.STDEV.S($E$2:$E$26) -> -0.94066328
A12: FR | B12: France | C12: 5.32435 | D12: 2.7167626 | E12: 31.2 | F12: 5.222367 | G12: 9.952116 | H12: 10.89068 | I12: 10.90701 | J12: 18.03773 | K12: 23.58888 | L12: 71.51073 | M12: 7.303 | N12: 17.856 | O12: 0.420066 | P12: =VLOOKUP(B12,elasticities!$A$11:$D$35,2,FALSE) -> -0.6909012 | Q12: =VLOOKUP(B12,elasticities!$A$11:$D$35,3,FALSE) -> -0.584589 | R12: =VLOOKUP(B12,elasticities!$A$11:$D$35,4,FALSE) -> -0.4644025 | S12: =(P12-AVERAGE($P$2:$P$26))/_xlfn.STDEV.S($P$2:$P$26) -> 0.96383682 | T12: =(Q12-AVERAGE($Q$2:$Q$26))/_xlfn.STDEV.S($Q$2:$Q$26) -> 0.80607809 | U12: =(Q12-AVERAGE($Q$2:$Q$26))/_xlfn.STDEV.S($Q$2:$Q$26) -> 0.80607809 | V12: =(C12-AVERAGE($C$2:$C$26))/_xlfn.STDEV.S($C$2:$C$26) -> 0.53452766 | W12: =(D12-AVERAGE($D$2:$D$26))/_xlfn.STDEV.S($D$2:$D$26) -> -0.25725658 | X12: =(E12-AVERAGE($E$2:$E$26))/_xlfn.STDEV.S($E$2:$E$26) -> -0.063154072
A13: GR | B13: Greece | C13: 3.37548 | D13: 5.5219858 | E13: 33.4 | F13: 9.64526 | G13: 9.59979 | H13: 10.48649 | I13: 10.47301 | J13: 16.16094 | K13: 28.93045 | L13: 166.38956 | M13: 12.426 | N13: 31.29 | O13: 0.3331187 | P13: =VLOOKUP(B13,elasticities!$A$11:$D$35,2,FALSE) -> -0.4603667 | Q13: =VLOOKUP(B13,elasticities!$A$11:$D$35,3,FALSE) -> -0.3204047 | R13: =VLOOKUP(B13,elasticities!$A$11:$D$35,4,FALSE) -> -0.2146625 | S13: =(P13-AVERAGE($P$2:$P$26))/_xlfn.STDEV.S($P$2:$P$26) -> 1.3139624 | T13: =(Q13-AVERAGE($Q$2:$Q$26))/_xlfn.STDEV.S($Q$2:$Q$26) -> 1.3991619 | U13: =(Q13-AVERAGE($Q$2:$Q$26))/_xlfn.STDEV.S($Q$2:$Q$26) -> 1.3991619 | V13: =(C13-AVERAGE($C$2:$C$26))/_xlfn.STDEV.S($C$2:$C$26) -> -1.4452635 | W13: =(D13-AVERAGE($D$2:$D$26))/_xlfn.STDEV.S($D$2:$D$26) -> 0.83351207 | X13: =(E13-AVERAGE($E$2:$E$26))/_xlfn.STDEV.S($E$2:$E$26) -> 0.52185206
A14: HR | B14: Croatia | C14: 4.09166 | D14: 7.2947911 | E14: 30 | F14: 10.780581 | G14: 9.194003 | H14: 10.59323 | I14: 10.55851 | J14: 15.16505 | K14: 19.69295 | L14: 80.76267 | M14: 6.811 | N14: 17.744 | O14: 0.3494334 | P14: =VLOOKUP(B14,elasticities!$A$11:$D$35,2,FALSE) -> -2.1014019 | Q14: =VLOOKUP(B14,elasticities!$A$11:$D$35,3,FALSE) -> -1.3195079 | R14: =VLOOKUP(B14,elasticities!$A$11:$D$35,4,FALSE) -> -0.8492813 | S14: =(P14-AVERAGE($P$2:$P$26))/_xlfn.STDEV.S($P$2:$P$26) -> -1.1783692 | T14: =(Q14-AVERAGE($Q$2:$Q$26))/_xlfn.STDEV.S($Q$2:$Q$26) -> -0.84378711 | U14: =(Q14-AVERAGE($Q$2:$Q$26))/_xlfn.STDEV.S($Q$2:$Q$26) -> -0.84378711 | V14: =(C14-AVERAGE($C$2:$C$26))/_xlfn.STDEV.S($C$2:$C$26) -> -0.71772044 | W14: =(D14-AVERAGE($D$2:$D$26))/_xlfn.STDEV.S($D$2:$D$26) -> 1.5228406 | X14: =(E14-AVERAGE($E$2:$E$26))/_xlfn.STDEV.S($E$2:$E$26) -> -0.38224833
A15: HU | B15: Hungary | C15: 3.8012 | D15: 4.1523806 | E15: NA | F15: 14.608144 | G15: 9.076741 | H15: 10.61179 | I15: 10.53659 | J15: 16.0778 | K15: 24.66472 | L15: 60.27468 | M15: 3.583 | N15: 10.541 | O15: 0.4748306 | P15: =VLOOKUP(B15,elasticities!$A$11:$D$35,2,FALSE) -> -0.7174964 | Q15: =VLOOKUP(B15,elasticities!$A$11:$D$35,3,FALSE) -> -0.48991 | R15: =VLOOKUP(B15,elasticities!$A$11:$D$35,4,FALSE) -> -0.3252514 | S15: =(P15-AVERAGE($P$2:$P$26))/_xlfn.STDEV.S($P$2:$P$26) -> 0.92344521 | T15: =(Q15-AVERAGE($Q$2:$Q$26))/_xlfn.STDEV.S($Q$2:$Q$26) -> 1.0186289 | U15: =(Q15-AVERAGE($Q$2:$Q$26))/_xlfn.STDEV.S($Q$2:$Q$26) -> 1.0186289 | V15: =(C15-AVERAGE($C$2:$C$26))/_xlfn.STDEV.S($C$2:$C$26) -> -1.0127889 | W15: =(D15-AVERAGE($D$2:$D$26))/_xlfn.STDEV.S($D$2:$D$26) -> 0.30096178 | X15: =(E15-AVERAGE($E$2:$E$26))/_xlfn.STDEV.S($E$2:$E$26) -> #VALUE!
A16: IT | B16: Italy | C16: 4.06776 | D16: 4.8211767 | E16: 33.7 | F16: 8.20129 | G16: 9.871999 | H16: 10.86539 | I16: 10.84347 | J16: 17.89328 | K16: 16.49017 | L16: 73.89621 | M16: 8.069 | N16: 23.704 | O16: 0.4547262 | P16: =VLOOKUP(B16,elasticities!$A$11:$D$35,2,FALSE) -> -1.0360092 | Q16: =VLOOKUP(B16,elasticities!$A$11:$D$35,3,FALSE) -> -0.7709308 | R16: =VLOOKUP(B16,elasticities!$A$11:$D$35,4,FALSE) -> -0.5476996 | S16: =(P16-AVERAGE($P$2:$P$26))/_xlfn.STDEV.S($P$2:$P$26) -> 0.43970207 | T16: =(Q16-AVERAGE($Q$2:$Q$26))/_xlfn.STDEV.S($Q$2:$Q$26) -> 0.38774778 | U16: =(Q16-AVERAGE($Q$2:$Q$26))/_xlfn.STDEV.S($Q$2:$Q$26) -> 0.38774778 | V16: =(C16-AVERAGE($C$2:$C$26))/_xlfn.STDEV.S($C$2:$C$26) -> -0.74199964 | W16: =(D16-AVERAGE($D$2:$D$26))/_xlfn.STDEV.S($D$2:$D$26) -> 0.56101304 | X16: =(E16-AVERAGE($E$2:$E$26))/_xlfn.STDEV.S($E$2:$E$26) -> 0.60162563
A17: LT | B17: Lithuania | C17: 4.25285 | D17: 2.4653201 | E17: 36.6 | F17: 19.705046 | G17: 9.297887 | H17: 10.75027 | I17: 10.6492 | J17: 14.85637 | K17: 41.41495 | L17: 76.91546 | M17: 5.955 | N17: 11.873 | O17: 0.4023293 | P17: =VLOOKUP(B17,elasticities!$A$11:$D$35,2,FALSE) -> -2.9275287 | Q17: =VLOOKUP(B17,elasticities!$A$11:$D$35,3,FALSE) -> -2.2043226 | R17: =VLOOKUP(B17,elasticities!$A$11:$D$35,4,FALSE) -> -1.579713 | S17: =(P17-AVERAGE($P$2:$P$26))/_xlfn.STDEV.S($P$2:$P$26) -> -2.433054 | T17: =(Q17-AVERAGE($Q$2:$Q$26))/_xlfn.STDEV.S($Q$2:$Q$26) -> -2.8301627 | U17: =(Q17-AVERAGE($Q$2:$Q$26))/_xlfn.STDEV.S($Q$2:$Q$26) -> -2.8301627 | V17: =(C17-AVERAGE($C$2:$C$26))/_xlfn.STDEV.S($C$2:$C$26) -> -0.55397297 | W17: =(D17-AVERAGE($D$2:$D$26))/_xlfn.STDEV.S($D$2:$D$26) -> -0.3550262 | X17: =(E17-AVERAGE($E$2:$E$26))/_xlfn.STDEV.S($E$2:$E$26) -> 1.3727701
A18: LU | B18: Luxembourg | C18: 3.74452 | D18: -1.0974126 | E18: 34.1 | F18: 6.336008 | G18: 10.512934 | H18: 11.79487 | I18: 11.35294 | J18: 13.38949 | K18: 42.03513 | L18: 21.0326 | M18: 4.588 | N18: 17.599 | O18: 0.465603 | P18: =VLOOKUP(B18,elasticities!$A$11:$D$35,2,FALSE) -> -0.6961173 | Q18: =VLOOKUP(B18,elasticities!$A$11:$D$35,3,FALSE) -> -0.6486761 | R18: =VLOOKUP(B18,elasticities!$A$11:$D$35,4,FALSE) -> -0.5796385 | S18: =(P18-AVERAGE($P$2:$P$26))/_xlfn.STDEV.S($P$2:$P$26) -> 0.95591484 | T18: =(Q18-AVERAGE($Q$2:$Q$26))/_xlfn.STDEV.S($Q$2:$Q$26) -> 0.66220497 | U18: =(Q18-AVERAGE($Q$2:$Q$26))/_xlfn.STDEV.S($Q$2:$Q$26) -> 0.66220497 | V18: =(C18-AVERAGE($C$2:$C$26))/_xlfn.STDEV.S($C$2:$C$26) -> -1.0703682 | W18: =(D18-AVERAGE($D$2:$D$26))/_xlfn.STDEV.S($D$2:$D$26) -> -1.740341 | X18: =(E18-AVERAGE($E$2:$E$26))/_xlfn.STDEV.S($E$2:$E$26) -> 0.70799038
A19: LV | B19: Latvia | C19: 4.31967 | D19: 1.9085342 | E19: 33.7 | F19: 17.310283 | G19: 9.196285 | H19: 10.53791 | I19: 10.49653 | J19: 14.44645 | K19: 32.57349 | L19: 91.33037 | M19: 6.815 | N19: 15.27 | O19: 0.4793727 | P19: =VLOOKUP(B19,elasticities!$A$11:$D$35,2,FALSE) -> -1.9315724 | Q19: =VLOOKUP(B19,elasticities!$A$11:$D$35,3,FALSE) -> -1.1325831 | R19: =VLOOKUP(B19,elasticities!$A$11:$D$35,4,FALSE) -> -0.7064287 | S19: =(P19-AVERAGE($P$2:$P$26))/_xlfn.STDEV.S($P$2:$P$26) -> -0.92043968 | T19: =(Q19-AVERAGE($Q$2:$Q$26))/_xlfn.STDEV.S($Q$2:$Q$26) -> -0.42414799 | U19: =(Q19-AVERAGE($Q$2:$Q$26))/_xlfn.STDEV.S($Q$2:$Q$26) -> -0.42414799 | V19: =(C19-AVERAGE($C$2:$C$26))/_xlfn.STDEV.S($C$2:$C$26) -> -0.48609279 | W19: =(D19-AVERAGE($D$2:$D$26))/_xlfn.STDEV.S($D$2:$D$26) -> -0.57152398 | X19: =(E19-AVERAGE($E$2:$E$26))/_xlfn.STDEV.S($E$2:$E$26) -> 0.60162563
A20: MT | B20: Malta | C20: 4.71258 | D20: 2.5927678 | E20: 34.6 | F20: 6.153756 | G20: 9.591231 | H20: 10.9486 | I20: 10.8588 | J20: 13.18273 | K20: 24.44054 | L20: 74.59013 | M20: 3.471 | N20: 9.064 | O20: 0.6387131 | P20: =VLOOKUP(B20,elasticities!$A$11:$D$35,2,FALSE) -> -0.6717079 | Q20: =VLOOKUP(B20,elasticities!$A$11:$D$35,3,FALSE) -> -0.4995946 | R20: =VLOOKUP(B20,elasticities!$A$11:$D$35,4,FALSE) -> -0.3547995 | S20: =(P20-AVERAGE($P$2:$P$26))/_xlfn.STDEV.S($P$2:$P$26) -> 0.99298676 | T20: =(Q20-AVERAGE($Q$2:$Q$26))/_xlfn.STDEV.S($Q$2:$Q$26) -> 0.99688732 | U20: =(Q20-AVERAGE($Q$2:$Q$26))/_xlfn.STDEV.S($Q$2:$Q$26) -> 0.99688732 | V20: =(C20-AVERAGE($C$2:$C$26))/_xlfn.STDEV.S($C$2:$C$26) -> -0.086948801 | W20: =(D20-AVERAGE($D$2:$D$26))/_xlfn.STDEV.S($D$2:$D$26) -> -0.30547009 | X20: =(E20-AVERAGE($E$2:$E$26))/_xlfn.STDEV.S($E$2:$E$26) -> 0.84094632
A21: PL | B21: Poland | C21: 4.31373 | D21: 5.255457 | E21: 28.9 | F21: 14.429451 | G21: 9.204532 | H21: 10.67833 | I21: 10.61905 | J21: 17.4216 | K21: 27.72372 | L21: 75.29111 | M21: 2.811 | N21: 10.56 | O21: 0.3560595 | P21: =VLOOKUP(B21,elasticities!$A$11:$D$35,2,FALSE) -> -1.8951127 | Q21: =VLOOKUP(B21,elasticities!$A$11:$D$35,3,FALSE) -> -1.1203355 | R21: =VLOOKUP(B21,elasticities!$A$11:$D$35,4,FALSE) -> -0.7015335 | S21: =(P21-AVERAGE($P$2:$P$26))/_xlfn.STDEV.S($P$2:$P$26) -> -0.8650663 | T21: =(Q21-AVERAGE($Q$2:$Q$26))/_xlfn.STDEV.S($Q$2:$Q$26) -> -0.39665259 | U21: =(Q21-AVERAGE($Q$2:$Q$26))/_xlfn.STDEV.S($Q$2:$Q$26) -> -0.39665259 | V21: =(C21-AVERAGE($C$2:$C$26))/_xlfn.STDEV.S($C$2:$C$26) -> -0.49212703 | W21: =(D21-AVERAGE($D$2:$D$26))/_xlfn.STDEV.S($D$2:$D$26) -> 0.72987637 | X21: =(E21-AVERAGE($E$2:$E$26))/_xlfn.STDEV.S($E$2:$E$26) -> -0.6747514
A22: PT | B22: Portugal | C22: 4.55161 | D22: 6.9858414 | E22: 36.3 | F22: 7.832691 | G22: 9.564911 | H22: 10.62305 | I22: 10.58709 | J22: 16.16061 | K22: 23.12239 | L22: 75.07148 | M22: 6.138 | N22: 19.183 | O22: 0.4016885 | P22: =VLOOKUP(B22,elasticities!$A$11:$D$35,2,FALSE) -> -1.139278 | Q22: =VLOOKUP(B22,elasticities!$A$11:$D$35,3,FALSE) -> -0.7606878 | R22: =VLOOKUP(B22,elasticities!$A$11:$D$35,4,FALSE) -> -0.5052611 | S22: =(P22-AVERAGE($P$2:$P$26))/_xlfn.STDEV.S($P$2:$P$26) -> 0.28286199 | T22: =(Q22-AVERAGE($Q$2:$Q$26))/_xlfn.STDEV.S($Q$2:$Q$26) -> 0.41074293 | U22: =(Q22-AVERAGE($Q$2:$Q$26))/_xlfn.STDEV.S($Q$2:$Q$26) -> 0.41074293 | V22: =(C22-AVERAGE($C$2:$C$26))/_xlfn.STDEV.S($C$2:$C$26) -> -0.25047278 | W22: =(D22-AVERAGE($D$2:$D$26))/_xlfn.STDEV.S($D$2:$D$26) -> 1.4027102 | X22: =(E22-AVERAGE($E$2:$E$26))/_xlfn.STDEV.S($E$2:$E$26) -> 1.2929965
A23: RO | B23: Romania | C23: 3.27882 | D23: 4.1877131 | E23: 32.3 | F23: 13.795489 | G23: 9.025929 | H23: 10.57788 | I23: 10.54992 | J23: 16.7625 | K23: 15.28347 | L23: 58.23904 | M23: 5.614 | N23: 22.874 | O23: 0.5629336 | P23: =VLOOKUP(B23,elasticities!$A$11:$D$35,2,FALSE) -> -2.420309 | Q23: =VLOOKUP(B23,elasticities!$A$11:$D$35,3,FALSE) -> -1.6501928 | R23: =VLOOKUP(B23,elasticities!$A$11:$D$35,4,FALSE) -> -1.1079519 | S23: =(P23-AVERAGE($P$2:$P$26))/_xlfn.STDEV.S($P$2:$P$26) -> -1.6627112 | T23: =(Q23-AVERAGE($Q$2:$Q$26))/_xlfn.STDEV.S($Q$2:$Q$26) -> -1.5861622 | U23: =(Q23-AVERAGE($Q$2:$Q$26))/_xlfn.STDEV.S($Q$2:$Q$26) -> -1.5861622 | V23: =(C23-AVERAGE($C$2:$C$26))/_xlfn.STDEV.S($C$2:$C$26) -> -1.5434571 | W23: =(D23-AVERAGE($D$2:$D$26))/_xlfn.STDEV.S($D$2:$D$26) -> 0.31470029 | X23: =(E23-AVERAGE($E$2:$E$26))/_xlfn.STDEV.S($E$2:$E$26) -> 0.229349
A24: SE | B24: Sweden | C24: 7.3191 | D24: 1.2554362 | E24: 31.6 | F24: 8.369291 | G24: 10.146343 | H24: 11.04363 | I24: 11.07484 | J24: 16.16564 | K24: 33.66415 | L24: 83.89761 | M24: 7.417 | N24: 21.597 | O24: 0.136586 | P24: =VLOOKUP(B24,elasticities!$A$11:$D$35,2,FALSE) -> -1.1550249 | Q24: =VLOOKUP(B24,elasticities!$A$11:$D$35,3,FALSE) -> -0.9578526 | R24: =VLOOKUP(B24,elasticities!$A$11:$D$35,4,FALSE) -> -0.7456929 | S24: =(P24-AVERAGE($P$2:$P$26))/_xlfn.STDEV.S($P$2:$P$26) -> 0.25894629 | T24: =(Q24-AVERAGE($Q$2:$Q$26))/_xlfn.STDEV.S($Q$2:$Q$26) -> -0.031884607 | U24: =(Q24-AVERAGE($Q$2:$Q$26))/_xlfn.STDEV.S($Q$2:$Q$26) -> -0.031884607 | V24: =(C24-AVERAGE($C$2:$C$26))/_xlfn.STDEV.S($C$2:$C$26) -> 2.5609268 | W24: =(D24-AVERAGE($D$2:$D$26))/_xlfn.STDEV.S($D$2:$D$26) -> -0.82547127 | X24: =(E24-AVERAGE($E$2:$E$26))/_xlfn.STDEV.S($E$2:$E$26) -> 0.043210681
A25: SI | B25: Slovenia | C25: 5.28065 | D25: 2.6685056 | E25: 24.3 | F25: 8.833699 | G25: 9.52219 | H25: 10.75916 | I25: 10.71675 | J25: 14.56318 | K25: 26.08932 | L25: 82.39226 | M25: 4.011 | N25: 10.14 | O25: 0.2494575 | P25: =VLOOKUP(B25,elasticities!$A$11:$D$35,2,FALSE) -> -1.5048475 | Q25: =VLOOKUP(B25,elasticities!$A$11:$D$35,3,FALSE) -> -1.1561129 | R25: =VLOOKUP(B25,elasticities!$A$11:$D$35,4,FALSE) -> -0.8415007 | S25: =(P25-AVERAGE($P$2:$P$26))/_xlfn.STDEV.S($P$2:$P$26) -> -0.27234879 | T25: =(Q25-AVERAGE($Q$2:$Q$26))/_xlfn.STDEV.S($Q$2:$Q$26) -> -0.4769715 | U25: =(Q25-AVERAGE($Q$2:$Q$26))/_xlfn.STDEV.S($Q$2:$Q$26) -> -0.4769715 | V25: =(C25-AVERAGE($C$2:$C$26))/_xlfn.STDEV.S($C$2:$C$26) -> 0.49013431 | W25: =(D25-AVERAGE($D$2:$D$26))/_xlfn.STDEV.S($D$2:$D$26) -> -0.27602059 | X25: =(E25-AVERAGE($E$2:$E$26))/_xlfn.STDEV.S($E$2:$E$26) -> -1.897946
A26: SK | B26: Slovakia | C26: 4.65689 | D26: 0.5445916 | E26: 24.1 | F26: 12.774146 | G26: 9.320139 | H26: 10.56228 | I26: 10.49298 | J26: 15.50777 | K26: 25.77268 | L26: 52.49591 | M26: 6.143 | N26: 19.924 | O26: 0.4550256 | P26: =VLOOKUP(B26,elasticities!$A$11:$D$35,2,FALSE) -> -1.4164243 | Q26: =VLOOKUP(B26,elasticities!$A$11:$D$35,3,FALSE) -> -0.8893191 | R26: =VLOOKUP(B26,elasticities!$A$11:$D$35,4,FALSE) -> -0.5713938 | S26: =(P26-AVERAGE($P$2:$P$26))/_xlfn.STDEV.S($P$2:$P$26) -> -0.13805555 | T26: =(Q26-AVERAGE($Q$2:$Q$26))/_xlfn.STDEV.S($Q$2:$Q$26) -> 0.12197052 | U26: =(Q26-AVERAGE($Q$2:$Q$26))/_xlfn.STDEV.S($Q$2:$Q$26) -> 0.12197052 | V26: =(C26-AVERAGE($C$2:$C$26))/_xlfn.STDEV.S($C$2:$C$26) -> -0.14352239 | W26: =(D26-AVERAGE($D$2:$D$26))/_xlfn.STDEV.S($D$2:$D$26) -> -1.1018725 | X26: =(E26-AVERAGE($E$2:$E$26))/_xlfn.STDEV.S($E$2:$E$26) -> -1.9511284
B29: AT | C29: 2022 | D29: =LN(WB_PULL_CHECK!I8) -> 11.09277
B30: AUS | C30: 0.2700792 | D30: Author estimate
B31: AUT | C31: =WB_PULL_CHECK!B5 -> 0.3334917 | D31: Author estimate
C33: =WB_PULL_CHECK!I3 -> GDP_PPP_pc | D33: =WB_PULL_CHECK!J3 -> GNI_PPP_pc | E33: =WB_PULL_CHECK!K3 -> HH_cons_pc | F33: =WB_PULL_CHECK!L3 -> Gini | G33: =WB_PULL_CHECK!M3 -> Unemp | H33: =WB_PULL_CHECK!N3 -> Youth_unemp | I33: =WB_PULL_CHECK!O3 -> Educ_spend_gdp | J33: =WB_PULL_CHECK!P3 -> Tertiary_enrol | ... R33: =WB_PULL_CHECK!X3 -> log_pop
A34: =B13 -> Greece | B34: 2022 | C34: =LN(WB_PULL_CHECK!I68) -> 10.48649 | D34: =LN(WB_PULL_CHECK!J68) -> 10.473008 | E34: =LN(WB_PULL_CHECK!K68) -> 9.5997904 | F34: =WB_PULL_CHECK!L68 -> 33.4 | G34: =WB_PULL_CHECK!M68 -> 12.426 | H34: =WB_PULL_CHECK!N68 -> 31.29 | I34: =LN(WB_PULL_CHECK!O68) -> 1.2165375 | J34: =LN(WB_PULL_CHECK!P68) -> 5.1143318 | K34: =LN(WB_PULL_CHECK!Q68) -> 3.3648947 | L34: =LN(WB_PULL_CHECK!R68) -> 1.7087375 | M34: =LN(WB_PULL_CHECK!S68) -> 2.2664666 | N34: =LN(WB_PULL_CHECK!T68) -> 16.160945 | O34: =LN(WB_PULL_CHECK!U68) -> 2.2617412 | P34: =LN(WB_PULL_CHECK!V68) -> 2.3500878 | ... R34: =LN(WB_PULL_CHECK!X68) -> 2.7825972
C35: =H13 -> 10.48649 | D35: =I13 -> 10.47301 | E35: =G13 -> 9.59979 | F35: =E13 -> 33.4 | G35: =M13 -> 12.426 | H35: =N13 -> 31.29 | I35: =C13 -> 3.37548 | J35: =L13 -> 166.38956 | N35: =J13 -> 16.16094

Sheet WB_PULL_CHECK
A1: from STATA
A2: code | B2: IGE | C2: source
A3: ARG | B3: 0.642 | C3: Jimenez 2011 | G3: iso2c | H3: year | I3: GDP_PPP_pc | J3: GNI_PPP_pc | K3: HH_cons_pc | L3: Gini | M3: Unemp | N3: Youth_unemp | O3: Educ_spend_gdp | P3: Tertiary_enrol | Q3: Tertiary_attain | R3: GDP_growth | S3: Inflation | T3: Population | U3: log_cons | V3: log_gdp | W3: log_gni | X3: log_pop
A4: AUS | B4: 0.2700792 | C4: Author estimate | F4: 1 | G4: AT | H4: 2018 | I4: 63777.94 | J4: 63521.33 | K4: 23450.163 | L4: 30.8 | M4: 4.933 | N4: 9.572 | O4: 5.25437 | P4: 85.86989 | Q4: 14.79561 | R4: 2.4842211 | S4: 1.9983798 | T4: 8840521 | U4: 10.062633 | V4: 11.06316 | W4: 11.05913 | X4: 15.99486
A5: AUT | B5: 0.3334917 | C5: Author estimate | F5: 2 | G5: AT | H5: 2019 | I5: 64609.28 | J5: 64512.44 | K5: 23506.085 | L5: 30.2 | M5: 4.56 | N5: 8.767 | O5: 5.23678 | P5: 86.32343 | Q5: 15.36363 | R5: 1.7549762 | S5: 1.5308956 | T5: 8879920 | U5: 10.065015 | V5: 11.07611 | W5: 11.07461 | X5: 15.9993
A6: BEL | B6: 0.3582048 | C6: Author estimate | F6: 3 | G6: AT | H6: 2020 | I6: 60276.33 | J6: 61260.45 | K6: 21635.354 | L6: 29.8 | M6: 5.201 | N6: 10.325 | O6: 5.57962 | P6: 88.7072 | Q6: 15.9696 | R6: -6.3182551 | S6: 1.3819106 | T6: 8916864 | U6: 9.982084 | V6: 11.00669 | W6: 11.02289 | X6: 16.00345
A7: BGR | B7: 0.6383207 | C7: Author estimate | F7: 4 | G7: AT | H7: 2021 | I7: 62968.85 | J7: 64007.47 | K7: 22600.486 | L7: 30.7 | M7: 6.459 | N7: 12.023 | O7: 5.48071 | P7: 93.94007 | Q7: 14.87918 | R7: 4.9230917 | S7: 2.7666667 | T7: 8955797 | U7: 10.025727 | V7: 11.0504 | W7: 11.06676 | X7: 16.00781
A8: BIH | B8: 0.5347345 | C8: Author estimate | F8: 5 | G8: AT | H8: 2022 | I8: 65694.46 | J8: 64044.88 | K8: 23586.796 | L8: 30.9 | M8: 4.992 | N8: 10.327 | O8: 5.27749 | P8: 94.51169 | Q8: NA | R8: 5.3309638 | S8: 8.5468699 | T8: 9041851 | U8: 10.068442 | V8: 11.09277 | W8: 11.06734 | X8: 16.01737
A9: BOL | B9: 0.4785001 | C9: Author estimate | F9: 6 | G9: BE | H9: 2018 | I9: 59357.69 | J9: 60040.29 | K9: 22209.966 | L9: 27.2 | M9: 5.941 | N9: 15.748 | O9: 6.38883 | P9: 79.12375 | Q9: 33.78887 | R9: 1.8779685 | S9: 2.053165 | T9: 11427054 | U9: 10.008296 | V9: 10.99134 | W9: 11.00277 | X9: 16.25149
A10: BRA | B10: 0.5422579 | C10: Author estimate | F10: 7 | G10: BE | H10: 2019 | I10: 60479.98 | J10: 61434.17 | K10: 22409.893 | L10: 27.2 | M10: 5.364 | N10: 14.236 | O10: 6.32381 | P10: 79.30448 | Q10: 35.30401 | R10: 2.44289 | S10: 1.4368196 | T10: 11488980 | U10: 10.017258 | V10: 11.01007 | W10: 11.02572 | X10: 16.2569
A11: CAN | B11: 0.1975056 | C11: Author estimate | F11: 8 | G11: BE | H11: 2020 | I11: 57333.54 | J11: 58454.92 | K11: 20708.131 | L11: 26 | M11: 5.545 | N11: 15.326 | O11: 6.7547 | P11: 79.4996 | Q11: 35.46608 | R11: -4.7929839 | S11: 0.74079181 | T11: 11538604 | U11: 9.938282 | V11: 10.95664 | W11: 10.97601 | X11: 16.26121
A12: CHE | B12: 0.277187 | C12: Author estimate | F12: 9 | G12: BE | H12: 2021 | I12: 60669.21 | J12: 61451.4 | K12: 21773.539 | L12: 26.6 | M12: 6.248 | N12: 18.206 | O12: 6.38082 | P12: 82.6882 | Q12: 37.58135 | R12: 6.2544569 | S12: 2.4402485 | T12: 11586195 | U12: 9.988451 | V12: 11.01319 | W12: 11.026 | X12: 16.26532
A13: CHL | B13: 0.5804277 | C13: Author estimate | F13: 10 | G13: BE | H13: 2022 | I13: 62602.93 | J13: 61037.61 | K13: 22392.885 | L13: 26.4 | M13: 5.57 | N13: 16.41 | O13: 6.27611 | P13: 83.57365 | Q13: 36.30749 | R13: 4.0246085 | S13: 9.5975117 | T13: 11680210 | U13: 10.016499 | V13: 11.04457 | W13: 11.01925 | X13: 16.27341
A14: CHN | B14: 0.5166999 | C14: Author estimate | F14: 11 | G14: BG | H14: 2018 | I14: 27690.89 | J14: 25500.49 | K14: 5267.799 | L14: 41.3 | M14: 5.211 | N14: 12.676 | O14: 4.05201 | P14: 83.13488 | Q14: 25.64857 | R14: 2.3301505 | S14: 2.8145447 | T14: 6710798 | U14: 8.569368 | V14: 10.22886 | W14: 10.14645 | X14: 15.71923
A15: COD | B15: 0.7621538 | C15: Author estimate | F15: 12 | G15: BG | H15: 2019 | I15: 29149.92 | J15: 28268.02 | K15: 5328.921 | L15: 40.3 | M15: 4.148 | N15: 8.777 | O15: 4.2143 | P15: 84.75031 | Q15: 24.75817 | R15: 3.7933196 | S15: 3.1037294 | T15: 6616726 | U15: 8.580904 | V15: 10.28021 | W15: 10.24949 | X15: 15.70511
A16: COL | B16: 0.738116 | C16: Author estimate | F16: 13 | G16: BG | H16: 2020 | I16: 28521.21 | J16: 27023.8 | K16: 5847.275 | L16: 40.5 | M16: 5.037 | N16: 14.143 | O16: 4.48299 | P16: 85.53311 | Q16: 26.05347 | R16: -3.1332354 | S16: 1.672441 | T16: 6550696 | U16: 8.673731 | V16: 10.2584 | W16: 10.20447 | X16: 15.69508
A17: CYP | B17: 0.5799067 | C17: Author estimate | F17: 14 | G17: BG | H17: 2021 | I17: 30958.98 | J17: 29722.71 | K17: 6122.527 | L17: 39 | M17: 5.166 | N17: 15.701 | O17: 4.70924 | P17: 85.30175 | Q17: 30.02296 | R17: 7.8281731 | S17: 3.2977443 | T17: 6507301 | U17: 8.71973 | V17: 10.34042 | W17: 10.29967 | X17: 15.68844
A18: CZE | B18: 0.4912439 | C18: Author estimate | F18: 15 | G18: BG | H18: 2022 | I18: 32433.66 | J18: 29240.05 | K18: 6228.255 | L18: 38.2 | M18: 4.148 | N18: 10.582 | O18: 4.50109 | P18: 84.12936 | Q18: 26.00696 | R18: 4.083864 | S18: 15.325259 | T18: 6465097 | U18: 8.736852 | V18: 10.38695 | W18: 10.28329 | X18: 15.68193
A19: DEU | B19: 0.3897916 | C19: Author estimate | F19: 16 | G19: CH | H19: 2018 | I19: 81371.89 | J19: 79804.74 | K19: 44565.024 | L19: 33.1 | M19: 4.713 | N19: 7.937 | O19: 4.93008 | P19: 64.35339 | Q19: 38.98468 | R19: 3.3274326 | S19: 0.93633546 | T19: 8514329 | U19: 10.704705 | V19: 11.30679 | W19: 11.28734 | X19: 15.95726
A20: DNK | B20: 0.2259895 | C20: Author estimate | F20: 17 | G20: CH | H20: 2019 | I20: 81694.63 | J20: 80262.12 | K20: 44875.258 | L20: 34 | M20: 4.394 | N20: 7.993 | O20: 5.01439 | P20: 66.30934 | Q20: 39.5556 | R20: 1.1153219 | S20: 0.36288618 | T20: 8575280 | U20: 10.711642 | V20: 11.31074 | W20: 11.29305 | X20: 15.96439
... A23: ESP | B23: 0.49607 | C23: Author estimate | F23: 20 | G23: CH | H23: 2022 | I23: 85762.28 | J23: 84338.64 | K23: 45211.254 | L23: 33.8 | M23: 4.122 | N23: 6.835 | O23: 4.86427 | P23: 74.15268 | Q23: 39.95473 | R23: 3.5343029 | S23: 2.835028 | T23: 8777088 | U23: 10.719101 | V23: 11.35933 | W23: 11.3426 | X23: 15.98766
A24: EST | B24: 0.3474851 | C24: Author estimate | F24: 21 | G24: CY | H24: 2018 | I24: 43510.03 | J24: 42117.02 | K24: 17705.057 | L24: 32.7 | M24: 8.504 | N24: 20.654 | O24: NA | P24: 86.58993 | Q24: 28.56136 | R24: 6.2716636 | S24: 1.4354912 | T24: 1270737 | U24: 9.781606 | V24: 10.68075 | W24: 10.64821 | X24: 14.05511
A25: ETH | B25: 0.6343259 | C25: Author estimate | F25: 22 | G25: CY | H25: 2019 | I25: 45454.18 | J25: 43251.84 | K25: 18256.674 | L25: 31.2 | M25: 7.155 | N25: 16.856 | O25: 5.16293 | P25: 93.92607 | Q25: 28.87141 | R25: 5.8755958 | S25: 0.250371 | T25: 1286671 | U25: 9.812286 | V25: 10.72446 | W25: 10.67479 | X25: 14.06757
A26: FIN | B26: 0.1449637 | C26: Author estimate | F26: 23 | G26: CY | H26: 2020 | I26: 43402.36 | J26: 40232.9 | K26: 16912.072 | L26: 31.7 | M26: 7.755 | N26: 18.491 | O26: 5.56462 | P26: 102.39076 | Q26: 29.79526 | R26: -3.2206302 | S26: -0.6384228 | T26: 1302247 | U26: 9.735783 | V26: 10.67827 | W26: 10.60244 | X26: 14.0796
A27: FRA | B27: 0.420066 | C27: Author estimate | F27: 24 | G27: CY | H27: 2021 | I27: 47632.57 | J27: 43413.63 | K27: 17445.852 | L27: 31.3 | M27: 7.513 | N27: 17.173 | O27: 5.08248 | P27: 106.36293 | Q27: 31.78488 | R27: 11.397559 | S27: 2.4460887 | T27: 1317309 | U27: 9.766857 | V27: 10.77127 | W27: 10.67853 | X27: 14.0911
A28: GBR | B28: 0.4714351 | C28: Author estimate | F28: 25 | G28: CY | H28: 2022 | I28: 50840.91 | J28: 45399.39 | K28: 18650.391 | L28: 31.5 | M28: 6.806 | N28: 18.707 | O28: 4.74211 | P28: 105.38498 | Q28: 33.16464 | R28: 8.7385469 | S28: 8.395483 | T28: 1331370 | U28: 9.833622 | V28: 10.83646 | W28: 10.72325 | X28: 14.10172
A29: GHA | B29: 0.5490857 | C29: Author estimate | F29: 26 | G29: CZ | H29: 2018 | I29: 46301.08 | J29: 43192.67 | K29: 9590.016 | L29: 25 | M29: 2.246 | N29: 6.714 | O29: 4.21541 | P29: 66.79022 | Q29: 21.00192 | R29: 2.8303059 | S29: 2.1494949 | T29: 10629928 | U29: 9.168478 | V29: 10.74292 | W29: 10.67343 | X29: 16.17918
A30: GRC | B30: 0.3331187 | C30: Author estimate | F30: 27 | G30: CZ | H30: 2019 | I30: 47763.62 | J30: 44401.36 | K30: 9845.791 | L30: 25.3 | M30: 2.015 | N30: 5.615 | O30: 4.46737 | P30: 66.88022 | Q30: 20.9109 | R30: 3.5657766 | S30: 2.847876 | T30: 10671870 | U30: 9.194799 | V30: 10.77402 | W30: 10.70103 | X30: 16.18312
A31: GTM | B31: 0.9343163 | C31: Author estimate | F31: 28 | G31: CZ | H31: 2020 | I31: 45119.94 | J31: 42810.54 | K31: 9190.253 | L31: 26.2 | M31: 2.55 | N31: 7.936 | O31: 4.62503 | P31: 67.18437 | Q31: 21.38517 | R31: -5.3048795 | S31: 3.1612953 | T31: 10697858 | U31: 9.125899 | V31: 10.71708 | W31: 10.66454 | X31: 16.18555
A32: HRV | B32: 0.3494334 | C32: Author estimate | F32: 29 | G32: CZ | H32: 2021 | I32: 47796.03 | J32: 46397.18 | K32: 9749.58 | L32: 26.2 | M32: 2.803 | N32: 8.134 | O32: 4.65164 | P32: 69.83693 | Q32: 22.2698 | R32: 4.0290183 | S32: 3.8398449 | T32: 10505772 | U32: 9.184979 | V32: 10.7747 | W32: 10.74499 | X32: 16.16744
A33: HUN | B33: 0.4748306 | C33: Author estimate | F33: 30 | G33: CZ | H33: 2022 | I33: 48390.66 | J33: 45261.41 | K33: 9648.554 | L33: 25.9 | M33: 2.224 | N33: 6.72 | O33: 4.30292 | P33: 70.81459 | Q33: 22.28766 | R33: 2.8471707 | S33: 15.100165 | T33: 10672118 | U33: 9.174563 | V33: 10.78706 | W33: 10.72021 | X33: 16.18315
A34: IDN | B34: 0.5050768 | C34: Author estimate | F34: 31 | G34: DE | H34: 2018 | I34: 62481.12 | J34: 64988.74 | K34: 23242.584 | L34: 31.9 | M34: 3.384 | N34: 6.22 | O34: 4.88402 | P34: 69.16343 | Q34: 25.14988 | R34: 1.135696 | S34: 1.7321688 | T34: 82905782 | U34: 10.053741 | V34: 11.04262 | W34: 11.08197 | X34: 18.23322
A35: IND | B35: 0.807923 | C35: Author estimate | F35: 32 | G35: DE | H35: 2019 | I35: 62949.89 | J35: 65457.17 | K35: 23577.17 | L35: 32.2 | M35: 3.163 | N35: 5.859 | O35: 5.02758 | P35: 72.70508 | Q35: 27.19798 | R35: 0.9777347 | S35: 1.4456598 | T35: 83092962 | U35: 10.068034 | V35: 11.05009 | W35: 11.08915 | X35: 18.23547
A36: IRL | B36: 0.441487 | C36: Author estimate | F36: 33 | G36: DE | H36: 2020 | I36: 60299.58 | J36: 62345.87 | K36: 21967.471 | L36: 32.5 | M36: 3.881 | N36: 7.862 | O36: 5.51601 | P36: 72.38942 | Q36: 28.34622 | R36: -4.1319144 | S36: 0.14487793 | T36: 83160871 | U36: 9.997318 | V36: 11.00708 | W36: 11.04045 | X36: 18.23629
... A43: KOR | B43: 0.2212296 | C43: Author estimate | F43: 40 | G43: DK | H43: 2022 | I43: 69089.47 | J43: 73107.46 | K43: 27643.241 | L43: 29.3 | M43: 4.434 | N43: 10.533 | O43: 6.35586 | P43: 84.58661 | Q43: 33.08082 | R43: 0.44383261 | S43: 7.696567 | T43: 5903037 | U43: 10.227137 | V43: 11.14316 | W43: 11.19969 | X43: 15.59098
A44: LBR | B44: 0.3377759 | C44: Author estimate | F44: 41 | G44: EE | H44: 2018 | I44: 40849.85 | J44: 40900.05 | K44: 10280.734 | L44: 30.3 | M44: 5.412 | N44: 12.076 | O44: 5.13963 | P44: 72.06596 | Q44: NA | R44: 3.6996976 | S44: 3.4363269 | T44: 1321977 | U44: 9.238027 | V44: 10.61766 | W44: 10.61889 | X44: 14.09464
A45: LKA | B45: 0.2651579 | C45: Author estimate | F45: 42 | G45: EE | H45: 2019 | I45: 42215.03 | J45: 42487.71 | K45: 10680.366 | L45: 30.8 | M45: 4.514 | N45: 11.623 | O45: 5.16415 | P45: 72.70603 | Q45: NA | R45: 3.7266494 | S45: 2.2772593 | T45: 1326898 | U45: 9.276162 | V45: 10.65053 | W45: 10.65697 | X45: 14.09835
A46: LTU | B46: 0.4023293 | C46: Author estimate | F46: 43 | G46: EE | H46: 2020 | I46: 40916.72 | J46: 40348.92 | K46: 10570.107 | L46: 30.7 | M46: 6.956 | N46: 18.417 | O46: 5.4418 | P46: 72.04436 | Q46: 30.84651 | R46: -2.8838075 | S46: -0.4445311 | T46: 1329522 | U46: 9.265785 | V46: 10.61929 | W46: 10.60532 | X46: 14.10033
A47: LUX | B47: 0.465603 | C47: Author estimate | F47: 44 | G47: EE | H47: 2021 | I47: 44247.42 | J47: 43219.48 | K47: 11316.462 | L47: 31.8 | M47: 6.178 | N47: 16.622 | O47: 5.21515 | P47: 73.15021 | Q47: 31.86923 | R47: 8.2548804 | S47: 4.6531667 | T47: 1330932 | U47: 9.334014 | V47: 10.69755 | W47: 10.67405 | X47: 14.10139
A48: LVA | B48: 0.4793727 | C48: Author estimate | F48: 45 | G48: EE | H48: 2022 | I48: 43124.62 | J48: 42807.81 | K48: 11491.341 | L48: 32.3 | M48: 5.571 | N48: 18.392 | O48: 5.20734 | P48: 71.42519 | Q48: 32.66017 | R48: -1.2261697 | S48: 19.398263 | T48: 1348840 | U48: 9.349349 | V48: 10.67185 | W48: 10.66448 | X48: 14.11476
...

Sheet regressions_check 
A1: regressions | E1: SUMMARY OUTPUT
A2: > audit_models[["Educ_spend_gdp_0.04"]]
E3: Regression Statistics
A4: Call | E4: Multiple R | F4: 0.1229749
A5: lm(formula = scale(y) ~ scale(x)) | E5: R Square | F5: 0.015122826
E6: Adjusted R Square | F6: -0.027697921
A7: Coefficients | E7: Standard Error | F7: 1.0137544
A8: (Intercept) scale(x) | E8: Observations | F8: 25
A9: 2.986e-17 1.230e-01
A10: 2.986e-17 | B10: 0.123 | E10: ANOVA
F11: df | G11: SS | H11: MS | I11: F | J11: Significance F
A12: eta_0.04 | B12: Educ_spend_gdp | E12: Regression | F12: 1 | G12: 0.36294783 | H12: 0.36294783 | I12: 0.35316587 | J12: 0.55812738
A13: 1.0545188 | B13: 0.48692417 | E13: Residual | F13: 23 | G13: 23.637052 | H13: 1.0276979
A14: 0.92239408 | B14: 1.5013885 | E14: Total | F14: 24 | G14: 24
A15: -0.88279063 | B15: -0.30179434
A16: 0.16260539 | B16: -0.056950272 | F16: Coefficients | G16: Standard Error | H16: t Stat | I16: P-value | J16: Lower 95% | K16: Upper 95% | L16: Lower 95.0% | M16: Upper 95.0%
A17: -0.22241164 | B17: -0.50310855 | E17: Intercept | F17: 3.1578981e-16 | G17: 0.20275087 | H17: 1.5575263e-15 | I17: 1 | J17: -0.41942214 | K17: 0.41942214 | L17: -0.41942214 | M17: 0.41942214
A18: 0.90213069 | B18: 0.44798602 | E18: Educ_spend_gdp | F18: 0.1229749 | G18: 0.20693174 | H18: 0.5942776 | I18: 0.55812738 | J18: -0.30509603 | K18: 0.55104583 | L18: -0.30509603 | M18: 0.55104583
A19: 0.10506778 | B19: 1.5824038
A20: -0.72740916 | B20: 0.41566116
A21: 1.0886011 | B21: -0.21600444
A22: -1.0643181 | B22: 1.6026399
A23: 0.96383682 | B23: 0.53452766
A24: 1.3139624 | B24: -1.4452635
A25: -1.1783692 | B25: -0.71772044
A26: 0.92344521 | B26: -1.0127889
A27: 0.43970207 | B27: -0.74199964
A28: -2.433054 | B28: -0.55397297
A29: 0.95591484 | B29: -1.0703682
A30: -0.92043968 | B30: -0.48609279
... A37: -0.13805555 | B37: -0.14352239
A39: eta_0.04_Z | B39: eta_0.075_Z | C39: eta_0.14_Z | D39: Educ_spend_gdp | E39: GDP_growth | F39: Gini | I39: udit_models[["GDP_growth_0.075"]]
A40: 1.0545188 | B40: 0.86075011 | C40: 0.86075011 | D40: 0.48692417 | E40: 0.75923605 | F40: -0.14292764
A41: 0.92239408 | B41: 0.68147438 | C41: 0.68147438 | D41: 1.5013885 | E41: 0.25127953 | F41: -1.3395311 | I41: Call
A42: -0.88279063 | B42: -0.62525328 | C42: -0.62525328 | D42: -0.30179434 | E42: 0.27432014 | F42: 1.7982291 | I42: lm(formula = scale(y) ~ scale(x))
A43: 0.16260539 | B43: 0.47754695 | C43: 0.47754695 | D43: -0.056950272 | E43: 2.0842232 | F43: 0.016619493
A44: -0.22241164 | B44: -0.012663464 | C44: -0.012663464 | D44: -0.50310855 | E44: -0.20654936 | F44: -1.472487 | I44: Coefficients
A45: 0.90213069 | B45: 0.69007528 | C45: 0.69007528 | D45: 0.44798602 | E45: -0.61012599 | F45: 0.60162563 | I45: (Intercept) scale(x)
A46: 0.10506778 | B46: -0.47071524 | C46: -0.47071524 | D46: 1.5824038 | E46: -1.1410511 | F46: -0.56838664 | I46: -2.473e-16 2.051e-01 | J46: 0.2051
A47: -0.72740916 | B47: -0.17246482 | C47: -0.17246482 | D47: 0.41566116 | E47: -1.7904062 | F47: 0.229349 | I47: -2.473e-16
...

Sheet elasticities
A1: > rho_alt[3] | E1: Check | F1: > betas[betas$Country=="Austria",]$Estimate_controls/(log(22200)-log(loan_pv(wages[wages$Country=="Austria",]$Wage_EURO*0.848248*(1+0.02), dat[dat$Country=="Austria",]$lower,dat[dat$Country=="Austria",]$upper,0.04)))
A2: [1] 0.04 | F2: [1] -0.6311931
A3: > rho_alt[10] | F3: > betas[betas$Country=="Austria",]$Estimate_controls/(log(22200)-log(loan_pv(wages[wages$Country=="Austria",]$Wage_EURO*0.848248*(1+0.02), dat[dat$Country=="Austria",]$lower,dat[dat$Country=="Austria",]$upper,0.075)))
A4: [1] 0.075 | F4: [1] -0.5602358
A5: > rho_alt[23] | F5: betas[betas$Country=="Austria",]$Estimate_controls/(log(22200)-log(loan_pv(wages[wages$Country=="Austria",]$Wage_EURO*0.848248*(1+0.02), dat[dat$Country=="Austria",]$lower,dat[dat$Country=="Austria",]$upper,0.14)))
A6: [1] 0.14 | F6: [1] -0.4696517
F8: > betas[betas$Country=="Slovakia",]$Estimate_controls/(log(22200)-log(loan_pv(wages[wages$Country=="Slovakia",]$Wage_EURO*0.848248*(1+0.02), dat[dat$Country=="Slovakia",]$lower,dat[dat$Country=="Slovakia",]$upper,0.075)))
F9: [1] -0.8893191
A10: country | B10: =A2 -> [1] 0.04 | C10: =A4 -> [1] 0.075 | D10: =A6 -> [1] 0.14 | F10: > betas[betas$Country=="Slovakia",]$Estimate_controls/(log(22200)-log(loan_pv(wages[wages$Country=="Slovakia",]$Wage_EURO*0.848248*(1+0.02), dat[dat$Country=="Slovakia",]$lower,dat[dat$Country=="Slovakia",]$upper,0.14)))
A11: Austria | B11: -0.6311931 | C11: -0.5602358 | D11: -0.4696517 | F11: [1] -0.5713938
A12: Belgium | B12: -0.7181885 | C12: -0.6400927 | D12: -0.5392725
A13: Bulgaria | B13: -1.906783 | C13: -1.2221638 | D13: -0.8081628 | F13: > betas[betas$Country=="Slovakia",]$Estimate_controls/(log(22200)-log(loan_pv(wages[wages$Country=="Slovakia",]$Wage_EURO*0.848248*(1+0.02), dat[dat$Country=="Slovakia",]$lower,dat[dat$Country=="Slovakia",]$upper,0.04)))
A14: Cyprus | B14: -1.218459 | C14: -0.7309305 | D14: -0.4555112 | F14: [1] -1.416424
A15: Czechia | B15: -1.4719672 | C15: -0.9492907 | D15: -0.6191261
A16: Germany | B16: -0.7315306 | C16: -0.6362615 | D16: -0.5208939
A17: Denmark | B17: -1.2563437 | C17: -1.1533261 | D17: -1.0095158
A18: Estonia | B18: -1.8044746 | C18: -1.0204729 | D18: -0.615241
A19: Spain | B19: -0.6087522 | C19: -0.4546566 | D19: -0.3238962
A20: Finland | B20: -2.0263068 | C20: -1.7187965 | D20: -1.3692607
A21: France | B21: -0.6909012 | C21: -0.584589 | D21: -0.4644025
A22: Greece | B22: -0.4603667 | C22: -0.3204047 | D22: -0.2146625
A23: Croatia | B23: -2.1014019 | C23: -1.3195079 | D23: -0.8492813
A24: Hungary | B24: -0.7174964 | C24: -0.48991 | D24: -0.3252514
A25: Italy | B25: -1.0360092 | C25: -0.7709308 | D25: -0.5476996
A26: Lithuania | B26: -2.9275287 | C26: -2.2043226 | D26: -1.579713
... A35: Slovakia | B35: -1.4164243 | C35: -0.8893191 | D35: -0.5713938
