Workbook

Sheet Bulgaria
A1: SDR=3%
A2: Label | B2: Value or formula
A3: 2024 wage in euros | B3: 15387
A4: EUR to GBP rate | B4: 0.848248
A5: Annual wage growth | B5: 0.02
A6: Years to first repayment | B6: 1
A7: 2024 wage in GBP | B7: =B3*B4 -> 13051.992
A8: First repayment-year earnings | B8: =B7*(1+B5)^B6 -> 13313.032
A9: Opening loan balance | B9: 9250
A10: Post-Brexit price | B10: 22200
A11: Repayment rate | B11: 0.09
A12: Lower threshold | B12: 11390
A13: Upper threshold | B13: 20500
A14: First RPI rate | B14: 0.043
A15: Months at first RPI rate | B15: 5
A16: Second RPI rate | B16: 0.032 | D16: monthly increase in income | E16: =-(B25-AE25)/12 -> 860.73709
A17: Months at second RPI rate | B17: 7
A18: Fixed weighted RPI | B18: =(B14*B15+B16*B17)/(B15+B17) -> 0.036583333
A19: Maximum interest spread | B19: 0.03
A20: Subjective discount rate | B20: 0.03
A21: Controlled TWFE coefficient | B21: -1.780743
A24: Repayment year | B24: 1 | C24: 2 | D24: 3 | E24: 4 | F24: 5 | G24: 6 | H24: 7 | I24: 8 | J24: 9 | K24: 10 | L24: 11 | M24: 12 | N24: 13 | O24: 14 | P24: 15 | Q24: 16 | R24: 17 | S24: 18 | T24: 19 | U24: 20 | V24: 21 | W24: 22 | X24: 23 | Y24: 24 | Z24: 25 | AA24: 26 | AB24: 27 | AC24: 28 | AD24: 29 | AE24: 30
A25: Earnings | B25: =$B$8 -> 13313.032 | C25: =$B$8*(1+$B$5)^(C$24-1) -> 13579.292 | D25: =$B$8*(1+$B$5)^(D$24-1) -> 13850.878 | E25: =$B$8*(1+$B$5)^(E$24-1) -> 14127.896 | F25: =$B$8*(1+$B$5)^(F$24-1) -> 14410.454 | G25: =$B$8*(1+$B$5)^(G$24-1) -> 14698.663 | H25: =$B$8*(1+$B$5)^(H$24-1) -> 14992.636 | I25: =$B$8*(1+$B$5)^(I$24-1) -> 15292.489 | J25: =$B$8*(1+$B$5)^(J$24-1) -> 15598.339 | ... AE25: =$B$8*(1+$B$5)^(AE$24-1) -> 23641.877
A26: Income loading | B26: =IF(B25<=$B$12,0,IF(B25<$B$13,(B25-$B$12)/($B$13-$B$12),1)) -> 0.21109021 | C26: =IF(C25<=$B$12,0,IF(C25<$B$13,(C25-$B$12)/($B$13-$B$12),1)) -> 0.2403175 | D26: =IF(D25<=$B$12,0,IF(D25<$B$13,(D25-$B$12)/($B$13-$B$12),1)) -> 0.27012934 | E26: =IF(E25<=$B$12,0,IF(E25<$B$13,(E25-$B$12)/($B$13-$B$12),1)) -> 0.30053742 | F26: =IF(F25<=$B$12,0,IF(F25<$B$13,(F25-$B$12)/($B$13-$B$12),1)) -> 0.33155365 | G26: =IF(G25<=$B$12,0,IF(G25<$B$13,(G25-$B$12)/($B$13-$B$12),1)) -> 0.36319022 | H26: =IF(H25<=$B$12,0,IF(H25<$B$13,(H25-$B$12)/($B$13-$B$12),1)) -> 0.39545951 | I26: =IF(I25<=$B$12,0,IF(I25<$B$13,(I25-$B$12)/($B$13-$B$12),1)) -> 0.42837419 | ... AE26: =IF(AE25<=$B$12,0,IF(AE25<$B$13,(AE25-$B$12)/($B$13-$B$12),1)) -> 1
A27: Interest rate | B27: =$B$18+$B$19*B26 -> 0.04291604 | C27: =$B$18+$B$19*C26 -> 0.043792858 | D27: =$B$18+$B$19*D26 -> 0.044687214 | E27: =$B$18+$B$19*E26 -> 0.045599456 | F27: =$B$18+$B$19*F26 -> 0.046529943 | G27: =$B$18+$B$19*G26 -> 0.04747904 | H27: =$B$18+$B$19*H26 -> 0.048447119 | I27: =$B$18+$B$19*I26 -> 0.049434559 | ... AE27: =$B$18+$B$19*AE26 -> 0.066583333
A28: Opening balance | B28: =$B$9 -> 9250 | C28: =B32 -> 9473.9005 | D28: =C32 -> 9691.7534 | E28: =D32 -> 9903.3718 | F28: =E32 -> 10108.55 | G28: =F32 -> 10307.059 | H28: =G32 -> 10498.649 | I28: =H32 -> 10683.041 | J28: =I32 -> 10859.928 | ... AE28: =AD32 -> 11282.922
A29: Balance after interest | B29: =B28*(1+B27) -> 9646.9734 | C29: =C28*(1+C27) -> 9888.7897 | D29: =D28*(1+D27) -> 10124.851 | E29: =E28*(1+E27) -> 10354.96 | F29: =F28*(1+F27) -> 10578.9 | G29: =G28*(1+G27) -> 10796.428 | H29: =H28*(1+H27) -> 11007.278 | I29: =I28*(1+I27) -> 11211.152 | ... AE29: =AE28*(1+AE27) -> 12034.176
A30: Scheduled repayment | B30: =$B$11*MAX(0,B25-$B$12) -> 173.07286 | C30: =$B$11*MAX(0,C25-$B$12) -> 197.03632 | D30: =$B$11*MAX(0,D25-$B$12) -> 221.47905 | E30: =$B$11*MAX(0,E25-$B$12) -> 246.41063 | F30: =$B$11*MAX(0,F25-$B$12) -> 271.84084 | G30: =$B$11*MAX(0,G25-$B$12) -> 297.77966 | H30: =$B$11*MAX(0,H25-$B$12) -> 324.23725 | I30: =$B$11*MAX(0,I25-$B$12) -> 351.224 | ... AE30: =$B$11*MAX(0,AE25-$B$12) -> 1102.6689
A31: Actual repayment | B31: =MIN(B30,B29) -> 173.07286 | C31: =MIN(C30,C29) -> 197.03632 | D31: =MIN(D30,D29) -> 221.47905 | E31: =MIN(E30,E29) -> 246.41063 | F31: =MIN(F30,F29) -> 271.84084 | G31: =MIN(G30,G29) -> 297.77966 | H31: =MIN(H30,H29) -> 324.23725 | I31: =MIN(I30,I29) -> 351.224 | ... AE31: =MIN(AE30,AE29) -> 1102.6689
A32: Closing balance | B32: =B29-B31 -> 9473.9005 | C32: =C29-C31 -> 9691.7534 | D32: =D29-D31 -> 9903.3718 | E32: =E29-E31 -> 10108.55 | F32: =F29-F31 -> 10307.059 | G32: =G29-G31 -> 10498.649 | H32: =H29-H31 -> 10683.041 | I32: =I29-I31 -> 10859.928 | ... AE32: =AE29-AE31 -> 10931.507
A33: Discount factor | B33: =1/(1+$B$20) -> 0.97087379 | C33: =1/(1+$B$20)^C$24 -> 0.94259591 | D33: =1/(1+$B$20)^D$24 -> 0.91514166 | E33: =1/(1+$B$20)^E$24 -> 0.88848705 | F33: =1/(1+$B$20)^F$24 -> 0.86260878 | G33: =1/(1+$B$20)^G$24 -> 0.83748426 | H33: =1/(1+$B$20)^H$24 -> 0.81309151 | I33: =1/(1+$B$20)^I$24 -> 0.78940923 | J33: =1/(1+$B$20)^J$24 -> 0.76641673 | ... AE33: =1/(1+$B$20)^AE$24 -> 0.41198676
A34: PV repayment | B34: =B31*B33 -> 168.03191 | C34: =C31*C33 -> 185.72563 | D34: =D31*D33 -> 202.6847 | E34: =E31*E33 -> 218.93265 | F34: =F31*F33 -> 234.4923 | G34: =G31*G33 -> 249.38578 | H34: =H31*H33 -> 263.63456 | I34: =I31*I33 -> 277.25947 | ... AE34: =AE31*AE33 -> 454.28499
A37: Loan PV at 3% | B37: =SUM(B34:AE34) -> 10310.387
A38: Log experienced price change | B38: =LN($B$10)-LN(B37) -> 0.7669405
A39: Implied elasticity | B39: =$B$21/B38 -> -2.3218789
A40: Balance written off after year 30 | B40: =AE32 -> 10931.507
A42: SDR=14.9%
A43: Label | B43: Value or formula
A44: 2024 wage in euros | B44: 15387
A45: EUR to GBP rate | B45: 0.848248
...

Sheet Luxemourg
A1: SDR=3%
A2: Label | B2: Value or formula
A3: 2024 wage in euros | B3: =data!J11 -> 82969
A4: EUR to GBP rate | B4: 0.848248
A5: Annual wage growth | B5: 0.02
A6: Years to first repayment | B6: 1
A7: 2024 wage in GBP | B7: =B3*B4 -> 70378.288
A8: First repayment-year earnings | B8: =B7*(1+B5)^B6 -> 71785.854
A9: Opening loan balance | B9: 9250
A10: Post-Brexit price | B10: 22200
A11: Repayment rate | B11: 0.09
A12: Lower threshold | B12: =data!D18 -> 28470
A13: Upper threshold | B13: =data!E18 -> 51245
A14: First RPI rate | B14: 0.043
A15: Months at first RPI rate | B15: 5
A16: Second RPI rate | B16: 0.032
A17: Months at second RPI rate | B17: 7
A18: Fixed weighted RPI | B18: =(B14*B15+B16*B17)/(B15+B17) -> 0.036583333
A19: Maximum interest spread | B19: 0.03
A20: Subjective discount rate | B20: 0.03
A21: Controlled TWFE coefficient | B21: -0.5771991
A24: Repayment year | B24: 1 | C24: 2 | D24: 3 | E24: 4 | F24: 5 | G24: 6 | H24: 7 | I24: 8 | J24: 9 | K24: 10 | L24: 11 | M24: 12 | N24: 13 | O24: 14 | P24: 15 | Q24: 16 | R24: 17 | S24: 18 | T24: 19 | U24: 20 | V24: 21 | W24: 22 | X24: 23 | Y24: 24 | Z24: 25 | AA24: 26 | AB24: 27 | AC24: 28 | AD24: 29 | AE24: 30
A25: Earnings | B25: =$B$8 -> 71785.854 | C25: =$B$8*(1+$B$5)^(C$24-1) -> 73221.571 | D25: =$B$8*(1+$B$5)^(D$24-1) -> 74686.003 | E25: =$B$8*(1+$B$5)^(E$24-1) -> 76179.723 | F25: =$B$8*(1+$B$5)^(F$24-1) -> 77703.317 | G25: =$B$8*(1+$B$5)^(G$24-1) -> 79257.383 | H25: =$B$8*(1+$B$5)^(H$24-1) -> 80842.531 | I25: =$B$8*(1+$B$5)^(I$24-1) -> 82459.382 | J25: =$B$8*(1+$B$5)^(J$24-1) -> 84108.569 | ... AE25: =$B$8*(1+$B$5)^(AE$24-1) -> 127480.53
A26: Income loading | B26: =IF(B25<=$B$12,0,IF(B25<$B$13,(B25-$B$12)/($B$13-$B$12),1)) -> 1 | C26: =IF(C25<=$B$12,0,IF(C25<$B$13,(C25-$B$12)/($B$13-$B$12),1)) -> 1 | D26: =IF(D25<=$B$12,0,IF(D25<$B$13,(D25-$B$12)/($B$13-$B$12),1)) -> 1 | E26: =IF(E25<=$B$12,0,IF(E25<$B$13,(E25-$B$12)/($B$13-$B$12),1)) -> 1 | F26: =IF(F25<=$B$12,0,IF(F25<$B$13,(F25-$B$12)/($B$13-$B$12),1)) -> 1 | G26: =IF(G25<=$B$12,0,IF(G25<$B$13,(G25-$B$12)/($B$13-$B$12),1)) -> 1 | H26: =IF(H25<=$B$12,0,IF(H25<$B$13,(H25-$B$12)/($B$13-$B$12),1)) -> 1 | I26: =IF(I25<=$B$12,0,IF(I25<$B$13,(I25-$B$12)/($B$13-$B$12),1)) -> 1 | ... AE26: =IF(AE25<=$B$12,0,IF(AE25<$B$13,(AE25-$B$12)/($B$13-$B$12),1)) -> 1
A27: Interest rate | B27: =$B$18+$B$19*B26 -> 0.066583333 | C27: =$B$18+$B$19*C26 -> 0.066583333 | D27: =$B$18+$B$19*D26 -> 0.066583333 | E27: =$B$18+$B$19*E26 -> 0.066583333 | F27: =$B$18+$B$19*F26 -> 0.066583333 | G27: =$B$18+$B$19*G26 -> 0.066583333 | H27: =$B$18+$B$19*H26 -> 0.066583333 | I27: =$B$18+$B$19*I26 -> 0.066583333 | ... AE27: =$B$18+$B$19*AE26 -> 0.066583333
A28: Opening balance | B28: =$B$9 -> 9250 | C28: =B32 -> 5967.469 | D28: =C32 -> 2337.1615 | E28: =D32 -> 0 | F28: =E32 -> 0 | G28: =F32 -> 0 | H28: =G32 -> 0 | I28: =H32 -> 0 | J28: =I32 -> 0 | ... AE28: =AD32 -> 0
A29: Balance after interest | B29: =B28*(1+B27) -> 9865.8958 | C29: =C28*(1+C27) -> 6364.8029 | D29: =D28*(1+D27) -> 2492.7775 | E29: =E28*(1+E27) -> 0 | F29: =F28*(1+F27) -> 0 | G29: =G28*(1+G27) -> 0 | H29: =H28*(1+H27) -> 0 | I29: =I28*(1+I27) -> 0 | ... AE29: =AE28*(1+AE27) -> 0
A30: Scheduled repayment | B30: =$B$11*MAX(0,B25-$B$12) -> 3898.4269 | C30: =$B$11*MAX(0,C25-$B$12) -> 4027.6414 | D30: =$B$11*MAX(0,D25-$B$12) -> 4159.4402 | E30: =$B$11*MAX(0,E25-$B$12) -> 4293.875 | F30: =$B$11*MAX(0,F25-$B$12) -> 4430.9985 | G30: =$B$11*MAX(0,G25-$B$12) -> 4570.8645 | H30: =$B$11*MAX(0,H25-$B$12) -> 4713.5278 | I30: =$B$11*MAX(0,I25-$B$12) -> 4859.0444 | ... AE30: =$B$11*MAX(0,AE25-$B$12) -> 8910.9475
A31: Actual repayment | B31: =MIN(B30,B29) -> 3898.4269 | C31: =MIN(C30,C29) -> 4027.6414 | D31: =MIN(D30,D29) -> 2492.7775 | E31: =MIN(E30,E29) -> 0 | F31: =MIN(F30,F29) -> 0 | G31: =MIN(G30,G29) -> 0 | H31: =MIN(H30,H29) -> 0 | I31: =MIN(I30,I29) -> 0 | ... AE31: =MIN(AE30,AE29) -> 0
A32: Closing balance | B32: =B29-B31 -> 5967.469 | C32: =C29-C31 -> 2337.1615 | D32: =D29-D31 -> 0 | E32: =E29-E31 -> 0 | F32: =F29-F31 -> 0 | G32: =G29-G31 -> 0 | H32: =H29-H31 -> 0 | I32: =I29-I31 -> 0 | ... AE32: =AE29-AE31 -> 0
A33: Discount factor | B33: =1/(1+$B$20) -> 0.97087379 | C33: =1/(1+$B$20)^C$24 -> 0.94259591 | D33: =1/(1+$B$20)^D$24 -> 0.91514166 | E33: =1/(1+$B$20)^E$24 -> 0.88848705 | F33: =1/(1+$B$20)^F$24 -> 0.86260878 | G33: =1/(1+$B$20)^G$24 -> 0.83748426 | H33: =1/(1+$B$20)^H$24 -> 0.81309151 | I33: =1/(1+$B$20)^I$24 -> 0.78940923 | J33: =1/(1+$B$20)^J$24 -> 0.76641673 | ... AE33: =1/(1+$B$20)^AE$24 -> 0.41198676
A34: PV repayment | B34: =B31*B33 -> 3784.8805 | C34: =C31*C33 -> 3796.4383 | D34: =D31*D33 -> 2281.2446 | E34: =E31*E33 -> 0 | F34: =F31*F33 -> 0 | G34: =G31*G33 -> 0 | H34: =H31*H33 -> 0 | I34: =I31*I33 -> 0 | ... AE34: =AE31*AE33 -> 0
A37: Loan PV at 3% | B37: =SUM(B34:AE34) -> 9862.5633
A38: Log experienced price change | B38: =LN($B$10)-LN(B37) -> 0.81134618
A39: Implied elasticity | B39: =$B$21/B38 -> -0.71140915
A40: Balance written off after year 30 | B40: =AE32 -> 0
A42: SDR=14.9%
A43: Label | B43: Value or formula
A44: 2024 wage in euros | B44: 82969
A45: EUR to GBP rate | B45: 0.848248
...

Sheet Portugal
A1: SDR=3%
A2: Label | B2: Value or formula
A3: 2024 wage in euros | B3: =data!J8 -> 24818
A4: EUR to GBP rate | B4: 0.848248
A5: Annual wage growth | B5: 0.02
A6: Years to first repayment | B6: 1
A7: 2024 wage in GBP | B7: =B3*B4 -> 21051.819
A8: First repayment-year earnings | B8: =B7*(1+B5)^B6 -> 21472.855
A9: Opening loan balance | B9: 9250
A10: Post-Brexit price | B10: 22200
A11: Repayment rate | B11: 0.09
A12: Lower threshold | B12: =data!D22 -> 17085
A13: Upper threshold | B13: =data!E22 -> 30750
A14: First RPI rate | B14: 0.043
A15: Months at first RPI rate | B15: 5
A16: Second RPI rate | B16: 0.032
A17: Months at second RPI rate | B17: 7
A18: Fixed weighted RPI | B18: =(B14*B15+B16*B17)/(B15+B17) -> 0.036583333
A19: Maximum interest spread | B19: 0.03
A20: Subjective discount rate | B20: 0.03
A21: Controlled TWFE coefficient | B21: -0.8357402
A24: Repayment year | B24: 1 | C24: 2 | D24: 3 | E24: 4 | F24: 5 | G24: 6 | H24: 7 | I24: 8 | J24: 9 | K24: 10 | L24: 11 | M24: 12 | N24: 13 | O24: 14 | P24: 15 | Q24: 16 | R24: 17 | S24: 18 | T24: 19 | U24: 20 | V24: 21 | W24: 22 | X24: 23 | Y24: 24 | Z24: 25 | AA24: 26 | AB24: 27 | AC24: 28 | AD24: 29 | AE24: 30
A25: Earnings | B25: =$B$8 -> 21472.855 | C25: =$B$8*(1+$B$5)^(C$24-1) -> 21902.312 | D25: =$B$8*(1+$B$5)^(D$24-1) -> 22340.359 | E25: =$B$8*(1+$B$5)^(E$24-1) -> 22787.166 | F25: =$B$8*(1+$B$5)^(F$24-1) -> 23242.909 | G25: =$B$8*(1+$B$5)^(G$24-1) -> 23707.767 | H25: =$B$8*(1+$B$5)^(H$24-1) -> 24181.923 | I25: =$B$8*(1+$B$5)^(I$24-1) -> 24665.561 | J25: =$B$8*(1+$B$5)^(J$24-1) -> 25158.872 | ... AE25: =$B$8*(1+$B$5)^(AE$24-1) -> 38132.456
A26: Income loading | B26: =IF(B25<=$B$12,0,IF(B25<$B$13,(B25-$B$12)/($B$13-$B$12),1)) -> 0.32110174 | C26: =IF(C25<=$B$12,0,IF(C25<$B$13,(C25-$B$12)/($B$13-$B$12),1)) -> 0.35252926 | D26: =IF(D25<=$B$12,0,IF(D25<$B$13,(D25-$B$12)/($B$13-$B$12),1)) -> 0.38458533 | E26: =IF(E25<=$B$12,0,IF(E25<$B$13,(E25-$B$12)/($B$13-$B$12),1)) -> 0.41728253 | F26: =IF(F25<=$B$12,0,IF(F25<$B$13,(F25-$B$12)/($B$13-$B$12),1)) -> 0.45063367 | G26: =IF(G25<=$B$12,0,IF(G25<$B$13,(G25-$B$12)/($B$13-$B$12),1)) -> 0.48465183 | H26: =IF(H25<=$B$12,0,IF(H25<$B$13,(H25-$B$12)/($B$13-$B$12),1)) -> 0.51935036 | I26: =IF(I25<=$B$12,0,IF(I25<$B$13,(I25-$B$12)/($B$13-$B$12),1)) -> 0.55474285 | ... AE26: =IF(AE25<=$B$12,0,IF(AE25<$B$13,(AE25-$B$12)/($B$13-$B$12),1)) -> 1
A27: Interest rate | B27: =$B$18+$B$19*B26 -> 0.046216385 | C27: =$B$18+$B$19*C26 -> 0.047159211 | D27: =$B$18+$B$19*D26 -> 0.048120893 | E27: =$B$18+$B$19*E26 -> 0.049101809 | F27: =$B$18+$B$19*F26 -> 0.050102343 | G27: =$B$18+$B$19*G26 -> 0.051122888 | H27: =$B$18+$B$19*H26 -> 0.052163844 | I27: =$B$18+$B$19*I26 -> 0.053225619 | ... AE27: =$B$18+$B$19*AE26 -> 0.066583333
A28: Opening balance | B28: =$B$9 -> 9250 | C28: =B32 -> 9282.5946 | D28: =C32 -> 9286.7963 | E28: =D32 -> 9260.703 | F28: =E32 -> 9202.2253 | G28: =F32 -> 9109.0666 | H28: =G32 -> 8978.6993 | I28: =H32 -> 8808.3397 | J28: =I32 -> 8594.9186 | ... AE28: =AD32 -> 0
A29: Balance after interest | B29: =B28*(1+B27) -> 9677.5016 | C29: =C28*(1+C27) -> 9720.3544 | D29: =D28*(1+D27) -> 9733.6853 | E29: =E28*(1+E27) -> 9715.4203 | F29: =F28*(1+F27) -> 9663.2784 | G29: =G28*(1+G27) -> 9574.7484 | H29: =H28*(1+H27) -> 9447.0628 | I29: =I28*(1+I27) -> 9277.1691 | ... AE29: =AE28*(1+AE27) -> 0
A30: Scheduled repayment | B30: =$B$11*MAX(0,B25-$B$12) -> 394.90697 | C30: =$B$11*MAX(0,C25-$B$12) -> 433.55811 | D30: =$B$11*MAX(0,D25-$B$12) -> 472.98227 | E30: =$B$11*MAX(0,E25-$B$12) -> 513.19492 | F30: =$B$11*MAX(0,F25-$B$12) -> 554.21182 | G30: =$B$11*MAX(0,G25-$B$12) -> 596.04905 | H30: =$B$11*MAX(0,H25-$B$12) -> 638.72303 | I30: =$B$11*MAX(0,I25-$B$12) -> 682.2505 | ... AE30: =$B$11*MAX(0,AE25-$B$12) -> 1894.271
A31: Actual repayment | B31: =MIN(B30,B29) -> 394.90697 | C31: =MIN(C30,C29) -> 433.55811 | D31: =MIN(D30,D29) -> 472.98227 | E31: =MIN(E30,E29) -> 513.19492 | F31: =MIN(F30,F29) -> 554.21182 | G31: =MIN(G30,G29) -> 596.04905 | H31: =MIN(H30,H29) -> 638.72303 | I31: =MIN(I30,I29) -> 682.2505 | ... AE31: =MIN(AE30,AE29) -> 0
A32: Closing balance | B32: =B29-B31 -> 9282.5946 | C32: =C29-C31 -> 9286.7963 | D32: =D29-D31 -> 9260.703 | E32: =E29-E31 -> 9202.2253 | F32: =F29-F31 -> 9109.0666 | G32: =G29-G31 -> 8978.6993 | H32: =H29-H31 -> 8808.3397 | I32: =I29-I31 -> 8594.9186 | ... AE32: =AE29-AE31 -> 0
A33: Discount factor | B33: =1/(1+$B$20) -> 0.97087379 | C33: =1/(1+$B$20)^C$24 -> 0.94259591 | D33: =1/(1+$B$20)^D$24 -> 0.91514166 | E33: =1/(1+$B$20)^E$24 -> 0.88848705 | F33: =1/(1+$B$20)^F$24 -> 0.86260878 | G33: =1/(1+$B$20)^G$24 -> 0.83748426 | H33: =1/(1+$B$20)^H$24 -> 0.81309151 | I33: =1/(1+$B$20)^I$24 -> 0.78940923 | J33: =1/(1+$B$20)^J$24 -> 0.76641673 | ... AE33: =1/(1+$B$20)^AE$24 -> 0.41198676
A34: PV repayment | B34: =B31*B33 -> 383.40483 | C34: =C31*C33 -> 408.6701 | D34: =D31*D33 -> 432.84578 | E34: =E31*E33 -> 455.96704 | F34: =F31*F33 -> 478.06798 | G34: =G31*G33 -> 499.1817 | H34: =H31*H33 -> 519.34028 | I34: =I31*I33 -> 538.57484 | ... AE34: =AE31*AE33 -> 0
A37: Loan PV at 3% | B37: =SUM(B34:AE34) -> 11944.227
A38: Log experienced price change | B38: =LN($B$10)-LN(B37) -> 0.6198442
A39: Implied elasticity | B39: =$B$21/B38 -> -1.3483069
A40: Balance written off after year 30 | B40: =AE32 -> 0
A42: SDR=14.9%
A43: Label | B43: Value or formula
A44: 2024 wage in euros | B44: 24818
A45: EUR to GBP rate | B45: 0.848248
...

Sheet data
A1: num | B1: Country | C1: iso | D1: tau_min | E1: tau_max | I1: Country | J1: Wage_EURO
A2: 1 | B2: Austria | C2: AT | D2: 28470 | E2: 51245 | I2: All | J2: All
A3: 2 | B3: Belgium | C3: BE | D3: 28470 | E3: 51245 | H3: 28 | I3: Sweden | J3: 46525
A4: 3 | B4: Bulgaria | C4: BG | D4: 11390 | E4: 20500 | H4: 11 | I4: Spain | J4: 33700
A5: 4 | B5: Croatia | C5: HR | D5: 17085 | E5: 30750 | H5: 25 | I5: Slovenia | J5: 35133
A6: 5 | B6: Cyprus | C6: CY | D6: 22780 | E6: 41000 | H6: 26 | I6: Slovakia | J6: 20287
A7: 6 | B7: Czechia | C7: CZ | D7: 17085 | E7: 30750 | H7: 24 | I7: Romania | J7: 21108
A8: 7 | B8: Denmark | C8: DK | D8: 28470 | E8: 51245 | H8: 23 | I8: Portugal | J8: 24818
A9: 8 | B9: Estonia | C9: EE | D9: 22780 | E9: 41000 | H9: 22 | I9: Poland | J9: 21246
A10: 9 | B10: Finland | C10: FI | D10: 28470 | E10: 51245 | H10: 20 | I10: Malta | J10: 33499
A11: 10 | B11: France | C11: FR | D11: 22780 | E11: 41000 | H11: 18 | I11: Luxembourg | J11: 82969
A12: 11 | B12: Germany | C12: DE | D12: 28470 | E12: 51245 | H12: 17 | I12: Lithuania | J12: 29104
A13: 12 | B13: Greece | C13: GR | D13: 17085 | E13: 30750 | H13: 16 | I13: Latvia | J13: 22262
A14: 13 | B14: Hungary | C14: HU | D14: 17085 | E14: 30750 | H14: 14 | I14: Italy | J14: 33523
... A27: 26 | B27: Sweden | C27: SE | D27: 28470 | E27: 51245 | H27: 13 | I27: Croatia | J27: 23446
H28: 4 | I28: Bulgaria | J28: 15387
H29: 3 | I29: Belgium | J29: 59632
H30: 21 | I30: Austria | J30: 58600
