Workbook

Sheet main_df
A1: Year | B1: Domicile_named_country | D1: Applicants | E1: Accepted_applicants | F1: Acceptance_rate | G1: Applicants_with_no_applications | H1: log_app | I1: EU | J1: Treated | K1: Post | L1: event_time | M1: EU_group | N1: treated_factor | O1: regression_weight | P1: did | Q1: iso3c | R1: GDP_ISO3c | S1: GDP_CN | T1: GDP_SOURCE | U1: GDPpc | V1: Pop_SOURCE | W1: Pop15_64 | X1: YU_SOURCE | Y1: YouthUnempl | Z1: EduSpendGDP | AA1: lN_GDP_SR | AB1: C_lN_GDP_SR | AC1: c_log_GDPpc | AD1: c_log_Pop15_64 | AE1: c_YouthUnempl | AG1: Check GDP | AH1: Check POP | AI1: CHECK YU | AJ1: CHECK_APP
A2: 2016 | B2: Austria | C2: =VLOOKUP(B2,Sheet5!$B$2:$C$2166,2,FALSE) -> 650 | D2: 650 | E2: 370 | F2: 0.5670000000000001 | G2: 5 | H2: 6.4769724 | I2: 1 | J2: 1 | K2: 0 | L2: -4 | M2: Real_EU | N2: Austria | O2: 1 | P2: 0 | Q2: AUT | R2: =VLOOKUP(Q2,GDP!$A$2:$B$266,1,FALSE) -> AUT | S2: =VLOOKUP(Q2,GDP!$A$2:$B$266,2,FALSE) -> Austria | T2: =VLOOKUP(Q2,GDP!$A$1:$C$266,3,FALSE) -> 61572.626 | U2: 61572.626 | V2: =VLOOKUP(Q2,POP!$B$5:$M$269,3,FALSE) -> 5865273 | W2: 5865273 | X2: =VLOOKUP(Q2,YU!$B$1:$D$266,3,FALSE) -> 11.424 | Y2: 11.424 | Z2: 5.5095401 | AA2: =LN(T2) -> 11.027973 | AB2: =AA2-AVERAGE($AA$2:$AA$469) -> 0.50357596 | AC2: 0.50357596 | AD2: -0.32732552 | AE2: -3.891406 | AG2: =T2-U2 -> 0 | AH2: =V2-W2 -> 0 | AI2: =X2-Y2 -> 0 | AJ2: =LN(C2)-H2 -> 0
A3: 2017 | B3: Austria | C3: =VLOOKUP(B3,Sheet5!$B$2:$C$2166,2,FALSE) -> 650 | D3: 590 | E3: 340 | F3: 0.5710000000000001 | G3: 0 | H3: 6.3801225 | I3: 1 | J3: 1 | K3: 0 | L3: -3 | M3: Real_EU | N3: Austria | O3: 1 | P3: 0 | Q3: AUT | R3: =VLOOKUP(Q3,GDP!$A$2:$B$266,1,FALSE) -> AUT | S3: =VLOOKUP(Q3,GDP!$A$2:$B$266,2,FALSE) -> Austria | T3: =VLOOKUP(Q3,GDP!$A$1:$L$266,4,FALSE) -> 62535.811 | U3: 62535.811 | V3: =VLOOKUP(Q3,POP!$B$5:$M$269,4,FALSE) -> 5892111 | W3: 5892111 | X3: =VLOOKUP(Q3,YU!$B$1:$M$266,4,FALSE) -> 9.971 | Y3: 9.971 | Z3: 5.4018102 | AA3: =LN(T3) -> 11.043495 | AB3: =AA3-AVERAGE($AA$2:$AA$469) -> 0.51909794 | AC3: 0.51909794 | AD3: -0.32276021 | AE3: -5.344406 | AG3: =T3-U3 -> 0 | AH3: =V3-W3 -> 0 | AI3: =X3-Y3 -> 0 | AJ3: =LN(C3)-H3 -> 0.096849826
A4: 2018 | B4: Austria | C4: =VLOOKUP(B4,Sheet5!$B$2:$C$2166,2,FALSE) -> 650 | D4: 625 | E4: 335 | F4: 0.537 | G4: 0 | H4: 6.4377516 | I4: 1 | J4: 1 | K4: 0 | L4: -2 | M4: Real_EU | N4: Austria | O4: 1 | P4: 0 | Q4: AUT | R4: =VLOOKUP(Q4,GDP!$A$2:$B$266,1,FALSE) -> AUT | S4: =VLOOKUP(Q4,GDP!$A$2:$B$266,2,FALSE) -> Austria | T4: =VLOOKUP(Q4,GDP!$A$1:$L$266,5,FALSE) -> 63777.936 | U4: 63777.936 | V4: =VLOOKUP(Q4,POP!$B$5:$M$269,5,FALSE) -> 5906127 | W4: 5906127 | X4: =VLOOKUP(Q4,YU!$B$1:$M$266,5,FALSE) -> 9.572 | Y4: 9.572 | Z4: 5.2543702 | AA4: =LN(T4) -> 11.063163 | AB4: =AA4-AVERAGE($AA$2:$AA$469) -> 0.53876588 | AC4: 0.53876588 | AD4: -0.32038426 | AE4: -5.743406 | AG4: =T4-U4 -> 0 | AH4: =V4-W4 -> 0 | AI4: =X4-Y4 -> 0 | AJ4: =LN(C4)-H4 -> 0.039220713
A5: 2019 | B5: Austria | C5: =VLOOKUP(B5,Sheet5!$B$2:$C$2166,2,FALSE) -> 650 | D5: 625 | E5: 345 | F5: 0.551 | G5: 0 | H5: 6.4377516 | I5: 1 | J5: 1 | K5: 0 | L5: -1 | M5: Real_EU | N5: Austria | O5: 1 | P5: 0 | Q5: AUT | R5: =VLOOKUP(Q5,GDP!$A$2:$B$266,1,FALSE) -> AUT | S5: =VLOOKUP(Q5,GDP!$A$2:$B$266,2,FALSE) -> Austria | T5: =VLOOKUP(Q5,GDP!$A$1:$L$266,6,FALSE) -> 64609.284 | U5: 64609.284 | V5: =VLOOKUP(Q5,POP!$B$5:$M$269,6,FALSE) -> 5917299 | W5: 5917299 | X5: =VLOOKUP(Q5,YU!$B$1:$M$266,6,FALSE) -> 8.767 | Y5: 8.767 | Z5: 5.2367802 | AA5: =LN(T5) -> 11.076113 | AB5: =AA5-AVERAGE($AA$2:$AA$469) -> 0.55171669 | AC5: 0.55171669 | AD5: -0.31849446 | AE5: -6.548406 | AG5: =T5-U5 -> 0 | AH5: =V5-W5 -> 0 | AI5: =X5-Y5 -> 0 | AJ5: =LN(C5)-H5 -> 0.039220713
A6: 2020 | B6: Austria | C6: =VLOOKUP(B6,Sheet5!$B$2:$C$2166,2,FALSE) -> 650 | D6: 550 | E6: 295 | F6: 0.535 | G6: 0 | H6: 6.3099183 | I6: 1 | J6: 1 | K6: 0 | L6: 0 | M6: Real_EU | N6: Austria | O6: 1 | P6: 0 | Q6: AUT | R6: =VLOOKUP(Q6,GDP!$A$2:$B$266,1,FALSE) -> AUT | S6: =VLOOKUP(Q6,GDP!$A$2:$B$266,2,FALSE) -> Austria | T6: =VLOOKUP(Q6,GDP!$A$1:$L$266,7,FALSE) -> 60276.331 | U6: 60276.331 | V6: =VLOOKUP(Q6,POP!$B$5:$M$269,7,FALSE) -> 5924102 | W6: 5924102 | X6: =VLOOKUP(Q6,YU!$B$1:$M$266,7,FALSE) -> 10.325 | Y6: 10.325 | Z6: 5.5796199 | AA6: =LN(T6) -> 11.006695 | AB6: =AA6-AVERAGE($AA$2:$AA$469) -> 0.48229808 | AC6: 0.48229808 | AD6: -0.31734544 | AE6: -4.990406 | AG6: =T6-U6 -> 0 | AH6: =V6-W6 -> 0 | AI6: =X6-Y6 -> 0 | AJ6: =LN(C6)-H6 -> 0.16705408
A7: 2021 | B7: Austria | C7: =VLOOKUP(B7,Sheet5!$B$2:$C$2166,2,FALSE) -> 650 | D7: 405 | E7: 165 | F7: 0.41300000000000003 | G7: 0 | H7: 6.0038871 | I7: 1 | J7: 1 | K7: 1 | L7: 1 | M7: Real_EU | N7: Austria | O7: 1 | P7: 1 | Q7: AUT | R7: =VLOOKUP(Q7,GDP!$A$2:$B$266,1,FALSE) -> AUT | S7: =VLOOKUP(Q7,GDP!$A$2:$B$266,2,FALSE) -> Austria | T7: =VLOOKUP(Q7,GDP!$A$1:$L$266,8,FALSE) -> 62968.854 | U7: 62968.854 | V7: =VLOOKUP(Q7,POP!$B$5:$M$269,8,FALSE) -> 5926631 | W7: 5926631 | X7: =VLOOKUP(Q7,YU!$B$1:$M$266,8,FALSE) -> 12.023 | Y7: 12.023 | Z7: 5.48071 | AA7: =LN(T7) -> 11.050396 | AB7: =AA7-AVERAGE($AA$2:$AA$469) -> 0.5259988 | AC7: 0.5259988 | AD7: -0.31691863 | AE7: -3.292406 | AG7: =T7-U7 -> 0 | AH7: =V7-W7 -> 0 | AI7: =X7-Y7 -> 0 | AJ7: =LN(C7)-H7 -> 0.4730853
A8: 2022 | B8: Austria | C8: =VLOOKUP(B8,Sheet5!$B$2:$C$2166,2,FALSE) -> 650 | D8: 365 | E8: 170 | F8: 0.463 | G8: 0 | H8: 5.8998974 | I8: 1 | J8: 1 | K8: 1 | L8: 2 | M8: Real_EU | N8: Austria | O8: 1 | P8: 1 | Q8: AUT | R8: =VLOOKUP(Q8,GDP!$A$2:$B$266,1,FALSE) -> AUT | S8: =VLOOKUP(Q8,GDP!$A$2:$B$266,2,FALSE) -> Austria | T8: =VLOOKUP(Q8,GDP!$A$1:$L$266,9,FALSE) -> 65694.459 | U8: 65694.459 | V8: =VLOOKUP(Q8,POP!$B$5:$M$269,9,FALSE) -> 5955333 | W8: 5955333 | X8: =VLOOKUP(Q8,YU!$B$1:$M$266,9,FALSE) -> 10.327 | Y8: 10.327 | Z8: 5.2774901 | AA8: =LN(T8) -> 11.09277 | AB8: =AA8-AVERAGE($AA$2:$AA$469) -> 0.56837316 | AC8: 0.56837316 | AD8: -0.31208743 | AE8: -4.988406 | AG8: =T8-U8 -> 0 | AH8: =V8-W8 -> 0 | AI8: =X8-Y8 -> 0 | AJ8: =LN(C8)-H8 -> 0.57707501
A9: 2023 | B9: Austria | C9: =VLOOKUP(B9,Sheet5!$B$2:$C$2166,2,FALSE) -> 650 | D9: 340 | E9: 155 | F9: 0.449 | G9: 0 | H9: 5.8289456 | I9: 1 | J9: 1 | K9: 1 | L9: 3 | M9: Real_EU | N9: Austria | O9: 1 | P9: 1 | Q9: AUT | R9: =VLOOKUP(Q9,GDP!$A$2:$B$266,1,FALSE) -> AUT | S9: =VLOOKUP(Q9,GDP!$A$2:$B$266,2,FALSE) -> Austria | T9: =VLOOKUP(Q9,GDP!$A$1:$L$266,10,FALSE) -> 64536.208 | U9: 64536.208 | V9: =VLOOKUP(Q9,POP!$B$5:$M$269,10,FALSE) -> 5984348 | W9: 5984348 | X9: =VLOOKUP(Q9,YU!$B$1:$M$266,10,FALSE) -> 10.98 | Y9: 10.98 | AA9: =LN(T9) -> 11.074982 | AB9: =AA9-AVERAGE($AA$2:$AA$469) -> 0.550585 | AC9: 0.550585 | AD9: -0.30722716 | AE9: -4.335406 | AG9: =T9-U9 -> 0 | AH9: =V9-W9 -> 0 | AI9: =X9-Y9 -> 0 | AJ9: =LN(C9)-H9 -> 0.64802675
A10: 2024 | B10: Austria | C10: =VLOOKUP(B10,Sheet5!$B$2:$C$2166,2,FALSE) -> 650 | D10: 365 | E10: 160 | F10: 0.44 | G10: 0 | H10: 5.8998974 | I10: 1 | J10: 1 | K10: 1 | L10: 4 | M10: Real_EU | N10: Austria | O10: 1 | P10: 1 | Q10: AUT | R10: =VLOOKUP(Q10,GDP!$A$2:$B$266,1,FALSE) -> AUT | S10: =VLOOKUP(Q10,GDP!$A$2:$B$266,2,FALSE) -> Austria | T10: =VLOOKUP(Q10,GDP!$A$1:$L$266,11,FALSE) -> 63787.989 | U10: 63787.989 | V10: =VLOOKUP(Q10,POP!$B$5:$M$269,11,FALSE) -> 5980887 | W10: 5980887 | X10: =VLOOKUP(Q10,YU!$B$1:$M$266,11,FALSE) -> 10.428 | Y10: 10.428 | AA10: =LN(T10) -> 11.06332 | AB10: =AA10-AVERAGE($AA$2:$AA$469) -> 0.53892349 | AC10: 0.53892349 | AD10: -0.30780567 | AE10: -4.887406 | AG10: =T10-U10 -> 0 | AH10: =V10-W10 -> 0 | AI10: =X10-Y10 -> 0 | AJ10: =LN(C10)-H10 -> 0.57707501
A11: 2016 | B11: Belgium | C11: =VLOOKUP(B11,Sheet5!$B$2:$C$2166,2,FALSE) -> 1135 | D11: 1135 | E11: 645 | F11: 0.5700000000000001 | G11: 0 | H11: 7.0343879 | I11: 1 | J11: 1 | K11: 0 | L11: -4 | M11: Real_EU | N11: Belgium | O11: 1 | P11: 0 | Q11: BEL | R11: =VLOOKUP(Q11,GDP!$A$2:$B$266,1,FALSE) -> BEL | S11: =VLOOKUP(Q11,GDP!$A$2:$B$266,2,FALSE) -> Belgium | T11: =VLOOKUP(Q11,GDP!$A$1:$C$266,3,FALSE) -> 57901.498 | U11: 57901.498 | V11: =VLOOKUP(Q11,POP!$B$5:$M$269,3,FALSE) -> 7326984 | W11: 7326984 | X11: =VLOOKUP(Q11,YU!$B$1:$D$266,3,FALSE) -> 20.108 | Y11: 20.108 | Z11: 6.4861302 | AA11: =LN(T11) -> 10.966499 | AB11: =AA11-AVERAGE($AA$2:$AA$469) -> 0.44210183 | AC11: 0.44210183 | AD11: -0.10481058 | AE11: 4.792594 | AG11: =T11-U11 -> 0 | AH11: =V11-W11 -> 0 | AI11: =X11-Y11 -> 0 | AJ11: =LN(C11)-H11 -> 0
A12: 2017 | B12: Belgium | C12: =VLOOKUP(B12,Sheet5!$B$2:$C$2166,2,FALSE) -> 1135 | D12: 1105 | E12: 650 | F12: 0.589 | G12: 5 | H12: 7.0076006 | I12: 1 | J12: 1 | K12: 0 | L12: -3 | M12: Real_EU | N12: Belgium | O12: 1 | P12: 0 | Q12: BEL | R12: =VLOOKUP(Q12,GDP!$A$2:$B$266,1,FALSE) -> BEL | S12: =VLOOKUP(Q12,GDP!$A$2:$B$266,2,FALSE) -> Belgium | T12: =VLOOKUP(Q12,GDP!$A$1:$L$266,4,FALSE) -> 58529.33 | U12: 58529.33 | V12: =VLOOKUP(Q12,POP!$B$5:$M$269,4,FALSE) -> 7330451 | W12: 7330451 | X12: =VLOOKUP(Q12,YU!$B$1:$M$266,4,FALSE) -> 19.236 | Y12: 19.236 | Z12: 6.4491501 | AA12: =LN(T12) -> 10.977283 | AB12: =AA12-AVERAGE($AA$2:$AA$469) -> 0.45288658 | AC12: 0.45288658 | AD12: -0.10433751 | AE12: 3.920594 | AG12: =T12-U12 -> 0 | AH12: =V12-W12 -> 0 | AI12: =X12-Y12 -> 0 | AJ12: =LN(C12)-H12 -> 0.026787316
A13: 2018 | B13: Belgium | C13: =VLOOKUP(B13,Sheet5!$B$2:$C$2166,2,FALSE) -> 1135 | D13: 1110 | E13: 670 | F13: 0.605 | G13: 5 | H13: 7.0121153 | I13: 1 | J13: 1 | K13: 0 | L13: -2 | M13: Real_EU | N13: Belgium | O13: 1 | P13: 0 | Q13: BEL | R13: =VLOOKUP(Q13,GDP!$A$2:$B$266,1,FALSE) -> BEL | S13: =VLOOKUP(Q13,GDP!$A$2:$B$266,2,FALSE) -> Belgium | T13: =VLOOKUP(Q13,GDP!$A$1:$L$266,5,FALSE) -> 59357.69 | U13: 59357.69 | V13: =VLOOKUP(Q13,POP!$B$5:$M$269,5,FALSE) -> 7341283 | W13: 7341283 | X13: =VLOOKUP(Q13,YU!$B$1:$M$266,5,FALSE) -> 15.748 | Y13: 15.748 | Z13: 6.3888302 | AA13: =LN(T13) -> 10.991337 | AB13: =AA13-AVERAGE($AA$2:$AA$469) -> 0.46694025 | AC13: 0.46694025 | AD13: -0.10286093 | AE13: 0.43259402 | AG13: =T13-U13 -> 0 | AH13: =V13-W13 -> 0 | AI13: =X13-Y13 -> 0 | AJ13: =LN(C13)-H13 -> 0.022272636
A14: 2019 | B14: Belgium | C14: =VLOOKUP(B14,Sheet5!$B$2:$C$2166,2,FALSE) -> 1135 | D14: 1055 | E14: 605 | F14: 0.5710000000000001 | G14: 5 | H14: 6.961296 | I14: 1 | J14: 1 | K14: 0 | L14: -1 | M14: Real_EU | N14: Belgium | O14: 1 | P14: 0 | Q14: BEL | R14: =VLOOKUP(Q14,GDP!$A$2:$B$266,1,FALSE) -> BEL | S14: =VLOOKUP(Q14,GDP!$A$2:$B$266,2,FALSE) -> Belgium | T14: =VLOOKUP(Q14,GDP!$A$1:$L$266,6,FALSE) -> 60479.977 | U14: 60479.977 | V14: =VLOOKUP(Q14,POP!$B$5:$M$269,6,FALSE) -> 7362072 | W14: 7362072 | X14: =VLOOKUP(Q14,YU!$B$1:$M$266,6,FALSE) -> 14.236 | Y14: 14.236 | Z14: 6.3238101 | AA14: =LN(T14) -> 11.010068 | AB14: =AA14-AVERAGE($AA$2:$AA$469) -> 0.48567093 | AC14: 0.48567093 | AD14: -0.10003314 | AE14: -1.079406 | AG14: =T14-U14 -> 0 | AH14: =V14-W14 -> 0 | AI14: =X14-Y14 -> 0 | AJ14: =LN(C14)-H14 -> 0.073091884
A15: 2020 | B15: Belgium | C15: =VLOOKUP(B15,Sheet5!$B$2:$C$2166,2,FALSE) -> 1135 | D15: 1025 | E15: 595 | F15: 0.58 | G15: 10 | H15: 6.9324479 | I15: 1 | J15: 1 | K15: 0 | L15: 0 | M15: Real_EU | N15: Belgium | O15: 1 | P15: 0 | Q15: BEL | R15: =VLOOKUP(Q15,GDP!$A$2:$B$266,1,FALSE) -> BEL | S15: =VLOOKUP(Q15,GDP!$A$2:$B$266,2,FALSE) -> Belgium | T15: =VLOOKUP(Q15,GDP!$A$1:$L$266,7,FALSE) -> 57333.542 | U15: 57333.542 | V15: =VLOOKUP(Q15,POP!$B$5:$M$269,7,FALSE) -> 7381890 | W15: 7381890 | X15: =VLOOKUP(Q15,YU!$B$1:$M$266,7,FALSE) -> 15.326 | Y15: 15.326 | Z15: 6.7547002 | AA15: =LN(T15) -> 10.956641 | AB15: =AA15-AVERAGE($AA$2:$AA$469) -> 0.43224441 | AC15: 0.43224441 | AD15: -0.097344847 | AE15: 0.010594017 | AG15: =T15-U15 -> 0 | AH15: =V15-W15 -> 0 | AI15: =X15-Y15 -> 0 | AJ15: =LN(C15)-H15 -> 0.10194004
A16: 2021 | B16: Belgium | C16: =VLOOKUP(B16,Sheet5!$B$2:$C$2166,2,FALSE) -> 1135 | D16: 725 | E16: 345 | F16: 0.47400000000000003 | G16: 0 | H16: 6.5861717 | I16: 1 | J16: 1 | K16: 1 | L16: 1 | M16: Real_EU | N16: Belgium | O16: 1 | P16: 1 | Q16: BEL | R16: =VLOOKUP(Q16,GDP!$A$2:$B$266,1,FALSE) -> BEL | S16: =VLOOKUP(Q16,GDP!$A$2:$B$266,2,FALSE) -> Belgium | T16: =VLOOKUP(Q16,GDP!$A$1:$L$266,8,FALSE) -> 60669.214 | U16: 60669.214 | V16: =VLOOKUP(Q16,POP!$B$5:$M$269,8,FALSE) -> 7399545 | W16: 7399545 | X16: =VLOOKUP(Q16,YU!$B$1:$M$266,8,FALSE) -> 18.206 | Y16: 18.206 | Z16: 6.3808198 | AA16: =LN(T16) -> 11.013192 | AB16: =AA16-AVERAGE($AA$2:$AA$469) -> 0.48879496 | AC16: 0.48879496 | AD16: -0.094956038 | AE16: 2.890594 | AG16: =T16-U16 -> 0 | AH16: =V16-W16 -> 0 | AI16: =X16-Y16 -> 0 | AJ16: =LN(C16)-H16 -> 0.44821628
A17: 2022 | B17: Belgium | C17: =VLOOKUP(B17,Sheet5!$B$2:$C$2166,2,FALSE) -> 1135 | D17: 620 | E17: 305 | F17: 0.489 | G17: 5 | H17: 6.4297195 | I17: 1 | J17: 1 | K17: 1 | L17: 2 | M17: Real_EU | N17: Belgium | O17: 1 | P17: 1 | Q17: BEL | R17: =VLOOKUP(Q17,GDP!$A$2:$B$266,1,FALSE) -> BEL | S17: =VLOOKUP(Q17,GDP!$A$2:$B$266,2,FALSE) -> Belgium | T17: =VLOOKUP(Q17,GDP!$A$1:$L$266,9,FALSE) -> 62602.927 | U17: 62602.927 | V17: =VLOOKUP(Q17,POP!$B$5:$M$269,9,FALSE) -> 7440659 | W17: 7440659 | X17: =VLOOKUP(Q17,YU!$B$1:$M$266,9,FALSE) -> 16.41 | Y17: 16.41 | Z17: 6.2761102 | AA17: =LN(T17) -> 11.044567 | AB17: =AA17-AVERAGE($AA$2:$AA$469) -> 0.52017061 | AC17: 0.52017061 | AD17: -0.08941513 | AE17: 1.094594 | AG17: =T17-U17 -> 0 | AH17: =V17-W17 -> 0 | AI17: =X17-Y17 -> 0 | AJ17: =LN(C17)-H17 -> 0.60466845
A18: 2023 | B18: Belgium | C18: =VLOOKUP(B18,Sheet5!$B$2:$C$2166,2,FALSE) -> 1135 | D18: 590 | E18: 295 | F18: 0.499 | G18: 5 | H18: 6.3801225 | I18: 1 | J18: 1 | K18: 1 | L18: 3 | M18: Real_EU | N18: Belgium | O18: 1 | P18: 1 | Q18: BEL | R18: =VLOOKUP(Q18,GDP!$A$2:$B$266,1,FALSE) -> BEL | S18: =VLOOKUP(Q18,GDP!$A$2:$B$266,2,FALSE) -> Belgium | T18: =VLOOKUP(Q18,GDP!$A$1:$L$266,10,FALSE) -> 63042.01 | U18: 63042.01 | V18: =VLOOKUP(Q18,POP!$B$5:$M$269,10,FALSE) -> 7487803 | W18: 7487803 | X18: =VLOOKUP(Q18,YU!$B$1:$M$266,10,FALSE) -> 16.119 | Y18: 16.119 | AA18: =LN(T18) -> 11.051557 | AB18: =AA18-AVERAGE($AA$2:$AA$469) -> 0.52715991 | AC18: 0.52715991 | AD18: -0.08309912 | AE18: 0.80359402 | AG18: =T18-U18 -> 0 | AH18: =V18-W18 -> 0 | AI18: =X18-Y18 -> 0 | AJ18: =LN(C18)-H18 -> 0.65426539
A19: 2024 | B19: Belgium | C19: =VLOOKUP(B19,Sheet5!$B$2:$C$2166,2,FALSE) -> 1135 | D19: 575 | E19: 285 | F19: 0.492 | G19: 5 | H19: 6.35437 | I19: 1 | J19: 1 | K19: 1 | L19: 4 | M19: Real_EU | N19: Belgium | O19: 1 | P19: 1 | Q19: BEL | R19: =VLOOKUP(Q19,GDP!$A$2:$B$266,1,FALSE) -> BEL | S19: =VLOOKUP(Q19,GDP!$A$2:$B$266,2,FALSE) -> Belgium | T19: =VLOOKUP(Q19,GDP!$A$1:$L$266,11,FALSE) -> 63311.277 | U19: 63311.277 | V19: =VLOOKUP(Q19,POP!$B$5:$M$269,11,FALSE) -> 7523789 | W19: 7523789 | X19: =VLOOKUP(Q19,YU!$B$1:$M$266,11,FALSE) -> 17.343 | Y19: 17.343 | AA19: =LN(T19) -> 11.055819 | AB19: =AA19-AVERAGE($AA$2:$AA$469) -> 0.53142204 | AC19: 0.53142204 | AD19: -0.078304683 | AE19: 2.027594 | AG19: =T19-U19 -> 0 | AH19: =V19-W19 -> 0 | AI19: =X19-Y19 -> 0 | AJ19: =LN(C19)-H19 -> 0.68001789
A20: 2016 | B20: Bulgaria | C20: =VLOOKUP(B20,Sheet5!$B$2:$C$2166,2,FALSE) -> 2515 | D20: 2515 | E20: 1830 | F20: 0.729 | G20: 5 | H20: 7.8300281 | I20: 1 | J20: 1 | K20: 0 | L20: -4 | M20: Real_EU | N20: Bulgaria | O20: 1 | P20: 0 | Q20: BGR | R20: =VLOOKUP(Q20,GDP!$A$2:$B$266,1,FALSE) -> BGR | S20: =VLOOKUP(Q20,GDP!$A$2:$B$266,2,FALSE) -> Bulgaria | T20: =VLOOKUP(Q20,GDP!$A$1:$C$266,3,FALSE) -> 25636.744 | U20: 25636.744 | V20: =VLOOKUP(Q20,POP!$B$5:$M$269,3,FALSE) -> 4508700 | W20: 4508700 | X20: =VLOOKUP(Q20,YU!$B$1:$D$266,3,FALSE) -> 17.224 | Y20: 17.224 | Z20: 3.8143599 | AA20: =LN(T20) -> 10.151782 | AB20: =AA20-AVERAGE($AA$2:$AA$469) -> -0.37261477 | AC20: -0.37261477 | AD20: -0.59036569 | AE20: 1.908594 | AG20: =T20-U20 -> 4.7293724e-11 | AH20: =V20-W20 -> 0 | AI20: =X20-Y20 -> 0 | AJ20: =LN(C20)-H20 -> 0
A21: 2017 | B21: Bulgaria | C21: =VLOOKUP(B21,Sheet5!$B$2:$C$2166,2,FALSE) -> 2515 | D21: 2265 | E21: 1625 | F21: 0.718 | G21: 5 | H21: 7.72533 | I21: 1 | J21: 1 | K21: 0 | L21: -3 | M21: Real_EU | N21: Bulgaria | O21: 1 | P21: 0 | Q21: BGR | R21: =VLOOKUP(Q21,GDP!$A$2:$B$266,1,FALSE) -> BGR | S21: =VLOOKUP(Q21,GDP!$A$2:$B$266,2,FALSE) -> Bulgaria | T21: =VLOOKUP(Q21,GDP!$A$1:$L$266,4,FALSE) -> 26691.758 | U21: 26691.758 | V21: =VLOOKUP(Q21,POP!$B$5:$M$269,4,FALSE) -> 4419454 | W21: 4419454 | X21: =VLOOKUP(Q21,YU!$B$1:$M$266,4,FALSE) -> 12.927 | Y21: 12.927 | Z21: 4.0775499 | AA21: =LN(T21) -> 10.19211 | AB21: =AA21-AVERAGE($AA$2:$AA$469) -> -0.33228659 | AC21: -0.33228659 | AD21: -0.61035839 | AE21: -2.388406 | AG21: =T21-U21 -> 0 | AH21: =V21-W21 -> 0 | AI21: =X21-Y21 -> 0 | AJ21: =LN(C21)-H21 -> 0.10469804
A22: 2018 | B22: Bulgaria | C22: =VLOOKUP(B22,Sheet5!$B$2:$C$2166,2,FALSE) -> 2515 | D22: 2265 | E22: 1650 | F22: 0.729 | G22: 5 | H22: 7.72533 | I22: 1 | J22: 1 | K22: 0 | L22: -2 | M22: Real_EU | N22: Bulgaria | O22: 1 | P22: 0 | Q22: BGR | R22: =VLOOKUP(Q22,GDP!$A$2:$B$266,1,FALSE) -> BGR | S22: =VLOOKUP(Q22,GDP!$A$2:$B$266,2,FALSE) -> Bulgaria | T22: =VLOOKUP(Q22,GDP!$A$1:$L$266,5,FALSE) -> 27690.894 | U22: 27690.894 | V22: =VLOOKUP(Q22,POP!$B$5:$M$269,5,FALSE) -> 4330344 | W22: 4330344 | X22: =VLOOKUP(Q22,YU!$B$1:$M$266,5,FALSE) -> 12.676 | Y22: 12.676 | Z22: 4.0520101 | AA22: =LN(T22) -> 10.228859 | AB22: =AA22-AVERAGE($AA$2:$AA$469) -> -0.29553781 | AC22: -0.29553781 | AD22: -0.63072757 | AE22: -2.639406 | AG22: =T22-U22 -> 0 | AH22: =V22-W22 -> 0 | AI22: =X22-Y22 -> 0 | AJ22: =LN(C22)-H22 -> 0.10469804
A23: 2019 | B23: Bulgaria | C23: =VLOOKUP(B23,Sheet5!$B$2:$C$2166,2,FALSE) -> 2515 | D23: 2120 | E23: 1495 | F23: 0.705 | G23: 5 | H23: 7.6591714 | I23: 1 | J23: 1 | K23: 0 | L23: -1 | M23: Real_EU | N23: Bulgaria | O23: 1 | P23: 0 | Q23: BGR | R23: =VLOOKUP(Q23,GDP!$A$2:$B$266,1,FALSE) -> BGR | S23: =VLOOKUP(Q23,GDP!$A$2:$B$266,2,FALSE) -> Bulgaria | T23: =VLOOKUP(Q23,GDP!$A$1:$L$266,6,FALSE) -> 29149.922 | U23: 29149.922 | V23: =VLOOKUP(Q23,POP!$B$5:$M$269,6,FALSE) -> 4243540 | W23: 4243540 | X23: =VLOOKUP(Q23,YU!$B$1:$M$266,6,FALSE) -> 8.777 | Y23: 8.777 | Z23: 4.2143002 | AA23: =LN(T23) -> 10.280207 | AB23: =AA23-AVERAGE($AA$2:$AA$469) -> -0.2441892 | AC23: -0.2441892 | AD23: -0.65097672 | AE23: -6.538406 | AG23: =T23-U23 -> 0 | AH23: =V23-W23 -> 0 | AI23: =X23-Y23 -> 0 | AJ23: =LN(C23)-H23 -> 0.17085671
A24: 2020 | B24: Bulgaria | C24: =VLOOKUP(B24,Sheet5!$B$2:$C$2166,2,FALSE) -> 2515 | D24: 1935 | E24: 1350 | F24: 0.6990000000000001 | G24: 5 | H24: 7.5678626 | I24: 1 | J24: 1 | K24: 0 | L24: 0 | M24: Real_EU | N24: Bulgaria | O24: 1 | P24: 0 | Q24: BGR | R24: =VLOOKUP(Q24,GDP!$A$2:$B$266,1,FALSE) -> BGR | S24: =VLOOKUP(Q24,GDP!$A$2:$B$266,2,FALSE) -> Bulgaria | T24: =VLOOKUP(Q24,GDP!$A$1:$L$266,7,FALSE) -> 28521.206 | U24: 28521.206 | V24: =VLOOKUP(Q24,POP!$B$5:$M$269,7,FALSE) -> 4184680 | W24: 4184680 | X24: =VLOOKUP(Q24,YU!$B$1:$M$266,7,FALSE) -> 14.143 | Y24: 14.143 | Z24: 4.4829898 | AA24: =LN(T24) -> 10.258403 | AB24: =AA24-AVERAGE($AA$2:$AA$469) -> -0.26599353 | AC24: -0.26599353 | AD24: -0.66494431 | AE24: -1.172406 | AG24: =T24-U24 -> 0 | AH24: =V24-W24 -> 0 | AI24: =X24-Y24 -> 0 | AJ24: =LN(C24)-H24 -> 0.26216548
A25: 2021 | B25: Bulgaria | C25: =VLOOKUP(B25,Sheet5!$B$2:$C$2166,2,FALSE) -> 2515 | D25: 525 | E25: 255 | F25: 0.484 | G25: 0 | H25: 6.2633983 | I25: 1 | J25: 1 | K25: 1 | L25: 1 | M25: Real_EU | N25: Bulgaria | O25: 1 | P25: 1 | Q25: BGR | R25: =VLOOKUP(Q25,GDP!$A$2:$B$266,1,FALSE) -> BGR | S25: =VLOOKUP(Q25,GDP!$A$2:$B$266,2,FALSE) -> Bulgaria | T25: =VLOOKUP(Q25,GDP!$A$1:$L$266,8,FALSE) -> 30958.983 | U25: 30958.983 | V25: =VLOOKUP(Q25,POP!$B$5:$M$269,8,FALSE) -> 4152537 | W25: 4152537 | X25: =VLOOKUP(Q25,YU!$B$1:$M$266,8,FALSE) -> 15.701 | Y25: 15.701 | Z25: 4.70924 | AA25: =LN(T25) -> 10.340418 | AB25: =AA25-AVERAGE($AA$2:$AA$469) -> -0.18397822 | AC25: -0.18397822 | AD25: -0.67265508 | AE25: 0.38559402 | AG25: =T25-U25 -> 0 | AH25: =V25-W25 -> 0 | AI25: =X25-Y25 -> 0 | AJ25: =LN(C25)-H25 -> 1.5666298
A26: 2022 | B26: Bulgaria | C26: =VLOOKUP(B26,Sheet5!$B$2:$C$2166,2,FALSE) -> 2515 | D26: 305 | E26: 150 | F26: 0.493 | G26: 0 | H26: 5.7203118 | I26: 1 | J26: 1 | K26: 1 | L26: 2 | M26: Real_EU | N26: Bulgaria | O26: 1 | P26: 1 | Q26: BGR | R26: =VLOOKUP(Q26,GDP!$A$2:$B$266,1,FALSE) -> BGR | S26: =VLOOKUP(Q26,GDP!$A$2:$B$266,2,FALSE) -> Bulgaria | T26: =VLOOKUP(Q26,GDP!$A$1:$L$266,9,FALSE) -> 32433.659 | U26: 32433.659 | V26: =VLOOKUP(Q26,POP!$B$5:$M$269,9,FALSE) -> 4122370 | W26: 4122370 | X26: =VLOOKUP(Q26,YU!$B$1:$M$266,9,FALSE) -> 10.582 | Y26: 10.582 | Z26: 4.50109 | AA26: =LN(T26) -> 10.386952 | AB26: =AA26-AVERAGE($AA$2:$AA$469) -> -0.13744469 | AC26: -0.13744469 | AD26: -0.67994631 | AE26: -4.733406 | AG26: =T26-U26 -> 4.7293724e-11 | AH26: =V26-W26 -> 0 | AI26: =X26-Y26 -> 0 | AJ26: =LN(C26)-H26 -> 2.1097163
A27: 2023 | B27: Bulgaria | C27: =VLOOKUP(B27,Sheet5!$B$2:$C$2166,2,FALSE) -> 2515 | D27: 335 | E27: 150 | F27: 0.456 | G27: 0 | H27: 5.8141305 | I27: 1 | J27: 1 | K27: 1 | L27: 3 | M27: Real_EU | N27: Bulgaria | O27: 1 | P27: 1 | Q27: BGR | R27: =VLOOKUP(Q27,GDP!$A$2:$B$266,1,FALSE) -> BGR | S27: =VLOOKUP(Q27,GDP!$A$2:$B$266,2,FALSE) -> Bulgaria | T27: =VLOOKUP(Q27,GDP!$A$1:$L$266,10,FALSE) -> 33073.68 | U27: 33073.68 | V27: =VLOOKUP(Q27,POP!$B$5:$M$269,10,FALSE) -> 4101928 | W27: 4101928 | X27: =VLOOKUP(Q27,YU!$B$1:$M$266,10,FALSE) -> 12.049 | Y27: 12.049 | AA27: =LN(T27) -> 10.406493 | AB27: =AA27-AVERAGE($AA$2:$AA$469) -> -0.11790361 | AC27: -0.11790361 | AD27: -0.68491744 | AE27: -3.266406 | AG27: =T27-U27 -> 0 | AH27: =V27-W27 -> 0 | AI27: =X27-Y27 -> 0 | AJ27: =LN(C27)-H27 -> 2.0158976
A28: 2024 | B28: Bulgaria | C28: =VLOOKUP(B28,Sheet5!$B$2:$C$2166,2,FALSE) -> 2515 | D28: 300 | E28: 150 | F28: 0.507 | G28: 0 | H28: 5.7037825 | I28: 1 | J28: 1 | K28: 1 | L28: 4 | M28: Real_EU | N28: Bulgaria | O28: 1 | P28: 1 | Q28: BGR | R28: =VLOOKUP(Q28,GDP!$A$2:$B$266,1,FALSE) -> BGR | S28: =VLOOKUP(Q28,GDP!$A$2:$B$266,2,FALSE) -> Bulgaria | T28: =VLOOKUP(Q28,GDP!$A$1:$L$266,11,FALSE) -> 34221.387 | U28: 34221.387 | V28: =VLOOKUP(Q28,POP!$B$5:$M$269,11,FALSE) -> 4089993 | W28: 4089993 | X28: =VLOOKUP(Q28,YU!$B$1:$M$266,11,FALSE) -> 12.493 | Y28: 12.493 | AA28: =LN(T28) -> 10.440606 | AB28: =AA28-AVERAGE($AA$2:$AA$469) -> -0.083790633 | AC28: -0.083790633 | AD28: -0.68783129 | AE28: -2.822406 | AG28: =T28-U28 -> 0 | AH28: =V28-W28 -> 0 | AI28: =X28-Y28 -> 0 | AJ28: =LN(C28)-H28 -> 2.1262456
A29: 2016 | B29: Denmark | C29: =VLOOKUP(B29,Sheet5!$B$2:$C$2166,2,FALSE) -> 520 | D29: 520 | E29: 285 | F29: 0.547 | G29: 0 | H29: 6.2538288 | I29: 1 | J29: 1 | K29: 0 | L29: -4 | M29: Real_EU | N29: Denmark | O29: 1 | P29: 0 | Q29: DNK | R29: =VLOOKUP(Q29,GDP!$A$2:$B$266,1,FALSE) -> DNK | S29: =VLOOKUP(Q29,GDP!$A$2:$B$266,2,FALSE) -> Denmark | T29: =VLOOKUP(Q29,GDP!$A$1:$C$266,3,FALSE) -> 63468.989 | U29: 63468.989 | V29: =VLOOKUP(Q29,POP!$B$5:$M$269,3,FALSE) -> 3682112 | W29: 3682112 | X29: =VLOOKUP(Q29,YU!$B$1:$D$266,3,FALSE) -> 12.147 | Y29: 12.147 | Z29: 7.7153401 | AA29: =LN(T29) -> 11.058307 | AB29: =AA29-AVERAGE($AA$2:$AA$469) -> 0.53391 | AC29: 0.53391 | AD29: -0.79288805 | AE29: -3.168406 | AG29: =T29-U29 -> 0 | AH29: =V29-W29 -> 0 | AI29: =X29-Y29 -> 0 | AJ29: =LN(C29)-H29 -> 0
A30: 2017 | B30: Denmark | C30: =VLOOKUP(B30,Sheet5!$B$2:$C$2166,2,FALSE) -> 520 | D30: 545 | E30: 275 | F30: 0.506 | G30: 0 | H30: 6.3007858 | I30: 1 | J30: 1 | K30: 0 | L30: -3 | M30: Real_EU | N30: Denmark | O30: 1 | P30: 0 | Q30: DNK | R30: =VLOOKUP(Q30,GDP!$A$2:$B$266,1,FALSE) -> DNK | S30: =VLOOKUP(Q30,GDP!$A$2:$B$266,2,FALSE) -> Denmark | T30: =VLOOKUP(Q30,GDP!$A$1:$L$266,4,FALSE) -> 64989.446 | U30: 64989.446 | V30: =VLOOKUP(Q30,POP!$B$5:$M$269,4,FALSE) -> 3698112 | W30: 3698112 | X30: =VLOOKUP(Q30,YU!$B$1:$M$266,4,FALSE) -> 12.384 | Y30: 12.384 | Z30: 7.3700099 | AA30: =LN(T30) -> 11.08198 | AB30: =AA30-AVERAGE($AA$2:$AA$469) -> 0.55758346 | AC30: 0.55758346 | AD30: -0.78855213 | AE30: -2.931406 | AG30: =T30-U30 -> 0 | AH30: =V30-W30 -> 0 | AI30: =X30-Y30 -> 0 | AJ30: =LN(C30)-H30 -> -0.046956983
A31: 2018 | B31: Denmark | C31: =VLOOKUP(B31,Sheet5!$B$2:$C$2166,2,FALSE) -> 520 | D31: 550 | E31: 285 | F31: 0.516 | G31: 0 | H31: 6.3099183 | I31: 1 | J31: 1 | K31: 0 | L31: -2 | M31: Real_EU | N31: Denmark | O31: 1 | P31: 0 | Q31: DNK | R31: =VLOOKUP(Q31,GDP!$A$2:$B$266,1,FALSE) -> DNK | S31: =VLOOKUP(Q31,GDP!$A$2:$B$266,2,FALSE) -> Denmark | T31: =VLOOKUP(Q31,GDP!$A$1:$L$266,5,FALSE) -> 65870.83 | U31: 65870.83 | V31: =VLOOKUP(Q31,POP!$B$5:$M$269,5,FALSE) -> 3708367 | W31: 3708367 | X31: =VLOOKUP(Q31,YU!$B$1:$M$266,5,FALSE) -> 10.52 | Y31: 10.52 | Z31: 7.3274798 | AA31: =LN(T31) -> 11.095451 | AB31: =AA31-AVERAGE($AA$2:$AA$469) -> 0.57105428 | AC31: 0.57105428 | AD31: -0.78578293 | AE31: -4.795406 | AG31: =T31-U31 -> 0 | AH31: =V31-W31 -> 0 | AI31: =X31-Y31 -> 0 | AJ31: =LN(C31)-H31 -> -0.056089467
A32: 2019 | B32: Denmark | C32: =VLOOKUP(B32,Sheet5!$B$2:$C$2166,2,FALSE) -> 520 | D32: 530 | E32: 285 | F32: 0.537 | G32: 0 | H32: 6.272877 | I32: 1 | J32: 1 | K32: 0 | L32: -1 | M32: Real_EU | N32: Denmark | O32: 1 | P32: 0 | Q32: DNK | R32: =VLOOKUP(Q32,GDP!$A$2:$B$266,1,FALSE) -> DNK | S32: =VLOOKUP(Q32,GDP!$A$2:$B$266,2,FALSE) -> Denmark | T32: =VLOOKUP(Q32,GDP!$A$1:$L$266,6,FALSE) -> 66758.632 | U32: 66758.632 | V32: =VLOOKUP(Q32,POP!$B$5:$M$269,6,FALSE) -> 3712914 | W32: 3712914 | X32: =VLOOKUP(Q32,YU!$B$1:$M$266,6,FALSE) -> 10.041 | Y32: 10.041 | Z32: 7.2758598 | AA32: =LN(T32) -> 11.108839 | AB32: =AA32-AVERAGE($AA$2:$AA$469) -> 0.58444219 | AC32: 0.58444219 | AD32: -0.78455754 | AE32: -5.274406 | AG32: =T32-U32 -> 0 | AH32: =V32-W32 -> 0 | AI32: =X32-Y32 -> 0 | AJ32: =LN(C32)-H32 -> -0.019048195
A33: 2020 | B33: Denmark | C33: =VLOOKUP(B33,Sheet5!$B$2:$C$2166,2,FALSE) -> 520 | D33: 470 | E33: 250 | F33: 0.53 | G33: 0 | H33: 6.1527327 | I33: 1 | J33: 1 | K33: 0 | L33: 0 | M33: Real_EU | N33: Denmark | O33: 1 | P33: 0 | Q33: DNK | R33: =VLOOKUP(Q33,GDP!$A$2:$B$266,1,FALSE) -> DNK | S33: =VLOOKUP(Q33,GDP!$A$2:$B$266,2,FALSE) -> Denmark | T33: =VLOOKUP(Q33,GDP!$A$1:$L$266,7,FALSE) -> 65379.307 | U33: 65379.307 | V33: =VLOOKUP(Q33,POP!$B$5:$M$269,7,FALSE) -> 3714181 | W33: 3714181 | X33: =VLOOKUP(Q33,YU!$B$1:$M$266,7,FALSE) -> 11.634 | Y33: 11.634 | Z33: 7.3857498 | AA33: =LN(T33) -> 11.087961 | AB33: =AA33-AVERAGE($AA$2:$AA$469) -> 0.56356437 | AC33: 0.56356437 | AD33: -0.78421635 | AE33: -3.681406 | AG33: =T33-U33 -> 0 | AH33: =V33-W33 -> 0 | AI33: =X33-Y33 -> 0 | AJ33: =LN(C33)-H33 -> 0.10109612
A34: 2021 | B34: Denmark | C34: =VLOOKUP(B34,Sheet5!$B$2:$C$2166,2,FALSE) -> 520 | D34: 235 | E34: 95 | F34: 0.405 | G34: 0 | H34: 5.4595855 | I34: 1 | J34: 1 | K34: 1 | L34: 1 | M34: Real_EU | N34: Denmark | O34: 1 | P34: 1 | Q34: DNK | R34: =VLOOKUP(Q34,GDP!$A$2:$B$266,1,FALSE) -> DNK | S34: =VLOOKUP(Q34,GDP!$A$2:$B$266,2,FALSE) -> Denmark | T34: =VLOOKUP(Q34,GDP!$A$1:$L$266,8,FALSE) -> 69327.998 | U34: 69327.998 | V34: =VLOOKUP(Q34,POP!$B$5:$M$269,8,FALSE) -> 3723590 | W34: 3723590 | X34: =VLOOKUP(Q34,YU!$B$1:$M$266,8,FALSE) -> 10.8 | Y34: 10.8 | Z34: 6.9591599 | AA34: =LN(T34) -> 11.146604 | AB34: =AA34-AVERAGE($AA$2:$AA$469) -> 0.62220742 | AC34: 0.62220742 | AD34: -0.78168629 | AE34: -4.515406 | AG34: =T34-U34 -> 0 | AH34: =V34-W34 -> 0 | AI34: =X34-Y34 -> 0 | AJ34: =LN(C34)-H34 -> 0.7942433
A35: 2022 | B35: Denmark | C35: =VLOOKUP(B35,Sheet5!$B$2:$C$2166,2,FALSE) -> 520 | D35: 215 | E35: 85 | F35: 0.402 | G35: 0 | H35: 5.370638 | I35: 1 | J35: 1 | K35: 1 | L35: 2 | M35: Real_EU | N35: Denmark | O35: 1 | P35: 1 | Q35: DNK | R35: =VLOOKUP(Q35,GDP!$A$2:$B$266,1,FALSE) -> DNK | S35: =VLOOKUP(Q35,GDP!$A$2:$B$266,2,FALSE) -> Denmark | T35: =VLOOKUP(Q35,GDP!$A$1:$L$266,9,FALSE) -> 69089.469 | U35: 69089.469 | V35: =VLOOKUP(Q35,POP!$B$5:$M$269,9,FALSE) -> 3752146 | W35: 3752146 | X35: =VLOOKUP(Q35,YU!$B$1:$M$266,9,FALSE) -> 10.533 | Y35: 10.533 | Z35: 6.3558602 | AA35: =LN(T35) -> 11.143158 | AB35: =AA35-AVERAGE($AA$2:$AA$469) -> 0.6187609 | AC35: 0.6187609 | AD35: -0.77404661 | AE35: -4.782406 | AG35: =T35-U35 -> 0 | AH35: =V35-W35 -> 0 | AI35: =X35-Y35 -> 0 | AJ35: =LN(C35)-H35 -> 0.88319078
A36: 2023 | B36: Denmark | C36: =VLOOKUP(B36,Sheet5!$B$2:$C$2166,2,FALSE) -> 520 | D36: 170 | E36: 60 | F36: 0.361 | G36: 0 | H36: 5.1357984 | I36: 1 | J36: 1 | K36: 1 | L36: 3 | M36: Real_EU | N36: Denmark | O36: 1 | P36: 1 | Q36: DNK | R36: =VLOOKUP(Q36,GDP!$A$2:$B$266,1,FALSE) -> DNK | S36: =VLOOKUP(Q36,GDP!$A$2:$B$266,2,FALSE) -> Denmark | T36: =VLOOKUP(Q36,GDP!$A$1:$L$266,10,FALSE) -> 68993.903 | U36: 68993.903 | V36: =VLOOKUP(Q36,POP!$B$5:$M$269,10,FALSE) -> 3778269 | W36: 3778269 | X36: =VLOOKUP(Q36,YU!$B$1:$M$266,10,FALSE) -> 11.499 | Y36: 11.499 | AA36: =LN(T36) -> 11.141773 | AB36: =AA36-AVERAGE($AA$2:$AA$469) -> 0.61737672 | AC36: 0.61737672 | AD36: -0.76710858 | AE36: -3.816406 | AG36: =T36-U36 -> 0 | AH36: =V36-W36 -> 0 | AI36: =X36-Y36 -> 0 | AJ36: =LN(C36)-H36 -> 1.1180304
A37: 2024 | B37: Denmark | C37: =VLOOKUP(B37,Sheet5!$B$2:$C$2166,2,FALSE) -> 520 | D37: 155 | E37: 65 | F37: 0.40900000000000003 | G37: 0 | H37: 5.0434251 | I37: 1 | J37: 1 | K37: 1 | L37: 4 | M37: Real_EU | N37: Denmark | O37: 1 | P37: 1 | Q37: DNK | R37: =VLOOKUP(Q37,GDP!$A$2:$B$266,1,FALSE) -> DNK | S37: =VLOOKUP(Q37,GDP!$A$2:$B$266,2,FALSE) -> Denmark | T37: =VLOOKUP(Q37,GDP!$A$1:$L$266,11,FALSE) -> 71034.579 | U37: 71034.579 | V37: =VLOOKUP(Q37,POP!$B$5:$M$269,11,FALSE) -> 3791657 | W37: 3791657 | X37: =VLOOKUP(Q37,YU!$B$1:$M$266,11,FALSE) -> 11.786 | Y37: 11.786 | AA37: =LN(T37) -> 11.170922 | AB37: =AA37-AVERAGE($AA$2:$AA$469) -> 0.64652536 | AC37: 0.64652536 | AD37: -0.76357142 | AE37: -3.529406 | AG37: =T37-U37 -> 0 | AH37: =V37-W37 -> 0 | AI37: =X37-Y37 -> 0 | AJ37: =LN(C37)-H37 -> 1.2104037
A38: 2016 | B38: Finland | C38: =VLOOKUP(B38,Sheet5!$B$2:$C$2166,2,FALSE) -> 1010 | D38: 1010 | E38: 555 | F38: 0.552 | G38: 5 | H38: 6.9177056 | I38: 1 | J38: 1 | K38: 0 | L38: -4 | M38: Real_EU | N38: Finland | O38: 1 | P38: 0 | Q38: FIN | R38: =VLOOKUP(Q38,GDP!$A$2:$B$266,1,FALSE) -> FIN | S38: =VLOOKUP(Q38,GDP!$A$2:$B$266,2,FALSE) -> Finland | T38: =VLOOKUP(Q38,GDP!$A$1:$C$266,3,FALSE) -> 53984.632 | U38: 53984.632 | V38: =VLOOKUP(Q38,POP!$B$5:$M$269,3,FALSE) -> 3463591 | W38: 3463591 | X38: =VLOOKUP(Q38,YU!$B$1:$D$266,3,FALSE) -> 20.057 | Y38: 20.057 | Z38: 6.90873 | AA38: =LN(T38) -> 10.896455 | AB38: =AA38-AVERAGE($AA$2:$AA$469) -> 0.37205798 | AC38: 0.37205798 | AD38: -0.85406864 | AE38: 4.741594 | AG38: =T38-U38 -> 0 | AH38: =V38-W38 -> 0 | AI38: =X38-Y38 -> 0 | AJ38: =LN(C38)-H38 -> 0
A39: 2017 | B39: Finland | C39: =VLOOKUP(B39,Sheet5!$B$2:$C$2166,2,FALSE) -> 1010 | D39: 875 | E39: 470 | F39: 0.536 | G39: 5 | H39: 6.7742239 | I39: 1 | J39: 1 | K39: 0 | L39: -3 | M39: Real_EU | N39: Finland | O39: 1 | P39: 0 | Q39: FIN | R39: =VLOOKUP(Q39,GDP!$A$2:$B$266,1,FALSE) -> FIN | S39: =VLOOKUP(Q39,GDP!$A$2:$B$266,2,FALSE) -> Finland | T39: =VLOOKUP(Q39,GDP!$A$1:$L$266,4,FALSE) -> 55637.226 | U39: 55637.226 | V39: =VLOOKUP(Q39,POP!$B$5:$M$269,4,FALSE) -> 3451187 | W39: 3451187 | X39: =VLOOKUP(Q39,YU!$B$1:$M$266,4,FALSE) -> 20.041 | Y39: 20.041 | Z39: 6.4082699 | AA39: =LN(T39) -> 10.926608 | AB39: =AA39-AVERAGE($AA$2:$AA$469) -> 0.40221109 | AC39: 0.40221109 | AD39: -0.85765632 | AE39: 4.725594 | AG39: =T39-U39 -> 0 | AH39: =V39-W39 -> 0 | AI39: =X39-Y39 -> 0 | AJ39: =LN(C39)-H39 -> 0.14348172
A40: 2018 | B40: Finland | C40: =VLOOKUP(B40,Sheet5!$B$2:$C$2166,2,FALSE) -> 1010 | D40: 920 | E40: 520 | F40: 0.5650000000000001 | G40: 5 | H40: 6.8243737 | I40: 1 | J40: 1 | K40: 0 | L40: -2 | M40: Real_EU | N40: Finland | O40: 1 | P40: 0 | Q40: FIN | R40: =VLOOKUP(Q40,GDP!$A$2:$B$266,1,FALSE) -> FIN | S40: =VLOOKUP(Q40,GDP!$A$2:$B$266,2,FALSE) -> Finland | T40: =VLOOKUP(Q40,GDP!$A$1:$L$266,5,FALSE) -> 56226.337 | U40: 56226.337 | V40: =VLOOKUP(Q40,POP!$B$5:$M$269,5,FALSE) -> 3437018 | W40: 3437018 | X40: =VLOOKUP(Q40,YU!$B$1:$M$266,5,FALSE) -> 16.958 | Y40: 16.958 | Z40: 6.3177199 | AA40: =LN(T40) -> 10.937141 | AB40: =AA40-AVERAGE($AA$2:$AA$469) -> 0.41274386 | AC40: 0.41274386 | AD40: -0.86177032 | AE40: 1.642594 | AG40: =T40-U40 -> 0 | AH40: =V40-W40 -> 0 | AI40: =X40-Y40 -> 0 | AJ40: =LN(C40)-H40 -> 0.09333194
...

Sheet GDP
A1: Country Code | B1: Country Name | C1: 2016 | D1: 2017 | E1: 2018 | F1: 2019 | G1: 2020 | H1: 2021 | I1: 2022 | J1: 2023 | K1: 2024 | L1: 2025
A2: ABW | B2: Aruba | C2: 36926.113 | D2: 38213.289 | E2: 39378.228 | F2: 39754.56 | G2: 30408.827 | H2: 35207.171 | I2: 39083.462 | J2: 42783.249 | K2: 45428.003
A3: AFE | B3: Africa Eastern and Southern | C3: 4210.9357 | D3: 4223.1881 | E3: 4229.8396 | F3: 4200.531 | G3: 3978.1335 | H3: 4049.9695 | I3: 4098.1262 | J3: 4076.2249 | K3: 4099.8898 | L3: 4164.6792
A4: AFG | B4: Afghanistan | C4: 2958.7854 | D4: 2952.9989 | E4: 2902.3921 | F4: 2927.2451 | G4: 2769.6857 | H4: 2144.1666 | I4: 1981.7102 | J4: 1983.8126 | K4: 1964.4523
A5: AFW | B5: Africa Western and Central | C5: 6034.827 | D5: 6009.5161 | E5: 6026.5276 | F5: 6070.2848 | G5: 5698.7667 | H5: 5702.1349 | I5: 5818.4832 | J5: 5886.7966 | K5: 6009.0847 | L5: 6139.5873
A6: AGO | B6: Angola | C6: 10963.997 | D6: 10565.168 | E6: 10154.839 | F6: 9712.9794 | G6: 8904.949 | H6: 8720.1877 | I6: 8750.9936 | J6: 8597.5388 | K6: 8752.7975 | L6: 8760.1908
A7: ALB | B7: Albania | C7: 14643.429 | D7: 15359.397 | E7: 16170.923 | F7: 16761.123 | G7: 16457.719 | H7: 18212.795 | I7: 19388.793 | J7: 20501.647 | K7: 21640.984 | L7: 22724.294
A8: AND | B8: Andorra | C8: 64402.809 | D8: 63239.658 | E8: 63048.599 | F8: 63215.9 | G8: 55488.49 | H8: 59332.203 | I8: 63913.384 | J8: 64631.296 | K8: 66232.744 | L8: 67993.052
A9: ARB | B9: Arab World | C9: 16632.43 | D9: 16568.802 | E9: 16749.898 | F9: 16808.652 | G9: 15768.041 | H9: 16194.23 | I9: 16933.169 | J9: 16830.759 | K9: 16802.429 | L9: 17050.85
A10: ARE | B10: United Arab Emirates | C10: 75671.037 | D10: 72529.042 | E10: 72671.079 | F10: 72822.947 | G10: 66808.621 | H10: 68580.131 | I10: 70075.638 | J10: 70239.833 | K10: 69701.786
A11: ARG | B11: Argentina | C11: 27802.106 | D11: 28334.904 | E11: 27367.115 | F11: 26629.553 | G11: 23877.093 | H11: 26300.274 | I11: 27825.027 | J11: 27230.397 | K11: 26771.966 | L11: 27846.598
A12: ARM | B12: Armenia | C12: 13192.994 | D12: 14243.875 | E12: 15037.045 | F12: 16215.361 | G12: 15052.936 | H12: 15921.705 | I12: 17886.178 | J12: 19402.751 | K12: 20078.785 | L12: 21153.478
A13: ASM | B13: American Samoa
A14: ATG | B14: Antigua and Barbuda | C14: 26627.715 | D14: 27199.195 | E14: 28878.607 | F14: 29651.864 | G14: 23930.671 | H14: 25745.496 | I14: 27785.557 | J14: 28712.397 | K14: 29298.647 | L14: 30620.308
A15: AUS | B15: Australia | C15: 56529.952 | D15: 56881.857 | E15: 57647.846 | F15: 58048.619 | G15: 57260.465 | H15: 58327.415 | I15: 60029.133 | J15: 60684.96 | K15: 60309.583 | L15: 60194.063
A16: AUT | B16: Austria | C16: 61572.626 | D16: 62535.811 | E16: 63777.936 | F16: 64609.284 | G16: 60276.331 | H16: 62968.854 | I16: 65694.459 | J16: 64536.208 | K16: 63787.989 | L16: 63970.401
A17: AZE | B17: Azerbaijan | C17: 19822.411 | D17: 19659.005 | E17: 19781.851 | F17: 20101.492 | G17: 19126.097 | H17: 20111.376 | I17: 21051.244 | J17: 21310.739 | K17: 22090.53 | L17: 22314.217
A18: BDI | B18: Burundi | C18: 1006.5591 | D18: 1020.8498 | E18: 1043.4056 | F18: 1054.7259 | G18: 1027.629 | H18: 1032.3827 | I18: 1028.1113 | J18: 1033.0094 | K18: 1048.0556 | L18: 1066.513
A19: BEL | B19: Belgium | C19: 57901.498 | D19: 58529.33 | E19: 59357.69 | F19: 60479.977 | G19: 57333.542 | H19: 60669.214 | I19: 62602.927 | J19: 63042.01 | K19: 63311.277 | L19: 63488.422
A20: BEN | B20: Benin | C20: 2962.6638 | D20: 3041.7793 | E20: 3155.4511 | F20: 3281.1047 | G20: 3317.8597 | H20: 3464.2886 | I20: 3588.3252 | J20: 3721.2125 | K20: 3901.3259 | L20: 4116.2152
A21: BFA | B21: Burkina Faso | C21: 2162.7258 | D21: 2232.2878 | E21: 2316.3943 | F21: 2391.5363 | G21: 2380.9317 | H21: 2486.4309 | I21: 2469.1996 | J21: 2486.2067 | K21: 2548.5025 | L21: 2624.8286
A22: BGD | B22: Bangladesh | C22: 5682.5355 | D22: 6005.7072 | E22: 6392.5933 | F22: 6838.3261 | G22: 7015.1979 | H22: 7441.0691 | I22: 7888.1639 | J22: 8242.398 | K22: 8486.785 | L22: 8676.7558
A23: BGR | B23: Bulgaria | C23: 25636.744 | D23: 26691.758 | E23: 27690.894 | F23: 29149.922 | G23: 28521.206 | H23: 30958.983 | I23: 32433.659 | J23: 33073.68 | K23: 34221.387 | L23: 35325.532
A24: BHR | B24: Bahrain | C24: 54107.075 | D24: 53859.775 | E24: 54893.072 | F24: 56749.963 | G24: 53814.245 | H24: 54954.676 | I24: 57572.998 | J24: 57819.905 | K24: 59060.182 | L24: 60669.631
A25: BHS | B25: Bahamas, The | C25: 32172.337 | D25: 33050.035 | E25: 33650.216 | F25: 33202.49 | G25: 26452.696 | H25: 31064.682 | I25: 34342.929 | J25: 35221.27 | K25: 36244.05
A26: BIH | B26: Bosnia and Herzegovina | C26: 14873.641 | D26: 15554.659 | E26: 16349 | F26: 17029.297 | G26: 16747.035 | H26: 18286.661 | I26: 19298.117 | J26: 19804.918 | K26: 20578.5 | L26: 21178.226
A27: BLR | B27: Belarus | C27: 24846.83 | D27: 25503.981 | E27: 26363.463 | F27: 26798.821 | G27: 26731.495 | H27: 27611.18 | I27: 26537.508 | J27: 27782.438 | K27: 29135.947 | L27: 29666.212
A28: BLZ | B28: Belize | C28: 12063.06 | D28: 11572.301 | E28: 11451.898 | F28: 11765.975 | G28: 10045.14 | H28: 11716.327 | I28: 12565.365 | J28: 12371.009 | K28: 12621.408 | L28: 12788.842
A29: BMU | B29: Bermuda | C29: 93269.014 | D29: 96441.272 | E29: 95643.273 | F29: 95523.962 | G29: 88484.816 | H29: 92319.671 | I29: 97943.055 | J29: 102268.92 | K29: 104299.94
A30: BOL | B30: Bolivia | C30: 11448.022 | D30: 11755.256 | E30: 11920.314 | F30: 11930.916 | G30: 10285.659 | H30: 11202.441 | I30: 11487.715 | J30: 11616.158 | K30: 11329.152 | L30: 11000.535
A31: BRA | B31: Brazil | C31: 17620.927 | D31: 17724.48 | E31: 17917.749 | F31: 18018.621 | G31: 17327.516 | H31: 18075.706 | I31: 18554.046 | J31: 19079.812 | K31: 19652.365 | L31: 20024.697
A32: BRB | B32: Barbados | C32: 19877.112 | D32: 19966.32 | E32: 19877.676 | F32: 19890.456 | G32: 16399.702 | H32: 17686.747 | I32: 20494.534 | J32: 20865.016 | K32: 21557.528 | L32: 22127.36
A33: BRN | B33: Brunei Darussalam | C33: 78880.623 | D33: 78966.864 | E33: 78099.051 | F33: 80228.16 | G33: 80280.898 | H33: 78248.797 | I33: 76357.829 | J33: 76616.701 | K33: 79071.733 | L33: 78985.122
A34: BTN | B34: Bhutan | C34: 13320.976 | D34: 13482.343 | E34: 13854.854 | F34: 14555.188 | G34: 12979.937 | H34: 13458.813 | I34: 14061.312 | J34: 14610.296 | K34: 15603.887 | L34: 16743.87
A35: BWA | B35: Botswana | C35: 16905.589 | D35: 17352.896 | E35: 17825.019 | F35: 18106.011 | G35: 16289.391 | H35: 17960.625 | I35: 18647.373 | J35: 18932.48 | K35: 18107.614 | L35: 17687.204
A36: CAF | B36: Central African Republic | C36: 1073.9448 | D36: 1103.8661 | E36: 1125.7009 | F36: 1145.0956 | G36: 1136.5705 | H36: 1128.5524 | I36: 1136.8017 | J36: 1132.6764 | K36: 1111.2194 | L36: 1122.7608
A37: CAN | B37: Canada | C37: 55606.133 | D37: 56612.306 | E37: 57337.468 | F37: 57583.823 | G37: 54092.858 | H37: 56995.095 | I37: 58583.13 | J37: 58088.378 | K37: 57534.092 | L37: 57989.578
A38: CEB | B38: Central Europe and the Baltics | C38: 33063.13 | D38: 34898.599 | E38: 36731.096 | F38: 38302.006 | G38: 37280.02 | H38: 40122.361 | I38: 41833.706 | J38: 42113.891 | K38: 43043.895 | L38: 44160.926
A39: CHE | B39: Switzerland | C39: 78956.067 | D39: 79333.744 | E39: 81371.894 | F39: 81694.631 | G39: 79270.871 | H39: 83524.983 | I39: 85762.283 | J39: 85383.356 | K39: 85448.059 | L39: 85732.11
A40: CHI | B40: Channel Islands
...

Sheet YU
A1: Country Name | B1: Country Code | C1: Indicator Name | D1: 2016 | E1: 2017 | F1: 2018 | G1: 2019 | H1: 2020 | I1: 2021 | J1: 2022 | K1: 2023 | L1: 2024 | M1: 2025
A2: Aruba | B2: ABW | C2: Unemployment, youth total (% of total labor force ages 15-24) (modeled ILO estimate)
A3: Africa Eastern and Southern | B3: AFE | C3: Unemployment, youth total (% of total labor force ages 15-24) (modeled ILO estimate) | D3: 13.725492 | E3: 13.594787 | F3: 13.565834 | G3: 13.839376 | H3: 15.018714 | I3: 14.929679 | J3: 13.938984 | K3: 13.688151 | L3: 13.52593 | M3: 13.440298
A4: Afghanistan | B4: AFG | C4: Unemployment, youth total (% of total labor force ages 15-24) (modeled ILO estimate) | D4: 14.932 | E4: 17.31 | F4: 16.402 | G4: 15.52 | H4: 16.053 | I4: 16.013 | J4: 17.539 | K4: 17.494 | L4: 17.235 | M4: 16.785
A5: Africa Western and Central | B5: AFW | C5: Unemployment, youth total (% of total labor force ages 15-24) (modeled ILO estimate) | D5: 7.704765 | E5: 7.8917311 | F5: 7.925676 | G5: 8.0132674 | H5: 8.6873194 | I5: 7.6464533 | J5: 5.9107512 | K5: 5.5005115 | L5: 5.4743629 | M5: 5.5965985
A6: Angola | B6: AGO | C6: Unemployment, youth total (% of total labor force ages 15-24) (modeled ILO estimate) | D6: 34.483 | E6: 33.725 | F6: 32.855 | G6: 31.832 | H6: 33.076 | I6: 30.171 | J6: 27.143 | K6: 26.834 | L6: 26.74 | M6: 27.229
A7: Albania | B7: ALB | C7: Unemployment, youth total (% of total labor force ages 15-24) (modeled ILO estimate) | D7: 35.918 | E7: 31.184 | F7: 28.109 | G7: 26.942 | H7: 26.422 | I7: 27.089 | J7: 24.543 | K7: 25.41 | L7: 25.582 | M7: 25.567
A8: Andorra | B8: AND | C8: Unemployment, youth total (% of total labor force ages 15-24) (modeled ILO estimate)
A9: Arab World | B9: ARB | C9: Unemployment, youth total (% of total labor force ages 15-24) (modeled ILO estimate) | D9: 28.387389 | E9: 29.11701 | F9: 27.567656 | G9: 26.102281 | H9: 28.096562 | I9: 26.729901 | J9: 24.100074 | K9: 25.313551 | L9: 25.368668 | M9: 25.4879
A10: United Arab Emirates | B10: ARE | C10: Unemployment, youth total (% of total labor force ages 15-24) (modeled ILO estimate) | D10: 5.107 | E10: 7.474 | F10: 6.747 | G10: 7.325 | H10: 13.482 | I10: 9.737 | J10: 9.992 | K10: 6.351 | L10: 6.425 | M10: 6.451
A11: Argentina | B11: ARG | C11: Unemployment, youth total (% of total labor force ages 15-24) (modeled ILO estimate) | D11: 21.799 | E11: 22.843 | F11: 23.845 | G11: 25.842 | H11: 30.429 | I11: 23.373 | J11: 19.004 | K11: 17.946 | L11: 19.228 | M11: 19.188
A12: Armenia | B12: ARM | C12: Unemployment, youth total (% of total labor force ages 15-24) (modeled ILO estimate) | D12: 35.657 | E12: 37.728 | F12: 33.62 | G12: 32.613 | H12: 32.079 | I12: 30.095 | J12: 26.691 | K12: 26.736 | L12: 26.659 | M12: 26.244
A13: American Samoa | B13: ASM | C13: Unemployment, youth total (% of total labor force ages 15-24) (modeled ILO estimate)
A14: Antigua and Barbuda | B14: ATG | C14: Unemployment, youth total (% of total labor force ages 15-24) (modeled ILO estimate)
A15: Australia | B15: AUS | C15: Unemployment, youth total (% of total labor force ages 15-24) (modeled ILO estimate) | D15: 12.642 | E15: 12.592 | F15: 11.935 | G15: 11.452 | H15: 14.142 | I15: 11.134 | J15: 8.468 | K15: 8.388 | L15: 9.408 | M15: 9.61
A16: Austria | B16: AUT | C16: Unemployment, youth total (% of total labor force ages 15-24) (modeled ILO estimate) | D16: 11.424 | E16: 9.971 | F16: 9.572 | G16: 8.767 | H16: 10.325 | I16: 12.023 | J16: 10.327 | K16: 10.98 | L16: 10.428 | M16: 10.998
A17: Azerbaijan | B17: AZE | C17: Unemployment, youth total (% of total labor force ages 15-24) (modeled ILO estimate) | D17: 12.925 | E17: 12.389 | F17: 11.637 | G17: 11.475 | H17: 15.129 | I17: 14.675 | J17: 13.616 | K17: 13.581 | L17: 13.544 | M17: 13.091
A18: Burundi | B18: BDI | C18: Unemployment, youth total (% of total labor force ages 15-24) (modeled ILO estimate) | D18: 2.456 | E18: 2.225 | F18: 1.993 | G18: 1.754 | H18: 1.69 | I18: 1.772 | J18: 1.705 | K18: 1.7 | L18: 1.695 | M18: 1.678
A19: Belgium | B19: BEL | C19: Unemployment, youth total (% of total labor force ages 15-24) (modeled ILO estimate) | D19: 20.108 | E19: 19.236 | F19: 15.748 | G19: 14.236 | H19: 15.326 | I19: 18.206 | J19: 16.41 | K19: 16.119 | L19: 17.343 | M19: 17.777
A20: Benin | B20: BEN | C20: Unemployment, youth total (% of total labor force ages 15-24) (modeled ILO estimate) | D20: 3.237 | E20: 2.981 | F20: 2.621 | G20: 2.302 | H20: 2.96 | I20: 3.242 | J20: 3.13 | K20: 3.09 | L20: 3.089 | M20: 2.887
A21: Burkina Faso | B21: BFA | C21: Unemployment, youth total (% of total labor force ages 15-24) (modeled ILO estimate) | D21: 7.383 | E21: 7.53 | F21: 7.638 | G21: 7.432 | H21: 7.978 | I21: 7.642 | J21: 6.722 | K21: 6.569 | L21: 6.525 | M21: 6.438
A22: Bangladesh | B22: BGD | C22: Unemployment, youth total (% of total labor force ages 15-24) (modeled ILO estimate) | D22: 10.956 | E22: 12.101 | F22: 11.907 | G22: 11.742 | H22: 13.473 | I22: 12.72 | J22: 10.985 | K22: 7.905 | L22: 9.097 | M22: 9.385
A23: Bulgaria | B23: BGR | C23: Unemployment, youth total (% of total labor force ages 15-24) (modeled ILO estimate) | D23: 17.224 | E23: 12.927 | F23: 12.676 | G23: 8.777 | H23: 14.143 | I23: 15.701 | J23: 10.582 | K23: 12.049 | L23: 12.493 | M23: 10.152
A24: Bahrain | B24: BHR | C24: Unemployment, youth total (% of total labor force ages 15-24) (modeled ILO estimate) | D24: 5.527 | E24: 5.593 | F24: 5.633 | G24: 5.657 | H24: 6.389 | I24: 6.043 | J24: 5.33 | K24: 5.381 | L24: 5.469 | M24: 5.416
A25: Bahamas, The | B25: BHS | C25: Unemployment, youth total (% of total labor force ages 15-24) (modeled ILO estimate) | D25: 25.844 | E25: 21.547 | F25: 24.16 | G25: 19.235 | H25: 23.943 | I25: 21.768 | J25: 18.694 | K25: 17.696 | L25: 18.291 | M25: 19.248
A26: Bosnia and Herzegovina | B26: BIH | C26: Unemployment, youth total (% of total labor force ages 15-24) (modeled ILO estimate) | D26: 56.261 | E26: 47.925 | F26: 40.535 | G26: 35.263 | H26: 37.924 | I26: 35.816 | J26: 31.728 | K26: 27.27 | L26: 27.334 | M26: 28.201
... A28: Belize | B28: BLZ | C28: Unemployment, youth total (% of total labor force ages 15-24) (modeled ILO estimate) | D28: 16.547 | E28: 15.686 | F28: 22.006 | G28: 19.934 | H28: 22.367 | I28: 21.819 | J28: 18.422 | K28: 17.833 | L28: 18.553 | M28: 19.321
A29: Bermuda | B29: BMU | C29: Unemployment, youth total (% of total labor force ages 15-24) (modeled ILO estimate)
A30: Bolivia | B30: BOL | C30: Unemployment, youth total (% of total labor force ages 15-24) (modeled ILO estimate) | D30: 6.772 | E30: 6.654 | F30: 6.78 | G30: 6.927 | H30: 15.241 | I30: 8.199 | J30: 6.044 | K30: 4.968 | L30: 5.17 | M30: 5.013
A31: Brazil | B31: BRA | C31: Unemployment, youth total (% of total labor force ages 15-24) (modeled ILO estimate) | D31: 26.596 | E31: 28.593 | F31: 27.958 | G31: 27.098 | H31: 30.267 | I31: 28.311 | J31: 20.732 | K31: 17.938 | L31: 15.674 | M31: 13.981
A32: Barbados | B32: BRB | C32: Unemployment, youth total (% of total labor force ages 15-24) (modeled ILO estimate) | D32: 26.183 | E32: 26.206 | F32: 24.207 | G32: 25.785 | H32: 30.031 | I32: 28.25 | J32: 21.026 | K32: 18.264 | L32: 18.049 | M32: 18.479
A33: Brunei Darussalam | B33: BRN | C33: Unemployment, youth total (% of total labor force ages 15-24) (modeled ILO estimate) | D33: 27.629 | E33: 29.255 | F33: 30.809 | G33: 20.141 | H33: 26.852 | I33: 16.238 | J33: 18.299 | K33: 17.955 | L33: 17.872 | M33: 18.23
A34: Bhutan | B34: BTN | C34: Unemployment, youth total (% of total labor force ages 15-24) (modeled ILO estimate) | D34: 11.614 | E34: 13.355 | F34: 15.199 | G34: 11.56 | H34: 21.989 | I34: 20.609 | J34: 27.177 | K34: 14.939 | L34: 17.934 | M34: 17.052
A35: Botswana | B35: BWA | C35: Unemployment, youth total (% of total labor force ages 15-24) (modeled ILO estimate) | D35: 34.851 | E35: 34.872 | F35: 34.404 | G35: 34.588 | H35: 40.436 | I35: 43.355 | J35: 42.611 | K35: 44.361 | L35: 45.296 | M35: 46.004
A36: Central African Republic | B36: CAF | C36: Unemployment, youth total (% of total labor force ages 15-24) (modeled ILO estimate) | D36: 9.746 | E36: 9.726 | F36: 9.574 | G36: 9.637 | H36: 10.863 | I36: 10.831 | J36: 10.078 | K36: 9.861 | L36: 9.991 | M36: 10.086
A37: Canada | B37: CAN | C37: Unemployment, youth total (% of total labor force ages 15-24) (modeled ILO estimate) | D37: 12.597 | E37: 11.236 | F37: 10.709 | G37: 10.744 | H37: 20.125 | I37: 13.557 | J37: 10.082 | K37: 10.806 | L37: 13.276 | M37: 13.8
A38: Central Europe and the Baltics | B38: CEB | C38: Unemployment, youth total (% of total labor force ages 15-24) (modeled ILO estimate) | D38: 17.711384 | E38: 15.009178 | F38: 12.663909 | G38: 11.677464 | H38: 13.636387 | I38: 14.859426 | J38: 13.676816 | K38: 14.160108 | L38: 14.631738 | M38: 14.539469
A39: Switzerland | B39: CHE | C39: Unemployment, youth total (% of total labor force ages 15-24) (modeled ILO estimate) | D39: 8.579 | E39: 8.059 | F39: 7.937 | G39: 7.993 | H39: 8.603 | I39: 8.315 | J39: 6.835 | K39: 7.865 | L39: 8.238 | M39: 9.041
A40: Channel Islands | B40: CHI | C40: Unemployment, youth total (% of total labor force ages 15-24) (modeled ILO estimate) | D40: 17.624 | E40: 15.811 | F40: 14.013 | G40: 13.75 | H40: 15.857 | I40: 15.619 | J40: 13.183 | K40: 13.382 | L40: 13.699 | M40: 14.126
A41: Chile | B41: CHL | C41: Unemployment, youth total (% of total labor force ages 15-24) (modeled ILO estimate) | D41: 15.799 | E41: 17.732 | F41: 18.138 | G41: 18.953 | H41: 24.377 | I41: 20.477 | J41: 18.287 | K41: 21.973 | L41: 20.988 | M41: 21.635
...

Sheet POP
A1: Data Source | B1: World Development Indicators
A2: Last Updated Date | B2: 46216
A4: Country Name | B4: Country Code | C4: Indicator Name | D4: 2016 | E4: 2017 | F4: 2018 | G4: 2019 | H4: 2020 | I4: 2021 | J4: 2022 | K4: 2023 | L4: 2024 | M4: 2025
A5: Aruba | B5: ABW | C5: Population ages 15-64, total | D5: 74904 | E5: 74413 | F5: 74029 | G5: 73736 | H5: 72936 | I5: 72127 | J5: 71635 | K5: 71335 | L5: 71383 | M5: 71494
A6: Africa Eastern and Southern | B6: AFE | C6: Population ages 15-64, total | D6: 339468543 | E6: 349952708 | F6: 361339357 | G6: 372963801 | H6: 384904376 | I6: 397031637 | J6: 409197442 | K6: 421361159 | L6: 433621343 | M6: 446435808
A7: Afghanistan | B7: AFG | C7: Population ages 15-64, total | D7: 17989857 | E7: 18656626 | F7: 19353761 | G7: 20081542 | H7: 20864851 | I7: 21495952 | J7: 21938957 | K7: 22549839 | L7: 23333093 | M7: 24120179
A8: Africa Western and Central | B8: AFW | C8: Population ages 15-64, total | D8: 228082797 | E8: 235027948 | F8: 242104005 | G8: 249283206 | H8: 256747586 | I8: 264518911 | J8: 272504904 | K8: 281039233 | L8: 289941374 | M8: 298818108
A9: Angola | B9: AGO | C9: Population ages 15-64, total | D9: 15184647 | E9: 15741446 | F9: 16308860 | G9: 16893364 | H9: 17479836 | I9: 18076361 | J9: 18697266 | K9: 19336436 | L9: 20002446 | M9: 20693794
A10: Albania | B10: ALB | C10: Population ages 15-64, total | D10: 1841574 | E10: 1811725 | F10: 1779914 | G10: 1746300 | H10: 1712060 | I10: 1677267 | J10: 1642625 | K10: 1607515 | L10: 1574525 | M10: 1545359
A11: Andorra | B11: AND | C11: Population ages 15-64, total | D11: 51890 | E11: 53144 | F11: 54337 | G11: 55411 | H11: 56010 | I11: 56705 | J11: 57686 | K11: 58486 | L11: 59134 | M11: 59541
A12: Arab World | B12: ARB | C12: Population ages 15-64, total | D12: 259948218 | E12: 265154282 | F12: 269777484 | G12: 275101711 | H12: 281455424 | I12: 286266742 | J12: 294283776 | K12: 302530294 | L12: 310517699 | M12: 318560634
A13: United Arab Emirates | B13: ARE | C13: Population ages 15-64, total | D13: 7300309 | E13: 7540665 | F13: 7644643 | G13: 7728787 | H13: 7695346 | I13: 7839407 | J13: 8249860 | K13: 8593051 | L13: 9022258 | M13: 9467296
A14: Argentina | B14: ARG | C14: Population ages 15-64, total | D14: 28132899 | E14: 28395268 | F14: 28651937 | G14: 28904522 | H14: 29152195 | I14: 29381676 | J14: 29612843 | K14: 29876069 | L14: 30150350 | M14: 30422322
A15: Armenia | B15: ARM | C15: Population ages 15-64, total | D15: 2050742 | E15: 2029303 | F15: 2014073 | G15: 2004252 | H15: 1998643 | I15: 1995138 | J15: 1995964 | K15: 1993303 | L15: 2034270 | M15: 2054803
A16: American Samoa | B16: ASM | C16: Population ages 15-64, total | D16: 33011 | E16: 32681 | F16: 32331 | G16: 31953 | H16: 31828 | I16: 31722 | J16: 31340 | K16: 30859 | L16: 30373 | M16: 29971
... A113: India | B113: IND | C113: Population ages 15-64, total | D113: 886641930 | E113: 901825708 | F113: 916251300 | G113: 929875277 | H113: 943088901 | I113: 955281267 | J113: 966626467 | K113: 978190678 | L113: 989967399 | M113: 1001696269
A114: Not classified | B114: INX | C114: Population ages 15-64, total
A115: Ireland | B115: IRL | C115: Population ages 15-64, total | D115: 3117425 | E115: 3156397 | F115: 3200720 | G115: 3251795 | H115: 3292799 | I115: 3339274 | J115: 3408271 | K115: 3475937 | L115: 3537072 | M115: 3603008
A116: Iran, Islamic Rep. | B116: IRN | C116: Population ages 15-64, total | D116: 58653653 | E116: 59181768 | F116: 59663966 | G116: 60127389 | H116: 60526092 | I116: 61073582 | J116: 61905803 | K116: 62742120 | L116: 63475136 | M116: 64135210
A117: Iraq | B117: IRQ | C117: Population ages 15-64, total | D117: 21865053 | E117: 22470795 | F117: 23127004 | G117: 23797416 | H117: 24488669 | I117: 25221090 | J117: 26008388 | K117: 26824423 | L117: 27627172 | M117: 28458766
A118: Iceland | B118: ISL | C118: Population ages 15-64, total | D118: 222029 | E118: 228097 | F118: 235266 | G118: 240957 | H118: 244460 | I118: 247754 | J118: 254073 | K118: 256835 | L118: 257381 | M118: 260968
A119: Israel | B119: ISR | C119: Population ages 15-64, total | D119: 5169199 | E119: 5250514 | F119: 5338168 | G119: 5431498 | H119: 5521012 | I119: 5609567 | J119: 5724315 | K119: 5906413 | L119: 6005125 | M119: 6088301
A120: Italy | B120: ITA | C120: Population ages 15-64, total | D120: 38555229 | E120: 38430960 | F120: 38307226 | G120: 38150120 | H120: 37918891 | I120: 37681637 | J120: 37580511 | K120: 37535657 | L120: 37424897 | M120: 37261028
A121: Jamaica | B121: JAM | C121: Population ages 15-64, total | D121: 1985195 | E121: 2001788 | F121: 2017091 | G121: 2030608 | H121: 2046447 | I121: 2061294 | J121: 2069255 | K121: 2073149 | L121: 2075097 | M121: 2074923
A122: Jordan | B122: JOR | C122: Population ages 15-64, total | D122: 6216745 | E122: 6382875 | F122: 6553683 | G122: 6716939 | H122: 6873279 | I122: 7038442 | J122: 7204554 | K122: 7372741 | L122: 7487234 | M122: 7494228
A123: Japan | B123: JPN | C123: Population ages 15-64, total | D123: 75946619 | E123: 75439583 | F123: 75025904 | G123: 74719384 | H123: 74318579 | I123: 73818755 | J123: 73496437 | K123: 73201968 | L123: 72876601 | M123: 72499552
A124: Kazakhstan | B124: KAZ | C124: Population ages 15-64, total | D124: 11921948 | E124: 12001387 | F124: 12095768 | G124: 12199208 | H124: 12301140 | I124: 12387379 | J124: 12499203 | K124: 12635718 | L124: 12761934 | M124: 12893926
A125: Kenya | B125: KEN | C125: Population ages 15-64, total | D125: 26948413 | E125: 27770185 | F125: 28569551 | G125: 29382342 | H125: 30247731 | I125: 31129981 | J125: 32044126 | K125: 33003939 | L125: 33971376 | M125: 34934452
A126: Kyrgyz Republic | B126: KGZ | C126: Population ages 15-64, total | D126: 3882299 | E126: 3954332 | F126: 4028758 | G126: 4100233 | H126: 4168894 | I126: 4239665 | J126: 4316165 | K126: 4394837 | L126: 4475861 | M126: 4561968
... A269: Zimbabwe | B269: ZWE | C269: Population ages 15-64, total | D269: 7752608 | E269: 7899470 | F269: 8060640 | G269: 8234856 | H269: 8420934 | I269: 8614234 | J269: 8802666 | K269: 8996994 | L269: 9236166 | M269: 9518709

Sheet Sheet5
A1: Year | B1: Domicile_named_country | C1: Applicants | D1: Accepted_applicants | E1: Acceptance_rate | F1: Applicants_with_no_applications
A2: 2016 | B2: England | C2: 488030 | D2: 394295 | E2: 0.808 | F2: 3450
A3: 2017 | B3: England | C3: 472190 | D3: 391370 | E3: 0.8290000000000001 | F3: 3100
A4: 2018 | B4: England | C4: 463865 | D4: 388025 | E4: 0.837 | F4: 2615
A5: 2019 | B5: England | C5: 470175 | D5: 394875 | E5: 0.84 | F5: 2770
A6: 2020 | B6: England | C6: 479895 | D6: 411755 | E6: 0.858 | F6: 3935
A7: 2021 | B7: England | C7: 504460 | D7: 417380 | E7: 0.8270000000000001 | F7: 2250
A8: 2022 | B8: England | C8: 517060 | D8: 418085 | E8: 0.809 | F8: 3175
A9: 2023 | B9: England | C9: 511065 | D9: 414025 | E9: 0.81 | F9: 3275
A10: 2024 | B10: England | C10: 513620 | D10: 423820 | E10: 0.8250000000000001 | F10: 3405
A11: 2025 | B11: England | C11: 515195 | D11: 431515 | E11: 0.838 | F11: 3625
A12: 2016 | B12: Northern Ireland | C12: 21260 | D12: 14800 | E12: 0.6960000000000001 | F12: 50
A13: 2017 | B13: Northern Ireland | C13: 20510 | D13: 14375 | E13: 0.7010000000000001 | F13: 40
... A77: 2021 | B77: Cyprus (Not otherwise specified) | C77: 45 | D77: 35 | E77: 0.791 | F77: 0
A78: 2022 | B78: Cyprus (Not otherwise specified) | C78: 5 | D78: 5 | F78: 0
A79: 2023 | B79: Cyprus (Not otherwise specified) | C79: 20 | D79: 10 | E79: 0.611 | F79: 0
A80: 2024 | B80: Cyprus (Not otherwise specified) | C80: 20 | D80: 15 | E80: 0.789 | F80: 0
A81: 2025 | B81: Cyprus (Not otherwise specified) | C81: 25 | D81: 20 | E81: 0.87 | F81: 0
A82: 2016 | B82: Denmark | C82: 520 | D82: 285 | E82: 0.547 | F82: 0
A83: 2017 | B83: Denmark | C83: 545 | D83: 275 | E83: 0.506 | F83: 0
A84: 2018 | B84: Denmark | C84: 550 | D84: 285 | E84: 0.516 | F84: 0
A85: 2019 | B85: Denmark | C85: 530 | D85: 285 | E85: 0.537 | F85: 0
A86: 2020 | B86: Denmark | C86: 470 | D86: 250 | E86: 0.53 | F86: 0
A87: 2021 | B87: Denmark | C87: 235 | D87: 95 | E87: 0.405 | F87: 0
A88: 2022 | B88: Denmark | C88: 215 | D88: 85 | E88: 0.402 | F88: 0
A89: 2023 | B89: Denmark | C89: 170 | D89: 60 | E89: 0.361 | F89: 0
A90: 2024 | B90: Denmark | C90: 155 | D90: 65 | E90: 0.40900000000000003 | F90: 0
... A241: 2025 | B241: Sweden | C241: 390 | D241: 160 | E241: 0.40700000000000003 | F241: 5
A242: 2017 | B242: French Guiana | C242: 5 | D242: 5 | F242: 0
A243: 2019 | B243: French Guiana | C243: 5 | D243: 0 | F243: 0
A244: 2020 | B244: French Guiana | C244: 5 | D244: 5 | F244: 0
A245: 2016 | B245: French West Indies (Not In Use) | C245: 5 | D245: 5 | F245: 0
A246: 2019 | B246: French West Indies (Not In Use) | C246: 5 | D246: 0 | F246: 0
A247: 2016 | B247: Reunion | C247: 10 | D247: 5 | F247: 0
A248: 2017 | B248: Reunion | C248: 10 | D248: 10 | F248: 0
A249: 2018 | B249: Reunion | C249: 15 | D249: 5 | F249: 0
A250: 2019 | B250: Reunion | C250: 20 | D250: 5 | F250: 0
A251: 2020 | B251: Reunion | C251: 10 | D251: 5 | F251: 0
A252: 2021 | B252: Reunion | C252: 5 | D252: 0 | F252: 0
A253: 2022 | B253: Reunion | C253: 10 | D253: 5 | F253: 0
...
